Workbook

Sheet Notes
A1: FirstEnergy distribution and customer costs compared with Northeast and Midwest peers, 2000–2025
A2: Prepared 2026-10-24.
A3: Measures
A4: Total costs = distribution O&M (accounts 580–598) + customer costs (accounts 901–910) + distribution depreciation and amortization (p. 336). Capital additions to distribution plant (p. 204) are reported separately and are not added to total costs, because depreciation already reflects past capital. Sales expenses (911–916), A&G, taxes and return on rate base are not included. Electric utility only. Nominal dollars unless the constant-dollar columns are filled.
A5: Per-customer values divide dollars by customers used (see data treatment 3). Group values divide group totals by group customers; Peer Medians gives the median of utility-level values.
A6: Sheets
A7: Group Results – FirstEnergy consolidated, Northeast peers and Midwest peers by year: dollars, per-customer values, constant-dollar columns, growth rates.
A8: Utility Results – each utility by year, with ranks among the 36 utilities. Includes a FirstEnergy Pennsylvania combined series (four Pennsylvania companies through 2023, FirstEnergy Pennsylvania Electric from 2024).
A9: Peer Medians – medians of utility-level per-customer values for each peer group, with FirstEnergy consolidated.
A10: Reconciliation – line items vs reported subtotals for every utility-year. Peer Groups – utilities, IDs and years. Category Map – accounts behind each measure. Assumptions – adjustable inputs. Data – inputs from PUDL.
A11: Source and version
A12: Catalyst Cooperative, Public Utility Data Liberation (PUDL), data release v2026.10.0 (datapackage created 2026-10-14T17:10:33Z; git SHA 90561c620a8292583c59b063fe7fd69f59035c24; DOI https://doi.org/10.5281/zenodo.22172378). Documentation: https://docs.catalyst.coop/pudl/en/v2026.10.0/data_sources/ferc1.html. License: CC-BY-4.0 (PUDL); underlying FERC and EIA data are U.S. Government works.
... A37: Blue text: input values from PUDL or typed labels. Black text: formulas referring only to the same sheet. Green text: formulas referring to another sheet. Yellow fill: adjustable inputs.

Sheet Group Results
A1: Distribution and customer costs per customer: FirstEnergy (consolidated) and peer groups, 2000–2025
A2: Group totals divided by group customers (dollar-weighted). Nominal dollars; constant-dollar columns fill when the GDP price index is entered on the Assumptions sheet. Total costs = distribution O&M + customer costs + distribution depreciation. Capital additions are shown separately.
A4: Year | B4: FirstEnergy: utilities | C4: FirstEnergy: customers | D4: FirstEnergy: Distribution O&M ($mm) | E4: FirstEnergy: Customer costs ($mm) | F4: FirstEnergy: Depreciation ($mm) | G4: FirstEnergy: Total costs ($mm) | H4: FirstEnergy: Capital additions ($mm) | I4: FirstEnergy: Distribution O&M per customer ($) | J4: FirstEnergy: Customer costs per customer ($) | K4: FirstEnergy: Depreciation per customer ($) | L4: FirstEnergy: Total costs per customer ($) | M4: FirstEnergy: Capital additions per customer ($) | N4: FirstEnergy: total costs per customer, constant $ | O4: FirstEnergy: capital additions per customer, constant $ | P4: Northeast peers: utilities | Q4: Northeast peers: customers | R4: Northeast peers: Distribution O&M ($mm) | S4: Northeast peers: Customer costs ($mm) | T4: Northeast peers: Depreciation ($mm) | U4: Northeast peers: Total costs ($mm) | V4: Northeast peers: Capital additions ($mm) | W4: Northeast peers: Distribution O&M per customer ($) | X4: Northeast peers: Customer costs per customer ($) | Y4: Northeast peers: Depreciation per customer ($) | Z4: Northeast peers: Total costs per customer ($) | AA4: Northeast peers: Capital additions per customer ($) | AB4: Northeast peers: total costs per customer, constant $ | AC4: Northeast peers: capital additions per customer, constant $ | AD4: Midwest peers: utilities | AE4: Midwest peers: customers | AF4: Midwest peers: Distribution O&M ($mm) | AG4: Midwest peers: Customer costs ($mm) | AH4: Midwest peers: Depreciation ($mm) | AI4: Midwest peers: Total costs ($mm) | AJ4: Midwest peers: Capital additions ($mm) | AK4: Midwest peers: Distribution O&M per customer ($) | AL4: Midwest peers: Customer costs per customer ($) | AM4: Midwest peers: Depreciation per customer ($) | AN4: Midwest peers: Total costs per customer ($) | AO4: Midwest peers: Capital additions per customer ($) | AP4: Midwest peers: total costs per customer, constant $ | AQ4: Midwest peers: capital additions per customer, constant $
A5: 2000 | B5: =COUNTIFS(Data!$A$2:$A$1006,$A5,Data!$C$2:$C$1006,"FirstEnergy") -> 10 | C5: =SUMIFS(Data!$L$2:$L$1006,Data!$A$2:$A$1006,$A5,Data!$C$2:$C$1006,"FirstEnergy") -> 5717603 | D5: =SUMIFS(Data!$E$2:$E$1006,Data!$A$2:$A$1006,$A5,Data!$C$2:$C$1006,"FirstEnergy") -> 452.5503 | E5: =SUMIFS(Data!$F$2:$F$1006,Data!$A$2:$A$1006,$A5,Data!$C$2:$C$1006,"FirstEnergy") -> 417.40168 | F5: =SUMIFS(Data!$G$2:$G$1006,Data!$A$2:$A$1006,$A5,Data!$C$2:$C$1006,"FirstEnergy") -> 313.46906 | G5: =SUMIFS(Data!$N$2:$N$1006,Data!$A$2:$A$1006,$A5,Data!$C$2:$C$1006,"FirstEnergy") -> 1183.421 | H5: =SUMIFS(Data!$H$2:$H$1006,Data!$A$2:$A$1006,$A5,Data!$C$2:$C$1006,"FirstEnergy") -> 452.52607 | I5: =IFERROR(D5*1000000/C5,"") -> 79.150355 | J5: =IFERROR(E5*1000000/C5,"") -> 73.002914 | K5: =IFERROR(F5*1000000/C5,"") -> 54.825257 | L5: =IFERROR(G5*1000000/C5,"") -> 206.97853 | M5: =IFERROR(H5*1000000/C5,"") -> 79.146116 | N5: =IFERROR(IF(OR(IFERROR(INDEX(Assumptions!$B$8:$B$33,MATCH(Assumptions!$B$5,Assumptions!$A$8:$A$33,0)),"")="",INDEX(Assumptions!$B$8:$B$33,MATCH($A5,Assumptions!$A$8:$A$33,0))=""),"",L5*IFERROR(INDEX(Assumptions!$B$8:$B$33,MATCH(Assumptions!$B$5,Assumptions!$A$8:$A$33,0)),"")/INDEX(Assumptions!$B$8:$B$33,MATCH($A5,Assumptions!$A$8:$A$33,0))),"") | O5: =IFERROR(IF(OR(IFERROR(INDEX(Assumptions!$B$8:$B$33,MATCH(Assumptions!$B$5,Assumptions!$A$8:$A$33,0)),"")="",INDEX(Assumptions!$B$8:$B$33,MATCH($A5,Assumptions!$A$8:$A$33,0))=""),"",M5*IFERROR(INDEX(Assumptions!$B$8:$B$33,MATCH(Assumptions!$B$5,Assumptions!$A$8:$A$33,0)),"")/INDEX(Assumptions!$B$8:$B$33,MATCH($A5,Assumptions!$A$8:$A$33,0))),"") | P5: =COUNTIFS(Data!$A$2:$A$1006,$A5,Data!$C$2:$C$1006,"Northeast peers") -> 12 | Q5: =SUMIFS(Data!$L$2:$L$1006,Data!$A$2:$A$1006,$A5,Data!$C$2:$C$1006,"Northeast peers") -> 11311217 | R5: =SUMIFS(Data!$E$2:$E$1006,Data!$A$2:$A$1006,$A5,Data!$C$2:$C$1006,"Northeast peers") -> 848.18644 | S5: =SUMIFS(Data!$F$2:$F$1006,Data!$A$2:$A$1006,$A5,Data!$C$2:$C$1006,"Northeast peers") -> 847.05251 | T5: =SUMIFS(Data!$G$2:$G$1006,Data!$A$2:$A$1006,$A5,Data!$C$2:$C$1006,"Northeast peers") -> 644.19853 | U5: =SUMIFS(Data!$N$2:$N$1006,Data!$A$2:$A$1006,$A5,Data!$C$2:$C$1006,"Northeast peers") -> 2339.4375 | V5: =SUMIFS(Data!$H$2:$H$1006,Data!$A$2:$A$1006,$A5,Data!$C$2:$C$1006,"Northeast peers") -> 1052.0881 | W5: =IFERROR(R5*1000000/Q5,"") -> 74.986311 | X5: =IFERROR(S5*1000000/Q5,"") -> 74.886063 | Y5: =IFERROR(T5*1000000/Q5,"") -> 56.952185 | Z5: =IFERROR(U5*1000000/Q5,"") -> 206.82456 | AA5: =IFERROR(V5*1000000/Q5,"") -> 93.012812 | AB5: =IFERROR(IF(OR(IFERROR(INDEX(Assumptions!$B$8:$B$33,MATCH(Assumptions!$B$5,Assumptions!$A$8:$A$33,0)),"")="",INDEX(Assumptions!$B$8:$B$33,MATCH($A5,Assumptions!$A$8:$A$33,0))=""),"",Z5*IFERROR(INDEX(Assumptions!$B$8:$B$33,MATCH(Assumptions!$B$5,Assumptions!$A$8:$A$33,0)),"")/INDEX(Assumptions!$B$8:$B$33,MATCH($A5,Assumptions!$A$8:$A$33,0))),"") | AC5: =IFERROR(IF(OR(IFERROR(INDEX(Assumptions!$B$8:$B$33,MATCH(Assumptions!$B$5,Assumptions!$A$8:$A$33,0)),"")="",INDEX(Assumptions!$B$8:$B$33,MATCH($A5,Assumptions!$A$8:$A$33,0))=""),"",AA5*IFERROR(INDEX(Assumptions!$B$8:$B$33,MATCH(Assumptions!$B$5,Assumptions!$A$8:$A$33,0)),"")/INDEX(Assumptions!$B$8:$B$33,MATCH($A5,Assumptions!$A$8:$A$33,0))),"") | AD5: =COUNTIFS(Data!$A$2:$A$1006,$A5,Data!$C$2:$C$1006,"Midwest peers") -> 17 | AE5: =SUMIFS(Data!$L$2:$L$1006,Data!$A$2:$A$1006,$A5,Data!$C$2:$C$1006,"Midwest peers") -> 10911721 | AF5: =SUMIFS(Data!$E$2:$E$1006,Data!$A$2:$A$1006,$A5,Data!$C$2:$C$1006,"Midwest peers") -> 784.85799 | AG5: =SUMIFS(Data!$F$2:$F$1006,Data!$A$2:$A$1006,$A5,Data!$C$2:$C$1006,"Midwest peers") -> 641.81182 | AH5: =SUMIFS(Data!$G$2:$G$1006,Data!$A$2:$A$1006,$A5,Data!$C$2:$C$1006,"Midwest peers") -> 732.8381 | AI5: =SUMIFS(Data!$N$2:$N$1006,Data!$A$2:$A$1006,$A5,Data!$C$2:$C$1006,"Midwest peers") -> 2159.5079 | AJ5: =SUMIFS(Data!$H$2:$H$1006,Data!$A$2:$A$1006,$A5,Data!$C$2:$C$1006,"Midwest peers") -> 1250.1348 | AK5: =IFERROR(AF5*1000000/AE5,"") -> 71.927975 | AL5: =IFERROR(AG5*1000000/AE5,"") -> 58.81857 | AM5: =IFERROR(AH5*1000000/AE5,"") -> 67.160634 | AN5: =IFERROR(AI5*1000000/AE5,"") -> 197.90718 | AO5: =IFERROR(AJ5*1000000/AE5,"") -> 114.56807 | AP5: =IFERROR(IF(OR(IFERROR(INDEX(Assumptions!$B$8:$B$33,MATCH(Assumptions!$B$5,Assumptions!$A$8:$A$33,0)),"")="",INDEX(Assumptions!$B$8:$B$33,MATCH($A5,Assumptions!$A$8:$A$33,0))=""),"",AN5*IFERROR(INDEX(Assumptions!$B$8:$B$33,MATCH(Assumptions!$B$5,Assumptions!$A$8:$A$33,0)),"")/INDEX(Assumptions!$B$8:$B$33,MATCH($A5,Assumptions!$A$8:$A$33,0))),"") | AQ5: =IFERROR(IF(OR(IFERROR(INDEX(Assumptions!$B$8:$B$33,MATCH(Assumptions!$B$5,Assumptions!$A$8:$A$33,0)),"")="",INDEX(Assumptions!$B$8:$B$33,MATCH($A5,Assumptions!$A$8:$A$33,0))=""),"",AO5*IFERROR(INDEX(Assumptions!$B$8:$B$33,MATCH(Assumptions!$B$5,Assumptions!$A$8:$A$33,0)),"")/INDEX(Assumptions!$B$8:$B$33,MATCH($A5,Assumptions!$A$8:$A$33,0))),"")
A6: 2001 | B6: =COUNTIFS(Data!$A$2:$A$1006,$A6,Data!$C$2:$C$1006,"FirstEnergy") -> 10 | C6: =SUMIFS(Data!$L$2:$L$1006,Data!$A$2:$A$1006,$A6,Data!$C$2:$C$1006,"FirstEnergy") -> 5786092 | D6: =SUMIFS(Data!$E$2:$E$1006,Data!$A$2:$A$1006,$A6,Data!$C$2:$C$1006,"FirstEnergy") -> 452.72893 | E6: =SUMIFS(Data!$F$2:$F$1006,Data!$A$2:$A$1006,$A6,Data!$C$2:$C$1006,"FirstEnergy") -> 296.75485 | F6: =SUMIFS(Data!$G$2:$G$1006,Data!$A$2:$A$1006,$A6,Data!$C$2:$C$1006,"FirstEnergy") -> 327.16523 | G6: =SUMIFS(Data!$N$2:$N$1006,Data!$A$2:$A$1006,$A6,Data!$C$2:$C$1006,"FirstEnergy") -> 1076.649 | H6: =SUMIFS(Data!$H$2:$H$1006,Data!$A$2:$A$1006,$A6,Data!$C$2:$C$1006,"FirstEnergy") -> 442.53223 | I6: =IFERROR(D6*1000000/C6,"") -> 78.244337 | J6: =IFERROR(E6*1000000/C6,"") -> 51.287613 | K6: =IFERROR(F6*1000000/C6,"") -> 56.543386 | L6: =IFERROR(G6*1000000/C6,"") -> 186.07534 | M6: =IFERROR(H6*1000000/C6,"") -> 76.48206 | N6: =IFERROR(IF(OR(IFERROR(INDEX(Assumptions!$B$8:$B$33,MATCH(Assumptions!$B$5,Assumptions!$A$8:$A$33,0)),"")="",INDEX(Assumptions!$B$8:$B$33,MATCH($A6,Assumptions!$A$8:$A$33,0))=""),"",L6*IFERROR(INDEX(Assumptions!$B$8:$B$33,MATCH(Assumptions!$B$5,Assumptions!$A$8:$A$33,0)),"")/INDEX(Assumptions!$B$8:$B$33,MATCH($A6,Assumptions!$A$8:$A$33,0))),"") | O6: =IFERROR(IF(OR(IFERROR(INDEX(Assumptions!$B$8:$B$33,MATCH(Assumptions!$B$5,Assumptions!$A$8:$A$33,0)),"")="",INDEX(Assumptions!$B$8:$B$33,MATCH($A6,Assumptions!$A$8:$A$33,0))=""),"",M6*IFERROR(INDEX(Assumptions!$B$8:$B$33,MATCH(Assumptions!$B$5,Assumptions!$A$8:$A$33,0)),"")/INDEX(Assumptions!$B$8:$B$33,MATCH($A6,Assumptions!$A$8:$A$33,0))),"") | P6: =COUNTIFS(Data!$A$2:$A$1006,$A6,Data!$C$2:$C$1006,"Northeast peers") -> 12 | Q6: =SUMIFS(Data!$L$2:$L$1006,Data!$A$2:$A$1006,$A6,Data!$C$2:$C$1006,"Northeast peers") -> 11714513 | R6: =SUMIFS(Data!$E$2:$E$1006,Data!$A$2:$A$1006,$A6,Data!$C$2:$C$1006,"Northeast peers") -> 969.73855 | S6: =SUMIFS(Data!$F$2:$F$1006,Data!$A$2:$A$1006,$A6,Data!$C$2:$C$1006,"Northeast peers") -> 836.00108 | T6: =SUMIFS(Data!$G$2:$G$1006,Data!$A$2:$A$1006,$A6,Data!$C$2:$C$1006,"Northeast peers") -> 660.32343 | U6: =SUMIFS(Data!$N$2:$N$1006,Data!$A$2:$A$1006,$A6,Data!$C$2:$C$1006,"Northeast peers") -> 2466.0631 | V6: =SUMIFS(Data!$H$2:$H$1006,Data!$A$2:$A$1006,$A6,Data!$C$2:$C$1006,"Northeast peers") -> 1187.3893 | W6: =IFERROR(R6*1000000/Q6,"") -> 82.780953 | X6: =IFERROR(S6*1000000/Q6,"") -> 71.364561 | Y6: =IFERROR(T6*1000000/Q6,"") -> 56.367979 | Z6: =IFERROR(U6*1000000/Q6,"") -> 210.51349 | AA6: =IFERROR(V6*1000000/Q6,"") -> 101.36054 | AB6: =IFERROR(IF(OR(IFERROR(INDEX(Assumptions!$B$8:$B$33,MATCH(Assumptions!$B$5,Assumptions!$A$8:$A$33,0)),"")="",INDEX(Assumptions!$B$8:$B$33,MATCH($A6,Assumptions!$A$8:$A$33,0))=""),"",Z6*IFERROR(INDEX(Assumptions!$B$8:$B$33,MATCH(Assumptions!$B$5,Assumptions!$A$8:$A$33,0)),"")/INDEX(Assumptions!$B$8:$B$33,MATCH($A6,Assumptions!$A$8:$A$33,0))),"") | AC6: =IFERROR(IF(OR(IFERROR(INDEX(Assumptions!$B$8:$B$33,MATCH(Assumptions!$B$5,Assumptions!$A$8:$A$33,0)),"")="",INDEX(Assumptions!$B$8:$B$33,MATCH($A6,Assumptions!$A$8:$A$33,0))=""),"",AA6*IFERROR(INDEX(Assumptions!$B$8:$B$33,MATCH(Assumptions!$B$5,Assumptions!$A$8:$A$33,0)),"")/INDEX(Assumptions!$B$8:$B$33,MATCH($A6,Assumptions!$A$8:$A$33,0))),"") | AD6: =COUNTIFS(Data!$A$2:$A$1006,$A6,Data!$C$2:$C$1006,"Midwest peers") -> 17 | AE6: =SUMIFS(Data!$L$2:$L$1006,Data!$A$2:$A$1006,$A6,Data!$C$2:$C$1006,"Midwest peers") -> 11041374 | AF6: =SUMIFS(Data!$E$2:$E$1006,Data!$A$2:$A$1006,$A6,Data!$C$2:$C$1006,"Midwest peers") -> 803.54397 | AG6: =SUMIFS(Data!$F$2:$F$1006,Data!$A$2:$A$1006,$A6,Data!$C$2:$C$1006,"Midwest peers") -> 678.32759 | AH6: =SUMIFS(Data!$G$2:$G$1006,Data!$A$2:$A$1006,$A6,Data!$C$2:$C$1006,"Midwest peers") -> 763.99208 | AI6: =SUMIFS(Data!$N$2:$N$1006,Data!$A$2:$A$1006,$A6,Data!$C$2:$C$1006,"Midwest peers") -> 2245.8636 | AJ6: =SUMIFS(Data!$H$2:$H$1006,Data!$A$2:$A$1006,$A6,Data!$C$2:$C$1006,"Midwest peers") -> 1238.9469 | AK6: =IFERROR(AF6*1000000/AE6,"") -> 72.775723 | AL6: =IFERROR(AG6*1000000/AE6,"") -> 61.435071 | AM6: =IFERROR(AH6*1000000/AE6,"") -> 69.19357 | AN6: =IFERROR(AI6*1000000/AE6,"") -> 203.40436 | AO6: =IFERROR(AJ6*1000000/AE6,"") -> 112.20949 | AP6: =IFERROR(IF(OR(IFERROR(INDEX(Assumptions!$B$8:$B$33,MATCH(Assumptions!$B$5,Assumptions!$A$8:$A$33,0)),"")="",INDEX(Assumptions!$B$8:$B$33,MATCH($A6,Assumptions!$A$8:$A$33,0))=""),"",AN6*IFERROR(INDEX(Assumptions!$B$8:$B$33,MATCH(Assumptions!$B$5,Assumptions!$A$8:$A$33,0)),"")/INDEX(Assumptions!$B$8:$B$33,MATCH($A6,Assumptions!$A$8:$A$33,0))),"") | AQ6: =IFERROR(IF(OR(IFERROR(INDEX(Assumptions!$B$8:$B$33,MATCH(Assumptions!$B$5,Assumptions!$A$8:$A$33,0)),"")="",INDEX(Assumptions!$B$8:$B$33,MATCH($A6,Assumptions!$A$8:$A$33,0))=""),"",AO6*IFERROR(INDEX(Assumptions!$B$8:$B$33,MATCH(Assumptions!$B$5,Assumptions!$A$8:$A$33,0)),"")/INDEX(Assumptions!$B$8:$B$33,MATCH($A6,Assumptions!$A$8:$A$33,0))),"")
A7: 2002 | B7: =COUNTIFS(Data!$A$2:$A$1006,$A7,Data!$C$2:$C$1006,"FirstEnergy") -> 10 | C7: =SUMIFS(Data!$L$2:$L$1006,Data!$A$2:$A$1006,$A7,Data!$C$2:$C$1006,"FirstEnergy") -> 5849398 | D7: =SUMIFS(Data!$E$2:$E$1006,Data!$A$2:$A$1006,$A7,Data!$C$2:$C$1006,"FirstEnergy") -> 445.09164 | E7: =SUMIFS(Data!$F$2:$F$1006,Data!$A$2:$A$1006,$A7,Data!$C$2:$C$1006,"FirstEnergy") -> 256.53968 | F7: =SUMIFS(Data!$G$2:$G$1006,Data!$A$2:$A$1006,$A7,Data!$C$2:$C$1006,"FirstEnergy") -> 325.16668 | G7: =SUMIFS(Data!$N$2:$N$1006,Data!$A$2:$A$1006,$A7,Data!$C$2:$C$1006,"FirstEnergy") -> 1026.798 | H7: =SUMIFS(Data!$H$2:$H$1006,Data!$A$2:$A$1006,$A7,Data!$C$2:$C$1006,"FirstEnergy") -> 410.86825 | I7: =IFERROR(D7*1000000/C7,"") -> 76.091871 | J7: =IFERROR(E7*1000000/C7,"") -> 43.85745 | K7: =IFERROR(F7*1000000/C7,"") -> 55.589768 | L7: =IFERROR(G7*1000000/C7,"") -> 175.53909 | M7: =IFERROR(H7*1000000/C7,"") -> 70.241116 | N7: =IFERROR(IF(OR(IFERROR(INDEX(Assumptions!$B$8:$B$33,MATCH(Assumptions!$B$5,Assumptions!$A$8:$A$33,0)),"")="",INDEX(Assumptions!$B$8:$B$33,MATCH($A7,Assumptions!$A$8:$A$33,0))=""),"",L7*IFERROR(INDEX(Assumptions!$B$8:$B$33,MATCH(Assumptions!$B$5,Assumptions!$A$8:$A$33,0)),"")/INDEX(Assumptions!$B$8:$B$33,MATCH($A7,Assumptions!$A$8:$A$33,0))),"") | O7: =IFERROR(IF(OR(IFERROR(INDEX(Assumptions!$B$8:$B$33,MATCH(Assumptions!$B$5,Assumptions!$A$8:$A$33,0)),"")="",INDEX(Assumptions!$B$8:$B$33,MATCH($A7,Assumptions!$A$8:$A$33,0))=""),"",M7*IFERROR(INDEX(Assumptions!$B$8:$B$33,MATCH(Assumptions!$B$5,Assumptions!$A$8:$A$33,0)),"")/INDEX(Assumptions!$B$8:$B$33,MATCH($A7,Assumptions!$A$8:$A$33,0))),"") | P7: =COUNTIFS(Data!$A$2:$A$1006,$A7,Data!$C$2:$C$1006,"Northeast peers") -> 12 | Q7: =SUMIFS(Data!$L$2:$L$1006,Data!$A$2:$A$1006,$A7,Data!$C$2:$C$1006,"Northeast peers") -> 11803407 | R7: =SUMIFS(Data!$E$2:$E$1006,Data!$A$2:$A$1006,$A7,Data!$C$2:$C$1006,"Northeast peers") -> 875.25374 | S7: =SUMIFS(Data!$F$2:$F$1006,Data!$A$2:$A$1006,$A7,Data!$C$2:$C$1006,"Northeast peers") -> 812.63265 | T7: =SUMIFS(Data!$G$2:$G$1006,Data!$A$2:$A$1006,$A7,Data!$C$2:$C$1006,"Northeast peers") -> 663.27585 | U7: =SUMIFS(Data!$N$2:$N$1006,Data!$A$2:$A$1006,$A7,Data!$C$2:$C$1006,"Northeast peers") -> 2351.1622 | V7: =SUMIFS(Data!$H$2:$H$1006,Data!$A$2:$A$1006,$A7,Data!$C$2:$C$1006,"Northeast peers") -> 1221.4337 | W7: =IFERROR(R7*1000000/Q7,"") -> 74.152635 | X7: =IFERROR(S7*1000000/Q7,"") -> 68.847295 | Y7: =IFERROR(T7*1000000/Q7,"") -> 56.193593 | Z7: =IFERROR(U7*1000000/Q7,"") -> 199.19352 | AA7: =IFERROR(V7*1000000/Q7,"") -> 103.48145 | AB7: =IFERROR(IF(OR(IFERROR(INDEX(Assumptions!$B$8:$B$33,MATCH(Assumptions!$B$5,Assumptions!$A$8:$A$33,0)),"")="",INDEX(Assumptions!$B$8:$B$33,MATCH($A7,Assumptions!$A$8:$A$33,0))=""),"",Z7*IFERROR(INDEX(Assumptions!$B$8:$B$33,MATCH(Assumptions!$B$5,Assumptions!$A$8:$A$33,0)),"")/INDEX(Assumptions!$B$8:$B$33,MATCH($A7,Assumptions!$A$8:$A$33,0))),"") | AC7: =IFERROR(IF(OR(IFERROR(INDEX(Assumptions!$B$8:$B$33,MATCH(Assumptions!$B$5,Assumptions!$A$8:$A$33,0)),"")="",INDEX(Assumptions!$B$8:$B$33,MATCH($A7,Assumptions!$A$8:$A$33,0))=""),"",AA7*IFERROR(INDEX(Assumptions!$B$8:$B$33,MATCH(Assumptions!$B$5,Assumptions!$A$8:$A$33,0)),"")/INDEX(Assumptions!$B$8:$B$33,MATCH($A7,Assumptions!$A$8:$A$33,0))),"") | AD7: =COUNTIFS(Data!$A$2:$A$1006,$A7,Data!$C$2:$C$1006,"Midwest peers") -> 16 | AE7: =SUMIFS(Data!$L$2:$L$1006,Data!$A$2:$A$1006,$A7,Data!$C$2:$C$1006,"Midwest peers") -> 9450554 | AF7: =SUMIFS(Data!$E$2:$E$1006,Data!$A$2:$A$1006,$A7,Data!$C$2:$C$1006,"Midwest peers") -> 696.7392 | AG7: =SUMIFS(Data!$F$2:$F$1006,Data!$A$2:$A$1006,$A7,Data!$C$2:$C$1006,"Midwest peers") -> 656.57887 | AH7: =SUMIFS(Data!$G$2:$G$1006,Data!$A$2:$A$1006,$A7,Data!$C$2:$C$1006,"Midwest peers") -> 687.41818 | AI7: =SUMIFS(Data!$N$2:$N$1006,Data!$A$2:$A$1006,$A7,Data!$C$2:$C$1006,"Midwest peers") -> 2040.7363 | AJ7: =SUMIFS(Data!$H$2:$H$1006,Data!$A$2:$A$1006,$A7,Data!$C$2:$C$1006,"Midwest peers") -> 1073.9155 | AK7: =IFERROR(AF7*1000000/AE7,"") -> 73.724694 | AL7: =IFERROR(AG7*1000000/AE7,"") -> 69.475173 | AM7: =IFERROR(AH7*1000000/AE7,"") -> 72.7384 | AN7: =IFERROR(AI7*1000000/AE7,"") -> 215.93827 | AO7: =IFERROR(AJ7*1000000/AE7,"") -> 113.63519 | AP7: =IFERROR(IF(OR(IFERROR(INDEX(Assumptions!$B$8:$B$33,MATCH(Assumptions!$B$5,Assumptions!$A$8:$A$33,0)),"")="",INDEX(Assumptions!$B$8:$B$33,MATCH($A7,Assumptions!$A$8:$A$33,0))=""),"",AN7*IFERROR(INDEX(Assumptions!$B$8:$B$33,MATCH(Assumptions!$B$5,Assumptions!$A$8:$A$33,0)),"")/INDEX(Assumptions!$B$8:$B$33,MATCH($A7,Assumptions!$A$8:$A$33,0))),"") | AQ7: =IFERROR(IF(OR(IFERROR(INDEX(Assumptions!$B$8:$B$33,MATCH(Assumptions!$B$5,Assumptions!$A$8:$A$33,0)),"")="",INDEX(Assumptions!$B$8:$B$33,MATCH($A7,Assumptions!$A$8:$A$33,0))=""),"",AO7*IFERROR(INDEX(Assumptions!$B$8:$B$33,MATCH(Assumptions!$B$5,Assumptions!$A$8:$A$33,0)),"")/INDEX(Assumptions!$B$8:$B$33,MATCH($A7,Assumptions!$A$8:$A$33,0))),"")
A8: 2003 | B8: =COUNTIFS(Data!$A$2:$A$1006,$A8,Data!$C$2:$C$1006,"FirstEnergy") -> 10 | C8: =SUMIFS(Data!$L$2:$L$1006,Data!$A$2:$A$1006,$A8,Data!$C$2:$C$1006,"FirstEnergy") -> 5895460 | D8: =SUMIFS(Data!$E$2:$E$1006,Data!$A$2:$A$1006,$A8,Data!$C$2:$C$1006,"FirstEnergy") -> 534.36972 | E8: =SUMIFS(Data!$F$2:$F$1006,Data!$A$2:$A$1006,$A8,Data!$C$2:$C$1006,"FirstEnergy") -> 312.91545 | F8: =SUMIFS(Data!$G$2:$G$1006,Data!$A$2:$A$1006,$A8,Data!$C$2:$C$1006,"FirstEnergy") -> 311.47871 | G8: =SUMIFS(Data!$N$2:$N$1006,Data!$A$2:$A$1006,$A8,Data!$C$2:$C$1006,"FirstEnergy") -> 1158.7639 | H8: =SUMIFS(Data!$H$2:$H$1006,Data!$A$2:$A$1006,$A8,Data!$C$2:$C$1006,"FirstEnergy") -> 448.41531 | I8: =IFERROR(D8*1000000/C8,"") -> 90.640887 | J8: =IFERROR(E8*1000000/C8,"") -> 53.07736 | K8: =IFERROR(F8*1000000/C8,"") -> 52.833656 | L8: =IFERROR(G8*1000000/C8,"") -> 196.5519 | M8: =IFERROR(H8*1000000/C8,"") -> 76.061123 | N8: =IFERROR(IF(OR(IFERROR(INDEX(Assumptions!$B$8:$B$33,MATCH(Assumptions!$B$5,Assumptions!$A$8:$A$33,0)),"")="",INDEX(Assumptions!$B$8:$B$33,MATCH($A8,Assumptions!$A$8:$A$33,0))=""),"",L8*IFERROR(INDEX(Assumptions!$B$8:$B$33,MATCH(Assumptions!$B$5,Assumptions!$A$8:$A$33,0)),"")/INDEX(Assumptions!$B$8:$B$33,MATCH($A8,Assumptions!$A$8:$A$33,0))),"") | O8: =IFERROR(IF(OR(IFERROR(INDEX(Assumptions!$B$8:$B$33,MATCH(Assumptions!$B$5,Assumptions!$A$8:$A$33,0)),"")="",INDEX(Assumptions!$B$8:$B$33,MATCH($A8,Assumptions!$A$8:$A$33,0))=""),"",M8*IFERROR(INDEX(Assumptions!$B$8:$B$33,MATCH(Assumptions!$B$5,Assumptions!$A$8:$A$33,0)),"")/INDEX(Assumptions!$B$8:$B$33,MATCH($A8,Assumptions!$A$8:$A$33,0))),"") | P8: =COUNTIFS(Data!$A$2:$A$1006,$A8,Data!$C$2:$C$1006,"Northeast peers") -> 12 | Q8: =SUMIFS(Data!$L$2:$L$1006,Data!$A$2:$A$1006,$A8,Data!$C$2:$C$1006,"Northeast peers") -> 11891572 | R8: =SUMIFS(Data!$E$2:$E$1006,Data!$A$2:$A$1006,$A8,Data!$C$2:$C$1006,"Northeast peers") -> 987.18704 | S8: =SUMIFS(Data!$F$2:$F$1006,Data!$A$2:$A$1006,$A8,Data!$C$2:$C$1006,"Northeast peers") -> 769.72625 | T8: =SUMIFS(Data!$G$2:$G$1006,Data!$A$2:$A$1006,$A8,Data!$C$2:$C$1006,"Northeast peers") -> 655.78689 | U8: =SUMIFS(Data!$N$2:$N$1006,Data!$A$2:$A$1006,$A8,Data!$C$2:$C$1006,"Northeast peers") -> 2412.7002 | V8: =SUMIFS(Data!$H$2:$H$1006,Data!$A$2:$A$1006,$A8,Data!$C$2:$C$1006,"Northeast peers") -> 1291.3414 | W8: =IFERROR(R8*1000000/Q8,"") -> 83.015689 | X8: =IFERROR(S8*1000000/Q8,"") -> 64.728721 | Y8: =IFERROR(T8*1000000/Q8,"") -> 55.147199 | Z8: =IFERROR(U8*1000000/Q8,"") -> 202.89161 | AA8: =IFERROR(V8*1000000/Q8,"") -> 108.59299 | AB8: =IFERROR(IF(OR(IFERROR(INDEX(Assumptions!$B$8:$B$33,MATCH(Assumptions!$B$5,Assumptions!$A$8:$A$33,0)),"")="",INDEX(Assumptions!$B$8:$B$33,MATCH($A8,Assumptions!$A$8:$A$33,0))=""),"",Z8*IFERROR(INDEX(Assumptions!$B$8:$B$33,MATCH(Assumptions!$B$5,Assumptions!$A$8:$A$33,0)),"")/INDEX(Assumptions!$B$8:$B$33,MATCH($A8,Assumptions!$A$8:$A$33,0))),"") | AC8: =IFERROR(IF(OR(IFERROR(INDEX(Assumptions!$B$8:$B$33,MATCH(Assumptions!$B$5,Assumptions!$A$8:$A$33,0)),"")="",INDEX(Assumptions!$B$8:$B$33,MATCH($A8,Assumptions!$A$8:$A$33,0))=""),"",AA8*IFERROR(INDEX(Assumptions!$B$8:$B$33,MATCH(Assumptions!$B$5,Assumptions!$A$8:$A$33,0)),"")/INDEX(Assumptions!$B$8:$B$33,MATCH($A8,Assumptions!$A$8:$A$33,0))),"") | AD8: =COUNTIFS(Data!$A$2:$A$1006,$A8,Data!$C$2:$C$1006,"Midwest peers") -> 16 | AE8: =SUMIFS(Data!$L$2:$L$1006,Data!$A$2:$A$1006,$A8,Data!$C$2:$C$1006,"Midwest peers") -> 9532900 | AF8: =SUMIFS(Data!$E$2:$E$1006,Data!$A$2:$A$1006,$A8,Data!$C$2:$C$1006,"Midwest peers") -> 741.83681 | AG8: =SUMIFS(Data!$F$2:$F$1006,Data!$A$2:$A$1006,$A8,Data!$C$2:$C$1006,"Midwest peers") -> 668.28068 | AH8: =SUMIFS(Data!$G$2:$G$1006,Data!$A$2:$A$1006,$A8,Data!$C$2:$C$1006,"Midwest peers") -> 717.66696 | AI8: =SUMIFS(Data!$N$2:$N$1006,Data!$A$2:$A$1006,$A8,Data!$C$2:$C$1006,"Midwest peers") -> 2127.7845 | AJ8: =SUMIFS(Data!$H$2:$H$1006,Data!$A$2:$A$1006,$A8,Data!$C$2:$C$1006,"Midwest peers") -> 1150.2861 | AK8: =IFERROR(AF8*1000000/AE8,"") -> 77.818587 | AL8: =IFERROR(AG8*1000000/AE8,"") -> 70.102559 | AM8: =IFERROR(AH8*1000000/AE8,"") -> 75.283173 | AN8: =IFERROR(AI8*1000000/AE8,"") -> 223.20432 | AO8: =IFERROR(AJ8*1000000/AE8,"") -> 120.66487 | AP8: =IFERROR(IF(OR(IFERROR(INDEX(Assumptions!$B$8:$B$33,MATCH(Assumptions!$B$5,Assumptions!$A$8:$A$33,0)),"")="",INDEX(Assumptions!$B$8:$B$33,MATCH($A8,Assumptions!$A$8:$A$33,0))=""),"",AN8*IFERROR(INDEX(Assumptions!$B$8:$B$33,MATCH(Assumptions!$B$5,Assumptions!$A$8:$A$33,0)),"")/INDEX(Assumptions!$B$8:$B$33,MATCH($A8,Assumptions!$A$8:$A$33,0))),"") | AQ8: =IFERROR(IF(OR(IFERROR(INDEX(Assumptions!$B$8:$B$33,MATCH(Assumptions!$B$5,Assumptions!$A$8:$A$33,0)),"")="",INDEX(Assumptions!$B$8:$B$33,MATCH($A8,Assumptions!$A$8:$A$33,0))=""),"",AO8*IFERROR(INDEX(Assumptions!$B$8:$B$33,MATCH(Assumptions!$B$5,Assumptions!$A$8:$A$33,0)),"")/INDEX(Assumptions!$B$8:$B$33,MATCH($A8,Assumptions!$A$8:$A$33,0))),"")
A9: 2004 | B9: =COUNTIFS(Data!$A$2:$A$1006,$A9,Data!$C$2:$C$1006,"FirstEnergy") -> 10 | C9: =SUMIFS(Data!$L$2:$L$1006,Data!$A$2:$A$1006,$A9,Data!$C$2:$C$1006,"FirstEnergy") -> 5941310 | D9: =SUMIFS(Data!$E$2:$E$1006,Data!$A$2:$A$1006,$A9,Data!$C$2:$C$1006,"FirstEnergy") -> 447.37982 | E9: =SUMIFS(Data!$F$2:$F$1006,Data!$A$2:$A$1006,$A9,Data!$C$2:$C$1006,"FirstEnergy") -> 304.58678 | F9: =SUMIFS(Data!$G$2:$G$1006,Data!$A$2:$A$1006,$A9,Data!$C$2:$C$1006,"FirstEnergy") -> 301.89728 | G9: =SUMIFS(Data!$N$2:$N$1006,Data!$A$2:$A$1006,$A9,Data!$C$2:$C$1006,"FirstEnergy") -> 1053.8639 | H9: =SUMIFS(Data!$H$2:$H$1006,Data!$A$2:$A$1006,$A9,Data!$C$2:$C$1006,"FirstEnergy") -> 517.7844 | I9: =IFERROR(D9*1000000/C9,"") -> 75.299862 | J9: =IFERROR(E9*1000000/C9,"") -> 51.265929 | K9: =IFERROR(F9*1000000/C9,"") -> 50.813252 | L9: =IFERROR(G9*1000000/C9,"") -> 177.37904 | M9: =IFERROR(H9*1000000/C9,"") -> 87.14987 | N9: =IFERROR(IF(OR(IFERROR(INDEX(Assumptions!$B$8:$B$33,MATCH(Assumptions!$B$5,Assumptions!$A$8:$A$33,0)),"")="",INDEX(Assumptions!$B$8:$B$33,MATCH($A9,Assumptions!$A$8:$A$33,0))=""),"",L9*IFERROR(INDEX(Assumptions!$B$8:$B$33,MATCH(Assumptions!$B$5,Assumptions!$A$8:$A$33,0)),"")/INDEX(Assumptions!$B$8:$B$33,MATCH($A9,Assumptions!$A$8:$A$33,0))),"") | O9: =IFERROR(IF(OR(IFERROR(INDEX(Assumptions!$B$8:$B$33,MATCH(Assumptions!$B$5,Assumptions!$A$8:$A$33,0)),"")="",INDEX(Assumptions!$B$8:$B$33,MATCH($A9,Assumptions!$A$8:$A$33,0))=""),"",M9*IFERROR(INDEX(Assumptions!$B$8:$B$33,MATCH(Assumptions!$B$5,Assumptions!$A$8:$A$33,0)),"")/INDEX(Assumptions!$B$8:$B$33,MATCH($A9,Assumptions!$A$8:$A$33,0))),"") | P9: =COUNTIFS(Data!$A$2:$A$1006,$A9,Data!$C$2:$C$1006,"Northeast peers") -> 12 | Q9: =SUMIFS(Data!$L$2:$L$1006,Data!$A$2:$A$1006,$A9,Data!$C$2:$C$1006,"Northeast peers") -> 12007423 | R9: =SUMIFS(Data!$E$2:$E$1006,Data!$A$2:$A$1006,$A9,Data!$C$2:$C$1006,"Northeast peers") -> 967.47299 | S9: =SUMIFS(Data!$F$2:$F$1006,Data!$A$2:$A$1006,$A9,Data!$C$2:$C$1006,"Northeast peers") -> 775.39309 | T9: =SUMIFS(Data!$G$2:$G$1006,Data!$A$2:$A$1006,$A9,Data!$C$2:$C$1006,"Northeast peers") -> 827.77558 | U9: =SUMIFS(Data!$N$2:$N$1006,Data!$A$2:$A$1006,$A9,Data!$C$2:$C$1006,"Northeast peers") -> 2570.6417 | V9: =SUMIFS(Data!$H$2:$H$1006,Data!$A$2:$A$1006,$A9,Data!$C$2:$C$1006,"Northeast peers") -> 1212.0515 | W9: =IFERROR(R9*1000000/Q9,"") -> 80.572908 | X9: =IFERROR(S9*1000000/Q9,"") -> 64.576145 | Y9: =IFERROR(T9*1000000/Q9,"") -> 68.938654 | Z9: =IFERROR(U9*1000000/Q9,"") -> 214.08771 | AA9: =IFERROR(V9*1000000/Q9,"") -> 100.94185 | AB9: =IFERROR(IF(OR(IFERROR(INDEX(Assumptions!$B$8:$B$33,MATCH(Assumptions!$B$5,Assumptions!$A$8:$A$33,0)),"")="",INDEX(Assumptions!$B$8:$B$33,MATCH($A9,Assumptions!$A$8:$A$33,0))=""),"",Z9*IFERROR(INDEX(Assumptions!$B$8:$B$33,MATCH(Assumptions!$B$5,Assumptions!$A$8:$A$33,0)),"")/INDEX(Assumptions!$B$8:$B$33,MATCH($A9,Assumptions!$A$8:$A$33,0))),"") | AC9: =IFERROR(IF(OR(IFERROR(INDEX(Assumptions!$B$8:$B$33,MATCH(Assumptions!$B$5,Assumptions!$A$8:$A$33,0)),"")="",INDEX(Assumptions!$B$8:$B$33,MATCH($A9,Assumptions!$A$8:$A$33,0))=""),"",AA9*IFERROR(INDEX(Assumptions!$B$8:$B$33,MATCH(Assumptions!$B$5,Assumptions!$A$8:$A$33,0)),"")/INDEX(Assumptions!$B$8:$B$33,MATCH($A9,Assumptions!$A$8:$A$33,0))),"") | AD9: =COUNTIFS(Data!$A$2:$A$1006,$A9,Data!$C$2:$C$1006,"Midwest peers") -> 16 | AE9: =SUMIFS(Data!$L$2:$L$1006,Data!$A$2:$A$1006,$A9,Data!$C$2:$C$1006,"Midwest peers") -> 9630221 | AF9: =SUMIFS(Data!$E$2:$E$1006,Data!$A$2:$A$1006,$A9,Data!$C$2:$C$1006,"Midwest peers") -> 732.37506 | AG9: =SUMIFS(Data!$F$2:$F$1006,Data!$A$2:$A$1006,$A9,Data!$C$2:$C$1006,"Midwest peers") -> 664.23152 | AH9: =SUMIFS(Data!$G$2:$G$1006,Data!$A$2:$A$1006,$A9,Data!$C$2:$C$1006,"Midwest peers") -> 756.00234 | AI9: =SUMIFS(Data!$N$2:$N$1006,Data!$A$2:$A$1006,$A9,Data!$C$2:$C$1006,"Midwest peers") -> 2152.6089 | AJ9: =SUMIFS(Data!$H$2:$H$1006,Data!$A$2:$A$1006,$A9,Data!$C$2:$C$1006,"Midwest peers") -> 1256.0857 | AK9: =IFERROR(AF9*1000000/AE9,"") -> 76.049663 | AL9: =IFERROR(AG9*1000000/AE9,"") -> 68.973653 | AM9: =IFERROR(AH9*1000000/AE9,"") -> 78.503114 | AN9: =IFERROR(AI9*1000000/AE9,"") -> 223.52643 | AO9: =IFERROR(AJ9*1000000/AE9,"") -> 130.43166 | AP9: =IFERROR(IF(OR(IFERROR(INDEX(Assumptions!$B$8:$B$33,MATCH(Assumptions!$B$5,Assumptions!$A$8:$A$33,0)),"")="",INDEX(Assumptions!$B$8:$B$33,MATCH($A9,Assumptions!$A$8:$A$33,0))=""),"",AN9*IFERROR(INDEX(Assumptions!$B$8:$B$33,MATCH(Assumptions!$B$5,Assumptions!$A$8:$A$33,0)),"")/INDEX(Assumptions!$B$8:$B$33,MATCH($A9,Assumptions!$A$8:$A$33,0))),"") | AQ9: =IFERROR(IF(OR(IFERROR(INDEX(Assumptions!$B$8:$B$33,MATCH(Assumptions!$B$5,Assumptions!$A$8:$A$33,0)),"")="",INDEX(Assumptions!$B$8:$B$33,MATCH($A9,Assumptions!$A$8:$A$33,0))=""),"",AO9*IFERROR(INDEX(Assumptions!$B$8:$B$33,MATCH(Assumptions!$B$5,Assumptions!$A$8:$A$33,0)),"")/INDEX(Assumptions!$B$8:$B$33,MATCH($A9,Assumptions!$A$8:$A$33,0))),"")
A10: 2005 | B10: =COUNTIFS(Data!$A$2:$A$1006,$A10,Data!$C$2:$C$1006,"FirstEnergy") -> 10 | C10: =SUMIFS(Data!$L$2:$L$1006,Data!$A$2:$A$1006,$A10,Data!$C$2:$C$1006,"FirstEnergy") -> 6008786 | D10: =SUMIFS(Data!$E$2:$E$1006,Data!$A$2:$A$1006,$A10,Data!$C$2:$C$1006,"FirstEnergy") -> 471.66532 | E10: =SUMIFS(Data!$F$2:$F$1006,Data!$A$2:$A$1006,$A10,Data!$C$2:$C$1006,"FirstEnergy") -> 346.40929 | F10: =SUMIFS(Data!$G$2:$G$1006,Data!$A$2:$A$1006,$A10,Data!$C$2:$C$1006,"FirstEnergy") -> 315.65434 | G10: =SUMIFS(Data!$N$2:$N$1006,Data!$A$2:$A$1006,$A10,Data!$C$2:$C$1006,"FirstEnergy") -> 1133.7289 | H10: =SUMIFS(Data!$H$2:$H$1006,Data!$A$2:$A$1006,$A10,Data!$C$2:$C$1006,"FirstEnergy") -> 680.83121 | I10: =IFERROR(D10*1000000/C10,"") -> 78.495942 | J10: =IFERROR(E10*1000000/C10,"") -> 57.650463 | K10: =IFERROR(F10*1000000/C10,"") -> 52.532131 | L10: =IFERROR(G10*1000000/C10,"") -> 188.67854 | M10: =IFERROR(H10*1000000/C10,"") -> 113.30595 | N10: =IFERROR(IF(OR(IFERROR(INDEX(Assumptions!$B$8:$B$33,MATCH(Assumptions!$B$5,Assumptions!$A$8:$A$33,0)),"")="",INDEX(Assumptions!$B$8:$B$33,MATCH($A10,Assumptions!$A$8:$A$33,0))=""),"",L10*IFERROR(INDEX(Assumptions!$B$8:$B$33,MATCH(Assumptions!$B$5,Assumptions!$A$8:$A$33,0)),"")/INDEX(Assumptions!$B$8:$B$33,MATCH($A10,Assumptions!$A$8:$A$33,0))),"") | O10: =IFERROR(IF(OR(IFERROR(INDEX(Assumptions!$B$8:$B$33,MATCH(Assumptions!$B$5,Assumptions!$A$8:$A$33,0)),"")="",INDEX(Assumptions!$B$8:$B$33,MATCH($A10,Assumptions!$A$8:$A$33,0))=""),"",M10*IFERROR(INDEX(Assumptions!$B$8:$B$33,MATCH(Assumptions!$B$5,Assumptions!$A$8:$A$33,0)),"")/INDEX(Assumptions!$B$8:$B$33,MATCH($A10,Assumptions!$A$8:$A$33,0))),"") | P10: =COUNTIFS(Data!$A$2:$A$1006,$A10,Data!$C$2:$C$1006,"Northeast peers") -> 12 | Q10: =SUMIFS(Data!$L$2:$L$1006,Data!$A$2:$A$1006,$A10,Data!$C$2:$C$1006,"Northeast peers") -> 12105214 | R10: =SUMIFS(Data!$E$2:$E$1006,Data!$A$2:$A$1006,$A10,Data!$C$2:$C$1006,"Northeast peers") -> 973.41842 | S10: =SUMIFS(Data!$F$2:$F$1006,Data!$A$2:$A$1006,$A10,Data!$C$2:$C$1006,"Northeast peers") -> 792.51232 | T10: =SUMIFS(Data!$G$2:$G$1006,Data!$A$2:$A$1006,$A10,Data!$C$2:$C$1006,"Northeast peers") -> 851.15631 | U10: =SUMIFS(Data!$N$2:$N$1006,Data!$A$2:$A$1006,$A10,Data!$C$2:$C$1006,"Northeast peers") -> 2617.087 | V10: =SUMIFS(Data!$H$2:$H$1006,Data!$A$2:$A$1006,$A10,Data!$C$2:$C$1006,"Northeast peers") -> 1428.0201 | W10: =IFERROR(R10*1000000/Q10,"") -> 80.413153 | X10: =IFERROR(S10*1000000/Q10,"") -> 65.468675 | Y10: =IFERROR(T10*1000000/Q10,"") -> 70.313198 | Z10: =IFERROR(U10*1000000/Q10,"") -> 216.19503 | AA10: =IFERROR(V10*1000000/Q10,"") -> 117.96736 | AB10: =IFERROR(IF(OR(IFERROR(INDEX(Assumptions!$B$8:$B$33,MATCH(Assumptions!$B$5,Assumptions!$A$8:$A$33,0)),"")="",INDEX(Assumptions!$B$8:$B$33,MATCH($A10,Assumptions!$A$8:$A$33,0))=""),"",Z10*IFERROR(INDEX(Assumptions!$B$8:$B$33,MATCH(Assumptions!$B$5,Assumptions!$A$8:$A$33,0)),"")/INDEX(Assumptions!$B$8:$B$33,MATCH($A10,Assumptions!$A$8:$A$33,0))),"") | AC10: =IFERROR(IF(OR(IFERROR(INDEX(Assumptions!$B$8:$B$33,MATCH(Assumptions!$B$5,Assumptions!$A$8:$A$33,0)),"")="",INDEX(Assumptions!$B$8:$B$33,MATCH($A10,Assumptions!$A$8:$A$33,0))=""),"",AA10*IFERROR(INDEX(Assumptions!$B$8:$B$33,MATCH(Assumptions!$B$5,Assumptions!$A$8:$A$33,0)),"")/INDEX(Assumptions!$B$8:$B$33,MATCH($A10,Assumptions!$A$8:$A$33,0))),"") | AD10: =COUNTIFS(Data!$A$2:$A$1006,$A10,Data!$C$2:$C$1006,"Midwest peers") -> 17 | AE10: =SUMIFS(Data!$L$2:$L$1006,Data!$A$2:$A$1006,$A10,Data!$C$2:$C$1006,"Midwest peers") -> 11556354 | AF10: =SUMIFS(Data!$E$2:$E$1006,Data!$A$2:$A$1006,$A10,Data!$C$2:$C$1006,"Midwest peers") -> 927.84981 | AG10: =SUMIFS(Data!$F$2:$F$1006,Data!$A$2:$A$1006,$A10,Data!$C$2:$C$1006,"Midwest peers") -> 758.04043 | AH10: =SUMIFS(Data!$G$2:$G$1006,Data!$A$2:$A$1006,$A10,Data!$C$2:$C$1006,"Midwest peers") -> 890.19774 | AI10: =SUMIFS(Data!$N$2:$N$1006,Data!$A$2:$A$1006,$A10,Data!$C$2:$C$1006,"Midwest peers") -> 2576.088 | AJ10: =SUMIFS(Data!$H$2:$H$1006,Data!$A$2:$A$1006,$A10,Data!$C$2:$C$1006,"Midwest peers") -> 1215.3361 | AK10: =IFERROR(AF10*1000000/AE10,"") -> 80.289148 | AL10: =IFERROR(AG10*1000000/AE10,"") -> 65.59512 | AM10: =IFERROR(AH10*1000000/AE10,"") -> 77.03102 | AN10: =IFERROR(AI10*1000000/AE10,"") -> 222.91529 | AO10: =IFERROR(AJ10*1000000/AE10,"") -> 105.16605 | AP10: =IFERROR(IF(OR(IFERROR(INDEX(Assumptions!$B$8:$B$33,MATCH(Assumptions!$B$5,Assumptions!$A$8:$A$33,0)),"")="",INDEX(Assumptions!$B$8:$B$33,MATCH($A10,Assumptions!$A$8:$A$33,0))=""),"",AN10*IFERROR(INDEX(Assumptions!$B$8:$B$33,MATCH(Assumptions!$B$5,Assumptions!$A$8:$A$33,0)),"")/INDEX(Assumptions!$B$8:$B$33,MATCH($A10,Assumptions!$A$8:$A$33,0))),"") | AQ10: =IFERROR(IF(OR(IFERROR(INDEX(Assumptions!$B$8:$B$33,MATCH(Assumptions!$B$5,Assumptions!$A$8:$A$33,0)),"")="",INDEX(Assumptions!$B$8:$B$33,MATCH($A10,Assumptions!$A$8:$A$33,0))=""),"",AO10*IFERROR(INDEX(Assumptions!$B$8:$B$33,MATCH(Assumptions!$B$5,Assumptions!$A$8:$A$33,0)),"")/INDEX(Assumptions!$B$8:$B$33,MATCH($A10,Assumptions!$A$8:$A$33,0))),"")
A11: 2006 | B11: =COUNTIFS(Data!$A$2:$A$1006,$A11,Data!$C$2:$C$1006,"FirstEnergy") -> 10 | C11: =SUMIFS(Data!$L$2:$L$1006,Data!$A$2:$A$1006,$A11,Data!$C$2:$C$1006,"FirstEnergy") -> 6027692 | D11: =SUMIFS(Data!$E$2:$E$1006,Data!$A$2:$A$1006,$A11,Data!$C$2:$C$1006,"FirstEnergy") -> 467.88616 | E11: =SUMIFS(Data!$F$2:$F$1006,Data!$A$2:$A$1006,$A11,Data!$C$2:$C$1006,"FirstEnergy") -> 351.45234 | F11: =SUMIFS(Data!$G$2:$G$1006,Data!$A$2:$A$1006,$A11,Data!$C$2:$C$1006,"FirstEnergy") -> 338.70169 | G11: =SUMIFS(Data!$N$2:$N$1006,Data!$A$2:$A$1006,$A11,Data!$C$2:$C$1006,"FirstEnergy") -> 1158.0402 | H11: =SUMIFS(Data!$H$2:$H$1006,Data!$A$2:$A$1006,$A11,Data!$C$2:$C$1006,"FirstEnergy") -> 678.01388 | I11: =IFERROR(D11*1000000/C11,"") -> 77.622771 | J11: =IFERROR(E11*1000000/C11,"") -> 58.306287 | K11: =IFERROR(F11*1000000/C11,"") -> 56.190942 | L11: =IFERROR(G11*1000000/C11,"") -> 192.12 | M11: =IFERROR(H11*1000000/C11,"") -> 112.48317 | N11: =IFERROR(IF(OR(IFERROR(INDEX(Assumptions!$B$8:$B$33,MATCH(Assumptions!$B$5,Assumptions!$A$8:$A$33,0)),"")="",INDEX(Assumptions!$B$8:$B$33,MATCH($A11,Assumptions!$A$8:$A$33,0))=""),"",L11*IFERROR(INDEX(Assumptions!$B$8:$B$33,MATCH(Assumptions!$B$5,Assumptions!$A$8:$A$33,0)),"")/INDEX(Assumptions!$B$8:$B$33,MATCH($A11,Assumptions!$A$8:$A$33,0))),"") | O11: =IFERROR(IF(OR(IFERROR(INDEX(Assumptions!$B$8:$B$33,MATCH(Assumptions!$B$5,Assumptions!$A$8:$A$33,0)),"")="",INDEX(Assumptions!$B$8:$B$33,MATCH($A11,Assumptions!$A$8:$A$33,0))=""),"",M11*IFERROR(INDEX(Assumptions!$B$8:$B$33,MATCH(Assumptions!$B$5,Assumptions!$A$8:$A$33,0)),"")/INDEX(Assumptions!$B$8:$B$33,MATCH($A11,Assumptions!$A$8:$A$33,0))),"") | P11: =COUNTIFS(Data!$A$2:$A$1006,$A11,Data!$C$2:$C$1006,"Northeast peers") -> 12 | Q11: =SUMIFS(Data!$L$2:$L$1006,Data!$A$2:$A$1006,$A11,Data!$C$2:$C$1006,"Northeast peers") -> 12195157 | R11: =SUMIFS(Data!$E$2:$E$1006,Data!$A$2:$A$1006,$A11,Data!$C$2:$C$1006,"Northeast peers") -> 1051.2267 | S11: =SUMIFS(Data!$F$2:$F$1006,Data!$A$2:$A$1006,$A11,Data!$C$2:$C$1006,"Northeast peers") -> 840.74935 | T11: =SUMIFS(Data!$G$2:$G$1006,Data!$A$2:$A$1006,$A11,Data!$C$2:$C$1006,"Northeast peers") -> 884.8069 | U11: =SUMIFS(Data!$N$2:$N$1006,Data!$A$2:$A$1006,$A11,Data!$C$2:$C$1006,"Northeast peers") -> 2776.783 | V11: =SUMIFS(Data!$H$2:$H$1006,Data!$A$2:$A$1006,$A11,Data!$C$2:$C$1006,"Northeast peers") -> 1721.5166 | W11: =IFERROR(R11*1000000/Q11,"") -> 86.200343 | X11: =IFERROR(S11*1000000/Q11,"") -> 68.941248 | Y11: =IFERROR(T11*1000000/Q11,"") -> 72.553958 | Z11: =IFERROR(U11*1000000/Q11,"") -> 227.69555 | AA11: =IFERROR(V11*1000000/Q11,"") -> 141.16395 | AB11: =IFERROR(IF(OR(IFERROR(INDEX(Assumptions!$B$8:$B$33,MATCH(Assumptions!$B$5,Assumptions!$A$8:$A$33,0)),"")="",INDEX(Assumptions!$B$8:$B$33,MATCH($A11,Assumptions!$A$8:$A$33,0))=""),"",Z11*IFERROR(INDEX(Assumptions!$B$8:$B$33,MATCH(Assumptions!$B$5,Assumptions!$A$8:$A$33,0)),"")/INDEX(Assumptions!$B$8:$B$33,MATCH($A11,Assumptions!$A$8:$A$33,0))),"") | AC11: =IFERROR(IF(OR(IFERROR(INDEX(Assumptions!$B$8:$B$33,MATCH(Assumptions!$B$5,Assumptions!$A$8:$A$33,0)),"")="",INDEX(Assumptions!$B$8:$B$33,MATCH($A11,Assumptions!$A$8:$A$33,0))=""),"",AA11*IFERROR(INDEX(Assumptions!$B$8:$B$33,MATCH(Assumptions!$B$5,Assumptions!$A$8:$A$33,0)),"")/INDEX(Assumptions!$B$8:$B$33,MATCH($A11,Assumptions!$A$8:$A$33,0))),"") | AD11: =COUNTIFS(Data!$A$2:$A$1006,$A11,Data!$C$2:$C$1006,"Midwest peers") -> 17 | AE11: =SUMIFS(Data!$L$2:$L$1006,Data!$A$2:$A$1006,$A11,Data!$C$2:$C$1006,"Midwest peers") -> 11551752 | AF11: =SUMIFS(Data!$E$2:$E$1006,Data!$A$2:$A$1006,$A11,Data!$C$2:$C$1006,"Midwest peers") -> 974.54212 | AG11: =SUMIFS(Data!$F$2:$F$1006,Data!$A$2:$A$1006,$A11,Data!$C$2:$C$1006,"Midwest peers") -> 830.81704 | AH11: =SUMIFS(Data!$G$2:$G$1006,Data!$A$2:$A$1006,$A11,Data!$C$2:$C$1006,"Midwest peers") -> 927.84153 | AI11: =SUMIFS(Data!$N$2:$N$1006,Data!$A$2:$A$1006,$A11,Data!$C$2:$C$1006,"Midwest peers") -> 2733.2007 | AJ11: =SUMIFS(Data!$H$2:$H$1006,Data!$A$2:$A$1006,$A11,Data!$C$2:$C$1006,"Midwest peers") -> 1423.3923 | AK11: =IFERROR(AF11*1000000/AE11,"") -> 84.363144 | AL11: =IFERROR(AG11*1000000/AE11,"") -> 71.921301 | AM11: =IFERROR(AH11*1000000/AE11,"") -> 80.320417 | AN11: =IFERROR(AI11*1000000/AE11,"") -> 236.60486 | AO11: =IFERROR(AJ11*1000000/AE11,"") -> 123.21874 | AP11: =IFERROR(IF(OR(IFERROR(INDEX(Assumptions!$B$8:$B$33,MATCH(Assumptions!$B$5,Assumptions!$A$8:$A$33,0)),"")="",INDEX(Assumptions!$B$8:$B$33,MATCH($A11,Assumptions!$A$8:$A$33,0))=""),"",AN11*IFERROR(INDEX(Assumptions!$B$8:$B$33,MATCH(Assumptions!$B$5,Assumptions!$A$8:$A$33,0)),"")/INDEX(Assumptions!$B$8:$B$33,MATCH($A11,Assumptions!$A$8:$A$33,0))),"") | AQ11: =IFERROR(IF(OR(IFERROR(INDEX(Assumptions!$B$8:$B$33,MATCH(Assumptions!$B$5,Assumptions!$A$8:$A$33,0)),"")="",INDEX(Assumptions!$B$8:$B$33,MATCH($A11,Assumptions!$A$8:$A$33,0))=""),"",AO11*IFERROR(INDEX(Assumptions!$B$8:$B$33,MATCH(Assumptions!$B$5,Assumptions!$A$8:$A$33,0)),"")/INDEX(Assumptions!$B$8:$B$33,MATCH($A11,Assumptions!$A$8:$A$33,0))),"")
A12: 2007 | B12: =COUNTIFS(Data!$A$2:$A$1006,$A12,Data!$C$2:$C$1006,"FirstEnergy") -> 10 | C12: =SUMIFS(Data!$L$2:$L$1006,Data!$A$2:$A$1006,$A12,Data!$C$2:$C$1006,"FirstEnergy") -> 6053941 | D12: =SUMIFS(Data!$E$2:$E$1006,Data!$A$2:$A$1006,$A12,Data!$C$2:$C$1006,"FirstEnergy") -> 506.78771 | E12: =SUMIFS(Data!$F$2:$F$1006,Data!$A$2:$A$1006,$A12,Data!$C$2:$C$1006,"FirstEnergy") -> 379.46568 | F12: =SUMIFS(Data!$G$2:$G$1006,Data!$A$2:$A$1006,$A12,Data!$C$2:$C$1006,"FirstEnergy") -> 351.10258 | G12: =SUMIFS(Data!$N$2:$N$1006,Data!$A$2:$A$1006,$A12,Data!$C$2:$C$1006,"FirstEnergy") -> 1237.356 | H12: =SUMIFS(Data!$H$2:$H$1006,Data!$A$2:$A$1006,$A12,Data!$C$2:$C$1006,"FirstEnergy") -> 684.49441 | I12: =IFERROR(D12*1000000/C12,"") -> 83.712033 | J12: =IFERROR(E12*1000000/C12,"") -> 62.680769 | K12: =IFERROR(F12*1000000/C12,"") -> 57.995706 | L12: =IFERROR(G12*1000000/C12,"") -> 204.38851 | M12: =IFERROR(H12*1000000/C12,"") -> 113.06592 | N12: =IFERROR(IF(OR(IFERROR(INDEX(Assumptions!$B$8:$B$33,MATCH(Assumptions!$B$5,Assumptions!$A$8:$A$33,0)),"")="",INDEX(Assumptions!$B$8:$B$33,MATCH($A12,Assumptions!$A$8:$A$33,0))=""),"",L12*IFERROR(INDEX(Assumptions!$B$8:$B$33,MATCH(Assumptions!$B$5,Assumptions!$A$8:$A$33,0)),"")/INDEX(Assumptions!$B$8:$B$33,MATCH($A12,Assumptions!$A$8:$A$33,0))),"") | O12: =IFERROR(IF(OR(IFERROR(INDEX(Assumptions!$B$8:$B$33,MATCH(Assumptions!$B$5,Assumptions!$A$8:$A$33,0)),"")="",INDEX(Assumptions!$B$8:$B$33,MATCH($A12,Assumptions!$A$8:$A$33,0))=""),"",M12*IFERROR(INDEX(Assumptions!$B$8:$B$33,MATCH(Assumptions!$B$5,Assumptions!$A$8:$A$33,0)),"")/INDEX(Assumptions!$B$8:$B$33,MATCH($A12,Assumptions!$A$8:$A$33,0))),"") | P12: =COUNTIFS(Data!$A$2:$A$1006,$A12,Data!$C$2:$C$1006,"Northeast peers") -> 12 | Q12: =SUMIFS(Data!$L$2:$L$1006,Data!$A$2:$A$1006,$A12,Data!$C$2:$C$1006,"Northeast peers") -> 12271387 | R12: =SUMIFS(Data!$E$2:$E$1006,Data!$A$2:$A$1006,$A12,Data!$C$2:$C$1006,"Northeast peers") -> 1091.6722 | S12: =SUMIFS(Data!$F$2:$F$1006,Data!$A$2:$A$1006,$A12,Data!$C$2:$C$1006,"Northeast peers") -> 1031.7015 | T12: =SUMIFS(Data!$G$2:$G$1006,Data!$A$2:$A$1006,$A12,Data!$C$2:$C$1006,"Northeast peers") -> 903.5284 | U12: =SUMIFS(Data!$N$2:$N$1006,Data!$A$2:$A$1006,$A12,Data!$C$2:$C$1006,"Northeast peers") -> 3026.9021 | V12: =SUMIFS(Data!$H$2:$H$1006,Data!$A$2:$A$1006,$A12,Data!$C$2:$C$1006,"Northeast peers") -> 1642.4438 | W12: =IFERROR(R12*1000000/Q12,"") -> 88.960785 | X12: =IFERROR(S12*1000000/Q12,"") -> 84.073747 | Y12: =IFERROR(T12*1000000/Q12,"") -> 73.628873 | Z12: =IFERROR(U12*1000000/Q12,"") -> 246.66341 | AA12: =IFERROR(V12*1000000/Q12,"") -> 133.84337 | AB12: =IFERROR(IF(OR(IFERROR(INDEX(Assumptions!$B$8:$B$33,MATCH(Assumptions!$B$5,Assumptions!$A$8:$A$33,0)),"")="",INDEX(Assumptions!$B$8:$B$33,MATCH($A12,Assumptions!$A$8:$A$33,0))=""),"",Z12*IFERROR(INDEX(Assumptions!$B$8:$B$33,MATCH(Assumptions!$B$5,Assumptions!$A$8:$A$33,0)),"")/INDEX(Assumptions!$B$8:$B$33,MATCH($A12,Assumptions!$A$8:$A$33,0))),"") | AC12: =IFERROR(IF(OR(IFERROR(INDEX(Assumptions!$B$8:$B$33,MATCH(Assumptions!$B$5,Assumptions!$A$8:$A$33,0)),"")="",INDEX(Assumptions!$B$8:$B$33,MATCH($A12,Assumptions!$A$8:$A$33,0))=""),"",AA12*IFERROR(INDEX(Assumptions!$B$8:$B$33,MATCH(Assumptions!$B$5,Assumptions!$A$8:$A$33,0)),"")/INDEX(Assumptions!$B$8:$B$33,MATCH($A12,Assumptions!$A$8:$A$33,0))),"") | AD12: =COUNTIFS(Data!$A$2:$A$1006,$A12,Data!$C$2:$C$1006,"Midwest peers") -> 17 | AE12: =SUMIFS(Data!$L$2:$L$1006,Data!$A$2:$A$1006,$A12,Data!$C$2:$C$1006,"Midwest peers") -> 11607120 | AF12: =SUMIFS(Data!$E$2:$E$1006,Data!$A$2:$A$1006,$A12,Data!$C$2:$C$1006,"Midwest peers") -> 1044.1054 | AG12: =SUMIFS(Data!$F$2:$F$1006,Data!$A$2:$A$1006,$A12,Data!$C$2:$C$1006,"Midwest peers") -> 875.56601 | AH12: =SUMIFS(Data!$G$2:$G$1006,Data!$A$2:$A$1006,$A12,Data!$C$2:$C$1006,"Midwest peers") -> 953.26703 | AI12: =SUMIFS(Data!$N$2:$N$1006,Data!$A$2:$A$1006,$A12,Data!$C$2:$C$1006,"Midwest peers") -> 2872.9384 | AJ12: =SUMIFS(Data!$H$2:$H$1006,Data!$A$2:$A$1006,$A12,Data!$C$2:$C$1006,"Midwest peers") -> 1494.5061 | AK12: =IFERROR(AF12*1000000/AE12,"") -> 89.953873 | AL12: =IFERROR(AG12*1000000/AE12,"") -> 75.433528 | AM12: =IFERROR(AH12*1000000/AE12,"") -> 82.127783 | AN12: =IFERROR(AI12*1000000/AE12,"") -> 247.51518 | AO12: =IFERROR(AJ12*1000000/AE12,"") -> 128.75771 | AP12: =IFERROR(IF(OR(IFERROR(INDEX(Assumptions!$B$8:$B$33,MATCH(Assumptions!$B$5,Assumptions!$A$8:$A$33,0)),"")="",INDEX(Assumptions!$B$8:$B$33,MATCH($A12,Assumptions!$A$8:$A$33,0))=""),"",AN12*IFERROR(INDEX(Assumptions!$B$8:$B$33,MATCH(Assumptions!$B$5,Assumptions!$A$8:$A$33,0)),"")/INDEX(Assumptions!$B$8:$B$33,MATCH($A12,Assumptions!$A$8:$A$33,0))),"") | AQ12: =IFERROR(IF(OR(IFERROR(INDEX(Assumptions!$B$8:$B$33,MATCH(Assumptions!$B$5,Assumptions!$A$8:$A$33,0)),"")="",INDEX(Assumptions!$B$8:$B$33,MATCH($A12,Assumptions!$A$8:$A$33,0))=""),"",AO12*IFERROR(INDEX(Assumptions!$B$8:$B$33,MATCH(Assumptions!$B$5,Assumptions!$A$8:$A$33,0)),"")/INDEX(Assumptions!$B$8:$B$33,MATCH($A12,Assumptions!$A$8:$A$33,0))),"")
A13: 2008 | B13: =COUNTIFS(Data!$A$2:$A$1006,$A13,Data!$C$2:$C$1006,"FirstEnergy") -> 10 | C13: =SUMIFS(Data!$L$2:$L$1006,Data!$A$2:$A$1006,$A13,Data!$C$2:$C$1006,"FirstEnergy") -> 6069675 | D13: =SUMIFS(Data!$E$2:$E$1006,Data!$A$2:$A$1006,$A13,Data!$C$2:$C$1006,"FirstEnergy") -> 521.29043 | E13: =SUMIFS(Data!$F$2:$F$1006,Data!$A$2:$A$1006,$A13,Data!$C$2:$C$1006,"FirstEnergy") -> 400.12271 | F13: =SUMIFS(Data!$G$2:$G$1006,Data!$A$2:$A$1006,$A13,Data!$C$2:$C$1006,"FirstEnergy") -> 372.24394 | G13: =SUMIFS(Data!$N$2:$N$1006,Data!$A$2:$A$1006,$A13,Data!$C$2:$C$1006,"FirstEnergy") -> 1293.6571 | H13: =SUMIFS(Data!$H$2:$H$1006,Data!$A$2:$A$1006,$A13,Data!$C$2:$C$1006,"FirstEnergy") -> 804.06991 | I13: =IFERROR(D13*1000000/C13,"") -> 85.884406 | J13: =IFERROR(E13*1000000/C13,"") -> 65.921603 | K13: =IFERROR(F13*1000000/C13,"") -> 61.32848 | L13: =IFERROR(G13*1000000/C13,"") -> 213.13449 | M13: =IFERROR(H13*1000000/C13,"") -> 132.47331 | N13: =IFERROR(IF(OR(IFERROR(INDEX(Assumptions!$B$8:$B$33,MATCH(Assumptions!$B$5,Assumptions!$A$8:$A$33,0)),"")="",INDEX(Assumptions!$B$8:$B$33,MATCH($A13,Assumptions!$A$8:$A$33,0))=""),"",L13*IFERROR(INDEX(Assumptions!$B$8:$B$33,MATCH(Assumptions!$B$5,Assumptions!$A$8:$A$33,0)),"")/INDEX(Assumptions!$B$8:$B$33,MATCH($A13,Assumptions!$A$8:$A$33,0))),"") | O13: =IFERROR(IF(OR(IFERROR(INDEX(Assumptions!$B$8:$B$33,MATCH(Assumptions!$B$5,Assumptions!$A$8:$A$33,0)),"")="",INDEX(Assumptions!$B$8:$B$33,MATCH($A13,Assumptions!$A$8:$A$33,0))=""),"",M13*IFERROR(INDEX(Assumptions!$B$8:$B$33,MATCH(Assumptions!$B$5,Assumptions!$A$8:$A$33,0)),"")/INDEX(Assumptions!$B$8:$B$33,MATCH($A13,Assumptions!$A$8:$A$33,0))),"") | P13: =COUNTIFS(Data!$A$2:$A$1006,$A13,Data!$C$2:$C$1006,"Northeast peers") -> 12 | Q13: =SUMIFS(Data!$L$2:$L$1006,Data!$A$2:$A$1006,$A13,Data!$C$2:$C$1006,"Northeast peers") -> 12308890 | R13: =SUMIFS(Data!$E$2:$E$1006,Data!$A$2:$A$1006,$A13,Data!$C$2:$C$1006,"Northeast peers") -> 1144.0037 | S13: =SUMIFS(Data!$F$2:$F$1006,Data!$A$2:$A$1006,$A13,Data!$C$2:$C$1006,"Northeast peers") -> 1218.2577 | T13: =SUMIFS(Data!$G$2:$G$1006,Data!$A$2:$A$1006,$A13,Data!$C$2:$C$1006,"Northeast peers") -> 896.96806 | U13: =SUMIFS(Data!$N$2:$N$1006,Data!$A$2:$A$1006,$A13,Data!$C$2:$C$1006,"Northeast peers") -> 3259.2295 | V13: =SUMIFS(Data!$H$2:$H$1006,Data!$A$2:$A$1006,$A13,Data!$C$2:$C$1006,"Northeast peers") -> 1907.8548 | W13: =IFERROR(R13*1000000/Q13,"") -> 92.94126 | X13: =IFERROR(S13*1000000/Q13,"") -> 98.973803 | Y13: =IFERROR(T13*1000000/Q13,"") -> 72.871564 | Z13: =IFERROR(U13*1000000/Q13,"") -> 264.78663 | AA13: =IFERROR(V13*1000000/Q13,"") -> 154.99812 | AB13: =IFERROR(IF(OR(IFERROR(INDEX(Assumptions!$B$8:$B$33,MATCH(Assumptions!$B$5,Assumptions!$A$8:$A$33,0)),"")="",INDEX(Assumptions!$B$8:$B$33,MATCH($A13,Assumptions!$A$8:$A$33,0))=""),"",Z13*IFERROR(INDEX(Assumptions!$B$8:$B$33,MATCH(Assumptions!$B$5,Assumptions!$A$8:$A$33,0)),"")/INDEX(Assumptions!$B$8:$B$33,MATCH($A13,Assumptions!$A$8:$A$33,0))),"") | AC13: =IFERROR(IF(OR(IFERROR(INDEX(Assumptions!$B$8:$B$33,MATCH(Assumptions!$B$5,Assumptions!$A$8:$A$33,0)),"")="",INDEX(Assumptions!$B$8:$B$33,MATCH($A13,Assumptions!$A$8:$A$33,0))=""),"",AA13*IFERROR(INDEX(Assumptions!$B$8:$B$33,MATCH(Assumptions!$B$5,Assumptions!$A$8:$A$33,0)),"")/INDEX(Assumptions!$B$8:$B$33,MATCH($A13,Assumptions!$A$8:$A$33,0))),"") | AD13: =COUNTIFS(Data!$A$2:$A$1006,$A13,Data!$C$2:$C$1006,"Midwest peers") -> 17 | AE13: =SUMIFS(Data!$L$2:$L$1006,Data!$A$2:$A$1006,$A13,Data!$C$2:$C$1006,"Midwest peers") -> 11646245 | AF13: =SUMIFS(Data!$E$2:$E$1006,Data!$A$2:$A$1006,$A13,Data!$C$2:$C$1006,"Midwest peers") -> 1118.3942 | AG13: =SUMIFS(Data!$F$2:$F$1006,Data!$A$2:$A$1006,$A13,Data!$C$2:$C$1006,"Midwest peers") -> 981.83744 | AH13: =SUMIFS(Data!$G$2:$G$1006,Data!$A$2:$A$1006,$A13,Data!$C$2:$C$1006,"Midwest peers") -> 986.11572 | AI13: =SUMIFS(Data!$N$2:$N$1006,Data!$A$2:$A$1006,$A13,Data!$C$2:$C$1006,"Midwest peers") -> 3086.3474 | AJ13: =SUMIFS(Data!$H$2:$H$1006,Data!$A$2:$A$1006,$A13,Data!$C$2:$C$1006,"Midwest peers") -> 1805.4703 | AK13: =IFERROR(AF13*1000000/AE13,"") -> 96.030454 | AL13: =IFERROR(AG13*1000000/AE13,"") -> 84.305064 | AM13: =IFERROR(AH13*1000000/AE13,"") -> 84.672417 | AN13: =IFERROR(AI13*1000000/AE13,"") -> 265.00794 | AO13: =IFERROR(AJ13*1000000/AE13,"") -> 155.02596 | AP13: =IFERROR(IF(OR(IFERROR(INDEX(Assumptions!$B$8:$B$33,MATCH(Assumptions!$B$5,Assumptions!$A$8:$A$33,0)),"")="",INDEX(Assumptions!$B$8:$B$33,MATCH($A13,Assumptions!$A$8:$A$33,0))=""),"",AN13*IFERROR(INDEX(Assumptions!$B$8:$B$33,MATCH(Assumptions!$B$5,Assumptions!$A$8:$A$33,0)),"")/INDEX(Assumptions!$B$8:$B$33,MATCH($A13,Assumptions!$A$8:$A$33,0))),"") | AQ13: =IFERROR(IF(OR(IFERROR(INDEX(Assumptions!$B$8:$B$33,MATCH(Assumptions!$B$5,Assumptions!$A$8:$A$33,0)),"")="",INDEX(Assumptions!$B$8:$B$33,MATCH($A13,Assumptions!$A$8:$A$33,0))=""),"",AO13*IFERROR(INDEX(Assumptions!$B$8:$B$33,MATCH(Assumptions!$B$5,Assumptions!$A$8:$A$33,0)),"")/INDEX(Assumptions!$B$8:$B$33,MATCH($A13,Assumptions!$A$8:$A$33,0))),"")
A14: 2009 | B14: =COUNTIFS(Data!$A$2:$A$1006,$A14,Data!$C$2:$C$1006,"FirstEnergy") -> 10 | C14: =SUMIFS(Data!$L$2:$L$1006,Data!$A$2:$A$1006,$A14,Data!$C$2:$C$1006,"FirstEnergy") -> 6077048 | D14: =SUMIFS(Data!$E$2:$E$1006,Data!$A$2:$A$1006,$A14,Data!$C$2:$C$1006,"FirstEnergy") -> 401.30227 | E14: =SUMIFS(Data!$F$2:$F$1006,Data!$A$2:$A$1006,$A14,Data!$C$2:$C$1006,"FirstEnergy") -> 410.58589 | F14: =SUMIFS(Data!$G$2:$G$1006,Data!$A$2:$A$1006,$A14,Data!$C$2:$C$1006,"FirstEnergy") -> 386.98517 | G14: =SUMIFS(Data!$N$2:$N$1006,Data!$A$2:$A$1006,$A14,Data!$C$2:$C$1006,"FirstEnergy") -> 1198.8733 | H14: =SUMIFS(Data!$H$2:$H$1006,Data!$A$2:$A$1006,$A14,Data!$C$2:$C$1006,"FirstEnergy") -> 781.66791 | I14: =IFERROR(D14*1000000/C14,"") -> 66.035725 | J14: =IFERROR(E14*1000000/C14,"") -> 67.563379 | K14: =IFERROR(F14*1000000/C14,"") -> 63.679795 | L14: =IFERROR(G14*1000000/C14,"") -> 197.2789 | M14: =IFERROR(H14*1000000/C14,"") -> 128.62625 | N14: =IFERROR(IF(OR(IFERROR(INDEX(Assumptions!$B$8:$B$33,MATCH(Assumptions!$B$5,Assumptions!$A$8:$A$33,0)),"")="",INDEX(Assumptions!$B$8:$B$33,MATCH($A14,Assumptions!$A$8:$A$33,0))=""),"",L14*IFERROR(INDEX(Assumptions!$B$8:$B$33,MATCH(Assumptions!$B$5,Assumptions!$A$8:$A$33,0)),"")/INDEX(Assumptions!$B$8:$B$33,MATCH($A14,Assumptions!$A$8:$A$33,0))),"") | O14: =IFERROR(IF(OR(IFERROR(INDEX(Assumptions!$B$8:$B$33,MATCH(Assumptions!$B$5,Assumptions!$A$8:$A$33,0)),"")="",INDEX(Assumptions!$B$8:$B$33,MATCH($A14,Assumptions!$A$8:$A$33,0))=""),"",M14*IFERROR(INDEX(Assumptions!$B$8:$B$33,MATCH(Assumptions!$B$5,Assumptions!$A$8:$A$33,0)),"")/INDEX(Assumptions!$B$8:$B$33,MATCH($A14,Assumptions!$A$8:$A$33,0))),"") | P14: =COUNTIFS(Data!$A$2:$A$1006,$A14,Data!$C$2:$C$1006,"Northeast peers") -> 12 | Q14: =SUMIFS(Data!$L$2:$L$1006,Data!$A$2:$A$1006,$A14,Data!$C$2:$C$1006,"Northeast peers") -> 12347413 | R14: =SUMIFS(Data!$E$2:$E$1006,Data!$A$2:$A$1006,$A14,Data!$C$2:$C$1006,"Northeast peers") -> 1199.8235 | S14: =SUMIFS(Data!$F$2:$F$1006,Data!$A$2:$A$1006,$A14,Data!$C$2:$C$1006,"Northeast peers") -> 1199.5655 | T14: =SUMIFS(Data!$G$2:$G$1006,Data!$A$2:$A$1006,$A14,Data!$C$2:$C$1006,"Northeast peers") -> 925.53827 | U14: =SUMIFS(Data!$N$2:$N$1006,Data!$A$2:$A$1006,$A14,Data!$C$2:$C$1006,"Northeast peers") -> 3324.9273 | V14: =SUMIFS(Data!$H$2:$H$1006,Data!$A$2:$A$1006,$A14,Data!$C$2:$C$1006,"Northeast peers") -> 1904.5997 | W14: =IFERROR(R14*1000000/Q14,"") -> 97.172052 | X14: =IFERROR(S14*1000000/Q14,"") -> 97.151163 | Y14: =IFERROR(T14*1000000/Q14,"") -> 74.958072 | Z14: =IFERROR(U14*1000000/Q14,"") -> 269.28129 | AA14: =IFERROR(V14*1000000/Q14,"") -> 154.25091 | AB14: =IFERROR(IF(OR(IFERROR(INDEX(Assumptions!$B$8:$B$33,MATCH(Assumptions!$B$5,Assumptions!$A$8:$A$33,0)),"")="",INDEX(Assumptions!$B$8:$B$33,MATCH($A14,Assumptions!$A$8:$A$33,0))=""),"",Z14*IFERROR(INDEX(Assumptions!$B$8:$B$33,MATCH(Assumptions!$B$5,Assumptions!$A$8:$A$33,0)),"")/INDEX(Assumptions!$B$8:$B$33,MATCH($A14,Assumptions!$A$8:$A$33,0))),"") | AC14: =IFERROR(IF(OR(IFERROR(INDEX(Assumptions!$B$8:$B$33,MATCH(Assumptions!$B$5,Assumptions!$A$8:$A$33,0)),"")="",INDEX(Assumptions!$B$8:$B$33,MATCH($A14,Assumptions!$A$8:$A$33,0))=""),"",AA14*IFERROR(INDEX(Assumptions!$B$8:$B$33,MATCH(Assumptions!$B$5,Assumptions!$A$8:$A$33,0)),"")/INDEX(Assumptions!$B$8:$B$33,MATCH($A14,Assumptions!$A$8:$A$33,0))),"") | AD14: =COUNTIFS(Data!$A$2:$A$1006,$A14,Data!$C$2:$C$1006,"Midwest peers") -> 17 | AE14: =SUMIFS(Data!$L$2:$L$1006,Data!$A$2:$A$1006,$A14,Data!$C$2:$C$1006,"Midwest peers") -> 11645338 | AF14: =SUMIFS(Data!$E$2:$E$1006,Data!$A$2:$A$1006,$A14,Data!$C$2:$C$1006,"Midwest peers") -> 1029.1813 | AG14: =SUMIFS(Data!$F$2:$F$1006,Data!$A$2:$A$1006,$A14,Data!$C$2:$C$1006,"Midwest peers") -> 964.65181 | AH14: =SUMIFS(Data!$G$2:$G$1006,Data!$A$2:$A$1006,$A14,Data!$C$2:$C$1006,"Midwest peers") -> 1025.5352 | AI14: =SUMIFS(Data!$N$2:$N$1006,Data!$A$2:$A$1006,$A14,Data!$C$2:$C$1006,"Midwest peers") -> 3019.3684 | AJ14: =SUMIFS(Data!$H$2:$H$1006,Data!$A$2:$A$1006,$A14,Data!$C$2:$C$1006,"Midwest peers") -> 1658.7769 | AK14: =IFERROR(AF14*1000000/AE14,"") -> 88.377112 | AL14: =IFERROR(AG14*1000000/AE14,"") -> 82.835879 | AM14: =IFERROR(AH14*1000000/AE14,"") -> 88.064017 | AN14: =IFERROR(AI14*1000000/AE14,"") -> 259.27701 | AO14: =IFERROR(AJ14*1000000/AE14,"") -> 142.44128 | AP14: =IFERROR(IF(OR(IFERROR(INDEX(Assumptions!$B$8:$B$33,MATCH(Assumptions!$B$5,Assumptions!$A$8:$A$33,0)),"")="",INDEX(Assumptions!$B$8:$B$33,MATCH($A14,Assumptions!$A$8:$A$33,0))=""),"",AN14*IFERROR(INDEX(Assumptions!$B$8:$B$33,MATCH(Assumptions!$B$5,Assumptions!$A$8:$A$33,0)),"")/INDEX(Assumptions!$B$8:$B$33,MATCH($A14,Assumptions!$A$8:$A$33,0))),"") | AQ14: =IFERROR(IF(OR(IFERROR(INDEX(Assumptions!$B$8:$B$33,MATCH(Assumptions!$B$5,Assumptions!$A$8:$A$33,0)),"")="",INDEX(Assumptions!$B$8:$B$33,MATCH($A14,Assumptions!$A$8:$A$33,0))=""),"",AO14*IFERROR(INDEX(Assumptions!$B$8:$B$33,MATCH(Assumptions!$B$5,Assumptions!$A$8:$A$33,0)),"")/INDEX(Assumptions!$B$8:$B$33,MATCH($A14,Assumptions!$A$8:$A$33,0))),"")
A15: 2010 | B15: =COUNTIFS(Data!$A$2:$A$1006,$A15,Data!$C$2:$C$1006,"FirstEnergy") -> 10 | C15: =SUMIFS(Data!$L$2:$L$1006,Data!$A$2:$A$1006,$A15,Data!$C$2:$C$1006,"FirstEnergy") -> 6081211 | D15: =SUMIFS(Data!$E$2:$E$1006,Data!$A$2:$A$1006,$A15,Data!$C$2:$C$1006,"FirstEnergy") -> 398.10287 | E15: =SUMIFS(Data!$F$2:$F$1006,Data!$A$2:$A$1006,$A15,Data!$C$2:$C$1006,"FirstEnergy") -> 420.83519 | F15: =SUMIFS(Data!$G$2:$G$1006,Data!$A$2:$A$1006,$A15,Data!$C$2:$C$1006,"FirstEnergy") -> 397.05029 | G15: =SUMIFS(Data!$N$2:$N$1006,Data!$A$2:$A$1006,$A15,Data!$C$2:$C$1006,"FirstEnergy") -> 1215.9884 | H15: =SUMIFS(Data!$H$2:$H$1006,Data!$A$2:$A$1006,$A15,Data!$C$2:$C$1006,"FirstEnergy") -> 752.64907 | I15: =IFERROR(D15*1000000/C15,"") -> 65.464408 | J15: =IFERROR(E15*1000000/C15,"") -> 69.202531 | K15: =IFERROR(F15*1000000/C15,"") -> 65.29132 | L15: =IFERROR(G15*1000000/C15,"") -> 199.95826 | M15: =IFERROR(H15*1000000/C15,"") -> 123.76631 | N15: =IFERROR(IF(OR(IFERROR(INDEX(Assumptions!$B$8:$B$33,MATCH(Assumptions!$B$5,Assumptions!$A$8:$A$33,0)),"")="",INDEX(Assumptions!$B$8:$B$33,MATCH($A15,Assumptions!$A$8:$A$33,0))=""),"",L15*IFERROR(INDEX(Assumptions!$B$8:$B$33,MATCH(Assumptions!$B$5,Assumptions!$A$8:$A$33,0)),"")/INDEX(Assumptions!$B$8:$B$33,MATCH($A15,Assumptions!$A$8:$A$33,0))),"") | O15: =IFERROR(IF(OR(IFERROR(INDEX(Assumptions!$B$8:$B$33,MATCH(Assumptions!$B$5,Assumptions!$A$8:$A$33,0)),"")="",INDEX(Assumptions!$B$8:$B$33,MATCH($A15,Assumptions!$A$8:$A$33,0))=""),"",M15*IFERROR(INDEX(Assumptions!$B$8:$B$33,MATCH(Assumptions!$B$5,Assumptions!$A$8:$A$33,0)),"")/INDEX(Assumptions!$B$8:$B$33,MATCH($A15,Assumptions!$A$8:$A$33,0))),"") | P15: =COUNTIFS(Data!$A$2:$A$1006,$A15,Data!$C$2:$C$1006,"Northeast peers") -> 12 | Q15: =SUMIFS(Data!$L$2:$L$1006,Data!$A$2:$A$1006,$A15,Data!$C$2:$C$1006,"Northeast peers") -> 12396097 | R15: =SUMIFS(Data!$E$2:$E$1006,Data!$A$2:$A$1006,$A15,Data!$C$2:$C$1006,"Northeast peers") -> 1316.9264 | S15: =SUMIFS(Data!$F$2:$F$1006,Data!$A$2:$A$1006,$A15,Data!$C$2:$C$1006,"Northeast peers") -> 1468.2604 | T15: =SUMIFS(Data!$G$2:$G$1006,Data!$A$2:$A$1006,$A15,Data!$C$2:$C$1006,"Northeast peers") -> 972.72631 | U15: =SUMIFS(Data!$N$2:$N$1006,Data!$A$2:$A$1006,$A15,Data!$C$2:$C$1006,"Northeast peers") -> 3757.9131 | V15: =SUMIFS(Data!$H$2:$H$1006,Data!$A$2:$A$1006,$A15,Data!$C$2:$C$1006,"Northeast peers") -> 2068.0841 | W15: =IFERROR(R15*1000000/Q15,"") -> 106.23718 | X15: =IFERROR(S15*1000000/Q15,"") -> 118.44538 | Y15: =IFERROR(T15*1000000/Q15,"") -> 78.470369 | Z15: =IFERROR(U15*1000000/Q15,"") -> 303.15293 | AA15: =IFERROR(V15*1000000/Q15,"") -> 166.83349 | AB15: =IFERROR(IF(OR(IFERROR(INDEX(Assumptions!$B$8:$B$33,MATCH(Assumptions!$B$5,Assumptions!$A$8:$A$33,0)),"")="",INDEX(Assumptions!$B$8:$B$33,MATCH($A15,Assumptions!$A$8:$A$33,0))=""),"",Z15*IFERROR(INDEX(Assumptions!$B$8:$B$33,MATCH(Assumptions!$B$5,Assumptions!$A$8:$A$33,0)),"")/INDEX(Assumptions!$B$8:$B$33,MATCH($A15,Assumptions!$A$8:$A$33,0))),"") | AC15: =IFERROR(IF(OR(IFERROR(INDEX(Assumptions!$B$8:$B$33,MATCH(Assumptions!$B$5,Assumptions!$A$8:$A$33,0)),"")="",INDEX(Assumptions!$B$8:$B$33,MATCH($A15,Assumptions!$A$8:$A$33,0))=""),"",AA15*IFERROR(INDEX(Assumptions!$B$8:$B$33,MATCH(Assumptions!$B$5,Assumptions!$A$8:$A$33,0)),"")/INDEX(Assumptions!$B$8:$B$33,MATCH($A15,Assumptions!$A$8:$A$33,0))),"") | AD15: =COUNTIFS(Data!$A$2:$A$1006,$A15,Data!$C$2:$C$1006,"Midwest peers") -> 17 | AE15: =SUMIFS(Data!$L$2:$L$1006,Data!$A$2:$A$1006,$A15,Data!$C$2:$C$1006,"Midwest peers") -> 11649576 | AF15: =SUMIFS(Data!$E$2:$E$1006,Data!$A$2:$A$1006,$A15,Data!$C$2:$C$1006,"Midwest peers") -> 1083.768 | AG15: =SUMIFS(Data!$F$2:$F$1006,Data!$A$2:$A$1006,$A15,Data!$C$2:$C$1006,"Midwest peers") -> 1067.6422 | AH15: =SUMIFS(Data!$G$2:$G$1006,Data!$A$2:$A$1006,$A15,Data!$C$2:$C$1006,"Midwest peers") -> 1048.5392 | AI15: =SUMIFS(Data!$N$2:$N$1006,Data!$A$2:$A$1006,$A15,Data!$C$2:$C$1006,"Midwest peers") -> 3199.9493 | AJ15: =SUMIFS(Data!$H$2:$H$1006,Data!$A$2:$A$1006,$A15,Data!$C$2:$C$1006,"Midwest peers") -> 1605.9715 | AK15: =IFERROR(AF15*1000000/AE15,"") -> 93.030682 | AL15: =IFERROR(AG15*1000000/AE15,"") -> 91.646441 | AM15: =IFERROR(AH15*1000000/AE15,"") -> 90.006637 | AN15: =IFERROR(AI15*1000000/AE15,"") -> 274.68376 | AO15: =IFERROR(AJ15*1000000/AE15,"") -> 137.85664 | AP15: =IFERROR(IF(OR(IFERROR(INDEX(Assumptions!$B$8:$B$33,MATCH(Assumptions!$B$5,Assumptions!$A$8:$A$33,0)),"")="",INDEX(Assumptions!$B$8:$B$33,MATCH($A15,Assumptions!$A$8:$A$33,0))=""),"",AN15*IFERROR(INDEX(Assumptions!$B$8:$B$33,MATCH(Assumptions!$B$5,Assumptions!$A$8:$A$33,0)),"")/INDEX(Assumptions!$B$8:$B$33,MATCH($A15,Assumptions!$A$8:$A$33,0))),"") | AQ15: =IFERROR(IF(OR(IFERROR(INDEX(Assumptions!$B$8:$B$33,MATCH(Assumptions!$B$5,Assumptions!$A$8:$A$33,0)),"")="",INDEX(Assumptions!$B$8:$B$33,MATCH($A15,Assumptions!$A$8:$A$33,0))=""),"",AO15*IFERROR(INDEX(Assumptions!$B$8:$B$33,MATCH(Assumptions!$B$5,Assumptions!$A$8:$A$33,0)),"")/INDEX(Assumptions!$B$8:$B$33,MATCH($A15,Assumptions!$A$8:$A$33,0))),"")
