Workbook

Sheet Notes
A1: Midwest IOU peer group: functional shares of non-generation O&M plus depreciation, 1995–2025
A2: Prepared 2026-10-25. Generation is excluded from this version. Supersedes the earlier 2026-10-25 version, which included generation, the version of 2026-10-24, which had 17 peers (no Illinois utilities), and the version of 2026-10-14, which used an earlier PUDL download (see Source and version).
A3: Measure
A4: Cost = operation and maintenance expense (FERC Form 1 pp. 320–323) plus depreciation and amortization expense (FERC Form 1 p. 336), electric utility only, nominal dollars, for transmission, distribution, regional market operation, customer accounts, service and sales, and administrative and general. Generation is excluded: O&M accounts 500–557 (including fuel and purchased power) and 577–578, and depreciation of production and energy-storage plant. Ohio and Illinois are retail-choice states in which the distribution utilities do not own generation, so the comparison is limited to the functions all peers perform.
A5: Not included: return on rate base, income and other taxes, interest.
A6: Account 565 (transmission of electricity by others) is included in Transmission.
A7: Shares are dollar-weighted: each category’s peer-group total divided by the peer-group non-generation total for the year. Utility Shares gives the same calculation for each utility.
A8: Sheets
A9: Peer Shares – aggregate shares of non-generation cost by year, with the O&M and depreciation portions of each year’s total.
A10: Utility Shares – shares of non-generation cost by utility and year.
A11: Reconciliation – line items compared with reported total O&M and total depreciation for every utility-year, with the tolerance in a labeled input cell.
A12: Transmission Transfers – transfers of peer transmission systems to transmission-only companies, with sources and the corresponding change in account 565.
... A40: Blue text: input values taken from PUDL or from the sources named on the sheet. Black text: formulas that refer only to cells on the same sheet. Green text: formulas that refer to another sheet. Yellow fill: the reconciliation tolerance, an adjustable input.

Sheet Peer Shares
A1: Peer-group aggregate shares of non-generation O&M plus depreciation
A2: Generation is excluded (O&M accounts 500–557 and 577–578, production depreciation). Dollar-weighted: each share is the category’s peer-group total divided by the peer-group non-generation total. Account 565 is included in Transmission. Source: Data sheet (PUDL v2026.10.0); see Notes.
A4: Year | B4: Utilities reporting | C4: Non-generation total ($mm) | D4: Transmission | E4: Distribution | F4: RTO/market operation | G4: Customer accounts, service & sales | H4: A&G and general | I4: Acct 565 (incl. in Transmission) | J4: Check: shares sum | K4: O&M portion of total | L4: Depreciation portion of total
A5: 1995 | B5: =COUNTIFS('Utility Shares'!$A:$A,$A5) -> 19 | C5: =SUMIFS(Data!$E$2:$E$2657,Data!$A$2:$A$2657,$A5)+SUMIFS(Data!$G$2:$G$2657,Data!$A$2:$A$2657,$A5) -> 5553.4981 | D5: =IFERROR((SUMIFS(Data!$E$2:$E$2657,Data!$A$2:$A$2657,$A5,Data!$D$2:$D$2657,"Transmission")+SUMIFS(Data!$G$2:$G$2657,Data!$A$2:$A$2657,$A5,Data!$D$2:$D$2657,"Transmission"))/$C5,0) -> 0.087193603 | E5: =IFERROR((SUMIFS(Data!$E$2:$E$2657,Data!$A$2:$A$2657,$A5,Data!$D$2:$D$2657,"Distribution")+SUMIFS(Data!$G$2:$G$2657,Data!$A$2:$A$2657,$A5,Data!$D$2:$D$2657,"Distribution"))/$C5,0) -> 0.31344485 | F5: =IFERROR((SUMIFS(Data!$E$2:$E$2657,Data!$A$2:$A$2657,$A5,Data!$D$2:$D$2657,"RTO/market operation")+SUMIFS(Data!$G$2:$G$2657,Data!$A$2:$A$2657,$A5,Data!$D$2:$D$2657,"RTO/market operation"))/$C5,0) -> 0 | G5: =IFERROR((SUMIFS(Data!$E$2:$E$2657,Data!$A$2:$A$2657,$A5,Data!$D$2:$D$2657,"Customer accounts, service & sales")+SUMIFS(Data!$G$2:$G$2657,Data!$A$2:$A$2657,$A5,Data!$D$2:$D$2657,"Customer accounts, service & sales"))/$C5,0) -> 0.15443601 | H5: =IFERROR((SUMIFS(Data!$E$2:$E$2657,Data!$A$2:$A$2657,$A5,Data!$D$2:$D$2657,"A&G and general")+SUMIFS(Data!$G$2:$G$2657,Data!$A$2:$A$2657,$A5,Data!$D$2:$D$2657,"A&G and general"))/$C5,0) -> 0.44492554 | I5: =IFERROR(SUMIFS(Data!$F$2:$F$2657,Data!$A$2:$A$2657,$A5)/$C5,0) -> -0.0062376998 | J5: =SUM(D5:H5) -> 1 | K5: =IFERROR(SUMIFS(Data!$E$2:$E$2657,Data!$A$2:$A$2657,$A5)/$C5,0) -> 0.77138146 | L5: =IFERROR(SUMIFS(Data!$G$2:$G$2657,Data!$A$2:$A$2657,$A5)/$C5,0) -> 0.22861854
A6: 1996 | B6: =COUNTIFS('Utility Shares'!$A:$A,$A6) -> 19 | C6: =SUMIFS(Data!$E$2:$E$2657,Data!$A$2:$A$2657,$A6)+SUMIFS(Data!$G$2:$G$2657,Data!$A$2:$A$2657,$A6) -> 5584.261 | D6: =IFERROR((SUMIFS(Data!$E$2:$E$2657,Data!$A$2:$A$2657,$A6,Data!$D$2:$D$2657,"Transmission")+SUMIFS(Data!$G$2:$G$2657,Data!$A$2:$A$2657,$A6,Data!$D$2:$D$2657,"Transmission"))/$C6,0) -> 0.092986737 | E6: =IFERROR((SUMIFS(Data!$E$2:$E$2657,Data!$A$2:$A$2657,$A6,Data!$D$2:$D$2657,"Distribution")+SUMIFS(Data!$G$2:$G$2657,Data!$A$2:$A$2657,$A6,Data!$D$2:$D$2657,"Distribution"))/$C6,0) -> 0.32453878 | F6: =IFERROR((SUMIFS(Data!$E$2:$E$2657,Data!$A$2:$A$2657,$A6,Data!$D$2:$D$2657,"RTO/market operation")+SUMIFS(Data!$G$2:$G$2657,Data!$A$2:$A$2657,$A6,Data!$D$2:$D$2657,"RTO/market operation"))/$C6,0) -> 0 | G6: =IFERROR((SUMIFS(Data!$E$2:$E$2657,Data!$A$2:$A$2657,$A6,Data!$D$2:$D$2657,"Customer accounts, service & sales")+SUMIFS(Data!$G$2:$G$2657,Data!$A$2:$A$2657,$A6,Data!$D$2:$D$2657,"Customer accounts, service & sales"))/$C6,0) -> 0.16947742 | H6: =IFERROR((SUMIFS(Data!$E$2:$E$2657,Data!$A$2:$A$2657,$A6,Data!$D$2:$D$2657,"A&G and general")+SUMIFS(Data!$G$2:$G$2657,Data!$A$2:$A$2657,$A6,Data!$D$2:$D$2657,"A&G and general"))/$C6,0) -> 0.41299706 | I6: =IFERROR(SUMIFS(Data!$F$2:$F$2657,Data!$A$2:$A$2657,$A6)/$C6,0) -> -0.003916465 | J6: =SUM(D6:H6) -> 1 | K6: =IFERROR(SUMIFS(Data!$E$2:$E$2657,Data!$A$2:$A$2657,$A6)/$C6,0) -> 0.75729247 | L6: =IFERROR(SUMIFS(Data!$G$2:$G$2657,Data!$A$2:$A$2657,$A6)/$C6,0) -> 0.24270753
A7: 1997 | B7: =COUNTIFS('Utility Shares'!$A:$A,$A7) -> 18 | C7: =SUMIFS(Data!$E$2:$E$2657,Data!$A$2:$A$2657,$A7)+SUMIFS(Data!$G$2:$G$2657,Data!$A$2:$A$2657,$A7) -> 4605.8205 | D7: =IFERROR((SUMIFS(Data!$E$2:$E$2657,Data!$A$2:$A$2657,$A7,Data!$D$2:$D$2657,"Transmission")+SUMIFS(Data!$G$2:$G$2657,Data!$A$2:$A$2657,$A7,Data!$D$2:$D$2657,"Transmission"))/$C7,0) -> 0.09817598 | E7: =IFERROR((SUMIFS(Data!$E$2:$E$2657,Data!$A$2:$A$2657,$A7,Data!$D$2:$D$2657,"Distribution")+SUMIFS(Data!$G$2:$G$2657,Data!$A$2:$A$2657,$A7,Data!$D$2:$D$2657,"Distribution"))/$C7,0) -> 0.3104333 | F7: =IFERROR((SUMIFS(Data!$E$2:$E$2657,Data!$A$2:$A$2657,$A7,Data!$D$2:$D$2657,"RTO/market operation")+SUMIFS(Data!$G$2:$G$2657,Data!$A$2:$A$2657,$A7,Data!$D$2:$D$2657,"RTO/market operation"))/$C7,0) -> 0 | G7: =IFERROR((SUMIFS(Data!$E$2:$E$2657,Data!$A$2:$A$2657,$A7,Data!$D$2:$D$2657,"Customer accounts, service & sales")+SUMIFS(Data!$G$2:$G$2657,Data!$A$2:$A$2657,$A7,Data!$D$2:$D$2657,"Customer accounts, service & sales"))/$C7,0) -> 0.17036429 | H7: =IFERROR((SUMIFS(Data!$E$2:$E$2657,Data!$A$2:$A$2657,$A7,Data!$D$2:$D$2657,"A&G and general")+SUMIFS(Data!$G$2:$G$2657,Data!$A$2:$A$2657,$A7,Data!$D$2:$D$2657,"A&G and general"))/$C7,0) -> 0.42102643 | I7: =IFERROR(SUMIFS(Data!$F$2:$F$2657,Data!$A$2:$A$2657,$A7)/$C7,0) -> 0.0029553381 | J7: =SUM(D7:H7) -> 1 | K7: =IFERROR(SUMIFS(Data!$E$2:$E$2657,Data!$A$2:$A$2657,$A7)/$C7,0) -> 0.7515751 | L7: =IFERROR(SUMIFS(Data!$G$2:$G$2657,Data!$A$2:$A$2657,$A7)/$C7,0) -> 0.2484249
A8: 1998 | B8: =COUNTIFS('Utility Shares'!$A:$A,$A8) -> 19 | C8: =SUMIFS(Data!$E$2:$E$2657,Data!$A$2:$A$2657,$A8)+SUMIFS(Data!$G$2:$G$2657,Data!$A$2:$A$2657,$A8) -> 6337.769 | D8: =IFERROR((SUMIFS(Data!$E$2:$E$2657,Data!$A$2:$A$2657,$A8,Data!$D$2:$D$2657,"Transmission")+SUMIFS(Data!$G$2:$G$2657,Data!$A$2:$A$2657,$A8,Data!$D$2:$D$2657,"Transmission"))/$C8,0) -> 0.093675971 | E8: =IFERROR((SUMIFS(Data!$E$2:$E$2657,Data!$A$2:$A$2657,$A8,Data!$D$2:$D$2657,"Distribution")+SUMIFS(Data!$G$2:$G$2657,Data!$A$2:$A$2657,$A8,Data!$D$2:$D$2657,"Distribution"))/$C8,0) -> 0.32231769 | F8: =IFERROR((SUMIFS(Data!$E$2:$E$2657,Data!$A$2:$A$2657,$A8,Data!$D$2:$D$2657,"RTO/market operation")+SUMIFS(Data!$G$2:$G$2657,Data!$A$2:$A$2657,$A8,Data!$D$2:$D$2657,"RTO/market operation"))/$C8,0) -> 0 | G8: =IFERROR((SUMIFS(Data!$E$2:$E$2657,Data!$A$2:$A$2657,$A8,Data!$D$2:$D$2657,"Customer accounts, service & sales")+SUMIFS(Data!$G$2:$G$2657,Data!$A$2:$A$2657,$A8,Data!$D$2:$D$2657,"Customer accounts, service & sales"))/$C8,0) -> 0.17369661 | H8: =IFERROR((SUMIFS(Data!$E$2:$E$2657,Data!$A$2:$A$2657,$A8,Data!$D$2:$D$2657,"A&G and general")+SUMIFS(Data!$G$2:$G$2657,Data!$A$2:$A$2657,$A8,Data!$D$2:$D$2657,"A&G and general"))/$C8,0) -> 0.41030973 | I8: =IFERROR(SUMIFS(Data!$F$2:$F$2657,Data!$A$2:$A$2657,$A8)/$C8,0) -> 0.006510672 | J8: =SUM(D8:H8) -> 1 | K8: =IFERROR(SUMIFS(Data!$E$2:$E$2657,Data!$A$2:$A$2657,$A8)/$C8,0) -> 0.75619811 | L8: =IFERROR(SUMIFS(Data!$G$2:$G$2657,Data!$A$2:$A$2657,$A8)/$C8,0) -> 0.24380189
A9: 1999 | B9: =COUNTIFS('Utility Shares'!$A:$A,$A9) -> 19 | C9: =SUMIFS(Data!$E$2:$E$2657,Data!$A$2:$A$2657,$A9)+SUMIFS(Data!$G$2:$G$2657,Data!$A$2:$A$2657,$A9) -> 6608.7734 | D9: =IFERROR((SUMIFS(Data!$E$2:$E$2657,Data!$A$2:$A$2657,$A9,Data!$D$2:$D$2657,"Transmission")+SUMIFS(Data!$G$2:$G$2657,Data!$A$2:$A$2657,$A9,Data!$D$2:$D$2657,"Transmission"))/$C9,0) -> 0.090250553 | E9: =IFERROR((SUMIFS(Data!$E$2:$E$2657,Data!$A$2:$A$2657,$A9,Data!$D$2:$D$2657,"Distribution")+SUMIFS(Data!$G$2:$G$2657,Data!$A$2:$A$2657,$A9,Data!$D$2:$D$2657,"Distribution"))/$C9,0) -> 0.32974931 | F9: =IFERROR((SUMIFS(Data!$E$2:$E$2657,Data!$A$2:$A$2657,$A9,Data!$D$2:$D$2657,"RTO/market operation")+SUMIFS(Data!$G$2:$G$2657,Data!$A$2:$A$2657,$A9,Data!$D$2:$D$2657,"RTO/market operation"))/$C9,0) -> 0 | G9: =IFERROR((SUMIFS(Data!$E$2:$E$2657,Data!$A$2:$A$2657,$A9,Data!$D$2:$D$2657,"Customer accounts, service & sales")+SUMIFS(Data!$G$2:$G$2657,Data!$A$2:$A$2657,$A9,Data!$D$2:$D$2657,"Customer accounts, service & sales"))/$C9,0) -> 0.17444528 | H9: =IFERROR((SUMIFS(Data!$E$2:$E$2657,Data!$A$2:$A$2657,$A9,Data!$D$2:$D$2657,"A&G and general")+SUMIFS(Data!$G$2:$G$2657,Data!$A$2:$A$2657,$A9,Data!$D$2:$D$2657,"A&G and general"))/$C9,0) -> 0.40555485 | I9: =IFERROR(SUMIFS(Data!$F$2:$F$2657,Data!$A$2:$A$2657,$A9)/$C9,0) -> 0.0034491988 | J9: =SUM(D9:H9) -> 1 | K9: =IFERROR(SUMIFS(Data!$E$2:$E$2657,Data!$A$2:$A$2657,$A9)/$C9,0) -> 0.75394548 | L9: =IFERROR(SUMIFS(Data!$G$2:$G$2657,Data!$A$2:$A$2657,$A9)/$C9,0) -> 0.24605452
A10: 2000 | B10: =COUNTIFS('Utility Shares'!$A:$A,$A10) -> 19 | C10: =SUMIFS(Data!$E$2:$E$2657,Data!$A$2:$A$2657,$A10)+SUMIFS(Data!$G$2:$G$2657,Data!$A$2:$A$2657,$A10) -> 6638.9201 | D10: =IFERROR((SUMIFS(Data!$E$2:$E$2657,Data!$A$2:$A$2657,$A10,Data!$D$2:$D$2657,"Transmission")+SUMIFS(Data!$G$2:$G$2657,Data!$A$2:$A$2657,$A10,Data!$D$2:$D$2657,"Transmission"))/$C10,0) -> 0.089766362 | E10: =IFERROR((SUMIFS(Data!$E$2:$E$2657,Data!$A$2:$A$2657,$A10,Data!$D$2:$D$2657,"Distribution")+SUMIFS(Data!$G$2:$G$2657,Data!$A$2:$A$2657,$A10,Data!$D$2:$D$2657,"Distribution"))/$C10,0) -> 0.36059848 | F10: =IFERROR((SUMIFS(Data!$E$2:$E$2657,Data!$A$2:$A$2657,$A10,Data!$D$2:$D$2657,"RTO/market operation")+SUMIFS(Data!$G$2:$G$2657,Data!$A$2:$A$2657,$A10,Data!$D$2:$D$2657,"RTO/market operation"))/$C10,0) -> 0 | G10: =IFERROR((SUMIFS(Data!$E$2:$E$2657,Data!$A$2:$A$2657,$A10,Data!$D$2:$D$2657,"Customer accounts, service & sales")+SUMIFS(Data!$G$2:$G$2657,Data!$A$2:$A$2657,$A10,Data!$D$2:$D$2657,"Customer accounts, service & sales"))/$C10,0) -> 0.15073055 | H10: =IFERROR((SUMIFS(Data!$E$2:$E$2657,Data!$A$2:$A$2657,$A10,Data!$D$2:$D$2657,"A&G and general")+SUMIFS(Data!$G$2:$G$2657,Data!$A$2:$A$2657,$A10,Data!$D$2:$D$2657,"A&G and general"))/$C10,0) -> 0.39890461 | I10: =IFERROR(SUMIFS(Data!$F$2:$F$2657,Data!$A$2:$A$2657,$A10)/$C10,0) -> 0.0059559476 | J10: =SUM(D10:H10) -> 1 | K10: =IFERROR(SUMIFS(Data!$E$2:$E$2657,Data!$A$2:$A$2657,$A10)/$C10,0) -> 0.7386369 | L10: =IFERROR(SUMIFS(Data!$G$2:$G$2657,Data!$A$2:$A$2657,$A10)/$C10,0) -> 0.2613631
A11: 2001 | B11: =COUNTIFS('Utility Shares'!$A:$A,$A11) -> 19 | C11: =SUMIFS(Data!$E$2:$E$2657,Data!$A$2:$A$2657,$A11)+SUMIFS(Data!$G$2:$G$2657,Data!$A$2:$A$2657,$A11) -> 6724.5755 | D11: =IFERROR((SUMIFS(Data!$E$2:$E$2657,Data!$A$2:$A$2657,$A11,Data!$D$2:$D$2657,"Transmission")+SUMIFS(Data!$G$2:$G$2657,Data!$A$2:$A$2657,$A11,Data!$D$2:$D$2657,"Transmission"))/$C11,0) -> 0.10953391 | E11: =IFERROR((SUMIFS(Data!$E$2:$E$2657,Data!$A$2:$A$2657,$A11,Data!$D$2:$D$2657,"Distribution")+SUMIFS(Data!$G$2:$G$2657,Data!$A$2:$A$2657,$A11,Data!$D$2:$D$2657,"Distribution"))/$C11,0) -> 0.35710191 | F11: =IFERROR((SUMIFS(Data!$E$2:$E$2657,Data!$A$2:$A$2657,$A11,Data!$D$2:$D$2657,"RTO/market operation")+SUMIFS(Data!$G$2:$G$2657,Data!$A$2:$A$2657,$A11,Data!$D$2:$D$2657,"RTO/market operation"))/$C11,0) -> 0 | G11: =IFERROR((SUMIFS(Data!$E$2:$E$2657,Data!$A$2:$A$2657,$A11,Data!$D$2:$D$2657,"Customer accounts, service & sales")+SUMIFS(Data!$G$2:$G$2657,Data!$A$2:$A$2657,$A11,Data!$D$2:$D$2657,"Customer accounts, service & sales"))/$C11,0) -> 0.14121192 | H11: =IFERROR((SUMIFS(Data!$E$2:$E$2657,Data!$A$2:$A$2657,$A11,Data!$D$2:$D$2657,"A&G and general")+SUMIFS(Data!$G$2:$G$2657,Data!$A$2:$A$2657,$A11,Data!$D$2:$D$2657,"A&G and general"))/$C11,0) -> 0.39215226 | I11: =IFERROR(SUMIFS(Data!$F$2:$F$2657,Data!$A$2:$A$2657,$A11)/$C11,0) -> 0.043097137 | J11: =SUM(D11:H11) -> 1 | K11: =IFERROR(SUMIFS(Data!$E$2:$E$2657,Data!$A$2:$A$2657,$A11)/$C11,0) -> 0.74201215 | L11: =IFERROR(SUMIFS(Data!$G$2:$G$2657,Data!$A$2:$A$2657,$A11)/$C11,0) -> 0.25798785
A12: 2002 | B12: =COUNTIFS('Utility Shares'!$A:$A,$A12) -> 18 | C12: =SUMIFS(Data!$E$2:$E$2657,Data!$A$2:$A$2657,$A12)+SUMIFS(Data!$G$2:$G$2657,Data!$A$2:$A$2657,$A12) -> 6291.066 | D12: =IFERROR((SUMIFS(Data!$E$2:$E$2657,Data!$A$2:$A$2657,$A12,Data!$D$2:$D$2657,"Transmission")+SUMIFS(Data!$G$2:$G$2657,Data!$A$2:$A$2657,$A12,Data!$D$2:$D$2657,"Transmission"))/$C12,0) -> 0.11625879 | E12: =IFERROR((SUMIFS(Data!$E$2:$E$2657,Data!$A$2:$A$2657,$A12,Data!$D$2:$D$2657,"Distribution")+SUMIFS(Data!$G$2:$G$2657,Data!$A$2:$A$2657,$A12,Data!$D$2:$D$2657,"Distribution"))/$C12,0) -> 0.34467786 | F12: =IFERROR((SUMIFS(Data!$E$2:$E$2657,Data!$A$2:$A$2657,$A12,Data!$D$2:$D$2657,"RTO/market operation")+SUMIFS(Data!$G$2:$G$2657,Data!$A$2:$A$2657,$A12,Data!$D$2:$D$2657,"RTO/market operation"))/$C12,0) -> 0 | G12: =IFERROR((SUMIFS(Data!$E$2:$E$2657,Data!$A$2:$A$2657,$A12,Data!$D$2:$D$2657,"Customer accounts, service & sales")+SUMIFS(Data!$G$2:$G$2657,Data!$A$2:$A$2657,$A12,Data!$D$2:$D$2657,"Customer accounts, service & sales"))/$C12,0) -> 0.15342232 | H12: =IFERROR((SUMIFS(Data!$E$2:$E$2657,Data!$A$2:$A$2657,$A12,Data!$D$2:$D$2657,"A&G and general")+SUMIFS(Data!$G$2:$G$2657,Data!$A$2:$A$2657,$A12,Data!$D$2:$D$2657,"A&G and general"))/$C12,0) -> 0.38564103 | I12: =IFERROR(SUMIFS(Data!$F$2:$F$2657,Data!$A$2:$A$2657,$A12)/$C12,0) -> 0.049832131 | J12: =SUM(D12:H12) -> 1 | K12: =IFERROR(SUMIFS(Data!$E$2:$E$2657,Data!$A$2:$A$2657,$A12)/$C12,0) -> 0.74270418 | L12: =IFERROR(SUMIFS(Data!$G$2:$G$2657,Data!$A$2:$A$2657,$A12)/$C12,0) -> 0.25729582
A13: 2003 | B13: =COUNTIFS('Utility Shares'!$A:$A,$A13) -> 18 | C13: =SUMIFS(Data!$E$2:$E$2657,Data!$A$2:$A$2657,$A13)+SUMIFS(Data!$G$2:$G$2657,Data!$A$2:$A$2657,$A13) -> 6769.0614 | D13: =IFERROR((SUMIFS(Data!$E$2:$E$2657,Data!$A$2:$A$2657,$A13,Data!$D$2:$D$2657,"Transmission")+SUMIFS(Data!$G$2:$G$2657,Data!$A$2:$A$2657,$A13,Data!$D$2:$D$2657,"Transmission"))/$C13,0) -> 0.11638451 | E13: =IFERROR((SUMIFS(Data!$E$2:$E$2657,Data!$A$2:$A$2657,$A13,Data!$D$2:$D$2657,"Distribution")+SUMIFS(Data!$G$2:$G$2657,Data!$A$2:$A$2657,$A13,Data!$D$2:$D$2657,"Distribution"))/$C13,0) -> 0.32444386 | F13: =IFERROR((SUMIFS(Data!$E$2:$E$2657,Data!$A$2:$A$2657,$A13,Data!$D$2:$D$2657,"RTO/market operation")+SUMIFS(Data!$G$2:$G$2657,Data!$A$2:$A$2657,$A13,Data!$D$2:$D$2657,"RTO/market operation"))/$C13,0) -> 0 | G13: =IFERROR((SUMIFS(Data!$E$2:$E$2657,Data!$A$2:$A$2657,$A13,Data!$D$2:$D$2657,"Customer accounts, service & sales")+SUMIFS(Data!$G$2:$G$2657,Data!$A$2:$A$2657,$A13,Data!$D$2:$D$2657,"Customer accounts, service & sales"))/$C13,0) -> 0.13921524 | H13: =IFERROR((SUMIFS(Data!$E$2:$E$2657,Data!$A$2:$A$2657,$A13,Data!$D$2:$D$2657,"A&G and general")+SUMIFS(Data!$G$2:$G$2657,Data!$A$2:$A$2657,$A13,Data!$D$2:$D$2657,"A&G and general"))/$C13,0) -> 0.41995639 | I13: =IFERROR(SUMIFS(Data!$F$2:$F$2657,Data!$A$2:$A$2657,$A13)/$C13,0) -> 0.055512896 | J13: =SUM(D13:H13) -> 1 | K13: =IFERROR(SUMIFS(Data!$E$2:$E$2657,Data!$A$2:$A$2657,$A13)/$C13,0) -> 0.75749784 | L13: =IFERROR(SUMIFS(Data!$G$2:$G$2657,Data!$A$2:$A$2657,$A13)/$C13,0) -> 0.24250216
A14: 2004 | B14: =COUNTIFS('Utility Shares'!$A:$A,$A14) -> 18 | C14: =SUMIFS(Data!$E$2:$E$2657,Data!$A$2:$A$2657,$A14)+SUMIFS(Data!$G$2:$G$2657,Data!$A$2:$A$2657,$A14) -> 6962.0021 | D14: =IFERROR((SUMIFS(Data!$E$2:$E$2657,Data!$A$2:$A$2657,$A14,Data!$D$2:$D$2657,"Transmission")+SUMIFS(Data!$G$2:$G$2657,Data!$A$2:$A$2657,$A14,Data!$D$2:$D$2657,"Transmission"))/$C14,0) -> 0.14113329 | E14: =IFERROR((SUMIFS(Data!$E$2:$E$2657,Data!$A$2:$A$2657,$A14,Data!$D$2:$D$2657,"Distribution")+SUMIFS(Data!$G$2:$G$2657,Data!$A$2:$A$2657,$A14,Data!$D$2:$D$2657,"Distribution"))/$C14,0) -> 0.31915068 | F14: =IFERROR((SUMIFS(Data!$E$2:$E$2657,Data!$A$2:$A$2657,$A14,Data!$D$2:$D$2657,"RTO/market operation")+SUMIFS(Data!$G$2:$G$2657,Data!$A$2:$A$2657,$A14,Data!$D$2:$D$2657,"RTO/market operation"))/$C14,0) -> 0 | G14: =IFERROR((SUMIFS(Data!$E$2:$E$2657,Data!$A$2:$A$2657,$A14,Data!$D$2:$D$2657,"Customer accounts, service & sales")+SUMIFS(Data!$G$2:$G$2657,Data!$A$2:$A$2657,$A14,Data!$D$2:$D$2657,"Customer accounts, service & sales"))/$C14,0) -> 0.13134706 | H14: =IFERROR((SUMIFS(Data!$E$2:$E$2657,Data!$A$2:$A$2657,$A14,Data!$D$2:$D$2657,"A&G and general")+SUMIFS(Data!$G$2:$G$2657,Data!$A$2:$A$2657,$A14,Data!$D$2:$D$2657,"A&G and general"))/$C14,0) -> 0.40836897 | I14: =IFERROR(SUMIFS(Data!$F$2:$F$2657,Data!$A$2:$A$2657,$A14)/$C14,0) -> 0.052785098 | J14: =SUM(D14:H14) -> 1 | K14: =IFERROR(SUMIFS(Data!$E$2:$E$2657,Data!$A$2:$A$2657,$A14)/$C14,0) -> 0.75004411 | L14: =IFERROR(SUMIFS(Data!$G$2:$G$2657,Data!$A$2:$A$2657,$A14)/$C14,0) -> 0.24995589
A15: 2005 | B15: =COUNTIFS('Utility Shares'!$A:$A,$A15) -> 19 | C15: =SUMIFS(Data!$E$2:$E$2657,Data!$A$2:$A$2657,$A15)+SUMIFS(Data!$G$2:$G$2657,Data!$A$2:$A$2657,$A15) -> 7824.2558 | D15: =IFERROR((SUMIFS(Data!$E$2:$E$2657,Data!$A$2:$A$2657,$A15,Data!$D$2:$D$2657,"Transmission")+SUMIFS(Data!$G$2:$G$2657,Data!$A$2:$A$2657,$A15,Data!$D$2:$D$2657,"Transmission"))/$C15,0) -> 0.17256808 | E15: =IFERROR((SUMIFS(Data!$E$2:$E$2657,Data!$A$2:$A$2657,$A15,Data!$D$2:$D$2657,"Distribution")+SUMIFS(Data!$G$2:$G$2657,Data!$A$2:$A$2657,$A15,Data!$D$2:$D$2657,"Distribution"))/$C15,0) -> 0.33196391 | F15: =IFERROR((SUMIFS(Data!$E$2:$E$2657,Data!$A$2:$A$2657,$A15,Data!$D$2:$D$2657,"RTO/market operation")+SUMIFS(Data!$G$2:$G$2657,Data!$A$2:$A$2657,$A15,Data!$D$2:$D$2657,"RTO/market operation"))/$C15,0) -> 0 | G15: =IFERROR((SUMIFS(Data!$E$2:$E$2657,Data!$A$2:$A$2657,$A15,Data!$D$2:$D$2657,"Customer accounts, service & sales")+SUMIFS(Data!$G$2:$G$2657,Data!$A$2:$A$2657,$A15,Data!$D$2:$D$2657,"Customer accounts, service & sales"))/$C15,0) -> 0.12827262 | H15: =IFERROR((SUMIFS(Data!$E$2:$E$2657,Data!$A$2:$A$2657,$A15,Data!$D$2:$D$2657,"A&G and general")+SUMIFS(Data!$G$2:$G$2657,Data!$A$2:$A$2657,$A15,Data!$D$2:$D$2657,"A&G and general"))/$C15,0) -> 0.36719539 | I15: =IFERROR(SUMIFS(Data!$F$2:$F$2657,Data!$A$2:$A$2657,$A15)/$C15,0) -> 0.068429875 | J15: =SUM(D15:H15) -> 1 | K15: =IFERROR(SUMIFS(Data!$E$2:$E$2657,Data!$A$2:$A$2657,$A15)/$C15,0) -> 0.75880012 | L15: =IFERROR(SUMIFS(Data!$G$2:$G$2657,Data!$A$2:$A$2657,$A15)/$C15,0) -> 0.24119988
A16: 2006 | B16: =COUNTIFS('Utility Shares'!$A:$A,$A16) -> 17 | C16: =SUMIFS(Data!$E$2:$E$2657,Data!$A$2:$A$2657,$A16)+SUMIFS(Data!$G$2:$G$2657,Data!$A$2:$A$2657,$A16) -> 8136.5722 | D16: =IFERROR((SUMIFS(Data!$E$2:$E$2657,Data!$A$2:$A$2657,$A16,Data!$D$2:$D$2657,"Transmission")+SUMIFS(Data!$G$2:$G$2657,Data!$A$2:$A$2657,$A16,Data!$D$2:$D$2657,"Transmission"))/$C16,0) -> 0.18719931 | E16: =IFERROR((SUMIFS(Data!$E$2:$E$2657,Data!$A$2:$A$2657,$A16,Data!$D$2:$D$2657,"Distribution")+SUMIFS(Data!$G$2:$G$2657,Data!$A$2:$A$2657,$A16,Data!$D$2:$D$2657,"Distribution"))/$C16,0) -> 0.30238382 | F16: =IFERROR((SUMIFS(Data!$E$2:$E$2657,Data!$A$2:$A$2657,$A16,Data!$D$2:$D$2657,"RTO/market operation")+SUMIFS(Data!$G$2:$G$2657,Data!$A$2:$A$2657,$A16,Data!$D$2:$D$2657,"RTO/market operation"))/$C16,0) -> 0.0037363274 | G16: =IFERROR((SUMIFS(Data!$E$2:$E$2657,Data!$A$2:$A$2657,$A16,Data!$D$2:$D$2657,"Customer accounts, service & sales")+SUMIFS(Data!$G$2:$G$2657,Data!$A$2:$A$2657,$A16,Data!$D$2:$D$2657,"Customer accounts, service & sales"))/$C16,0) -> 0.12527128 | H16: =IFERROR((SUMIFS(Data!$E$2:$E$2657,Data!$A$2:$A$2657,$A16,Data!$D$2:$D$2657,"A&G and general")+SUMIFS(Data!$G$2:$G$2657,Data!$A$2:$A$2657,$A16,Data!$D$2:$D$2657,"A&G and general"))/$C16,0) -> 0.38140926 | I16: =IFERROR(SUMIFS(Data!$F$2:$F$2657,Data!$A$2:$A$2657,$A16)/$C16,0) -> 0.085085051 | J16: =SUM(D16:H16) -> 1 | K16: =IFERROR(SUMIFS(Data!$E$2:$E$2657,Data!$A$2:$A$2657,$A16)/$C16,0) -> 0.72760909 | L16: =IFERROR(SUMIFS(Data!$G$2:$G$2657,Data!$A$2:$A$2657,$A16)/$C16,0) -> 0.27239091
... A35: 2025 | B35: =COUNTIFS('Utility Shares'!$A:$A,$A35) -> 19 | C35: =SUMIFS(Data!$E$2:$E$2657,Data!$A$2:$A$2657,$A35)+SUMIFS(Data!$G$2:$G$2657,Data!$A$2:$A$2657,$A35) -> 17691.271 | D35: =IFERROR((SUMIFS(Data!$E$2:$E$2657,Data!$A$2:$A$2657,$A35,Data!$D$2:$D$2657,"Transmission")+SUMIFS(Data!$G$2:$G$2657,Data!$A$2:$A$2657,$A35,Data!$D$2:$D$2657,"Transmission"))/$C35,0) -> 0.293286 | E35: =IFERROR((SUMIFS(Data!$E$2:$E$2657,Data!$A$2:$A$2657,$A35,Data!$D$2:$D$2657,"Distribution")+SUMIFS(Data!$G$2:$G$2657,Data!$A$2:$A$2657,$A35,Data!$D$2:$D$2657,"Distribution"))/$C35,0) -> 0.35107485 | F35: =IFERROR((SUMIFS(Data!$E$2:$E$2657,Data!$A$2:$A$2657,$A35,Data!$D$2:$D$2657,"RTO/market operation")+SUMIFS(Data!$G$2:$G$2657,Data!$A$2:$A$2657,$A35,Data!$D$2:$D$2657,"RTO/market operation"))/$C35,0) -> 0.0047601564 | G35: =IFERROR((SUMIFS(Data!$E$2:$E$2657,Data!$A$2:$A$2657,$A35,Data!$D$2:$D$2657,"Customer accounts, service & sales")+SUMIFS(Data!$G$2:$G$2657,Data!$A$2:$A$2657,$A35,Data!$D$2:$D$2657,"Customer accounts, service & sales"))/$C35,0) -> 0.11946787 | H35: =IFERROR((SUMIFS(Data!$E$2:$E$2657,Data!$A$2:$A$2657,$A35,Data!$D$2:$D$2657,"A&G and general")+SUMIFS(Data!$G$2:$G$2657,Data!$A$2:$A$2657,$A35,Data!$D$2:$D$2657,"A&G and general"))/$C35,0) -> 0.23141112 | I35: =IFERROR(SUMIFS(Data!$F$2:$F$2657,Data!$A$2:$A$2657,$A35)/$C35,0) -> 0.18645164 | J35: =SUM(D35:H35) -> 1 | K35: =IFERROR(SUMIFS(Data!$E$2:$E$2657,Data!$A$2:$A$2657,$A35)/$C35,0) -> 0.67575031 | L35: =IFERROR(SUMIFS(Data!$G$2:$G$2657,Data!$A$2:$A$2657,$A35)/$C35,0) -> 0.32424969

Sheet Utility Shares
A1: Year | B1: Utility | C1: State | D1: Non-generation total ($mm) | E1: Transmission | F1: Distribution | G1: RTO/market operation | H1: Customer accounts, service & sales | I1: A&G and general | J1: Acct 565 (incl. in Transmission) | K1: Check: shares sum
A2: 1995 | B2: ALLETE (Minnesota Power) | C2: MN | D2: =SUMIFS(Data!$E$2:$E$2657,Data!$A$2:$A$2657,$A2,Data!$B$2:$B$2657,$B2)+SUMIFS(Data!$G$2:$G$2657,Data!$A$2:$A$2657,$A2,Data!$B$2:$B$2657,$B2) -> 89.718785 | E2: =IFERROR((SUMIFS(Data!$E$2:$E$2657,Data!$A$2:$A$2657,$A2,Data!$B$2:$B$2657,$B2,Data!$D$2:$D$2657,"Transmission")+SUMIFS(Data!$G$2:$G$2657,Data!$A$2:$A$2657,$A2,Data!$B$2:$B$2657,$B2,Data!$D$2:$D$2657,"Transmission"))/$D2,0) -> 0.10622106 | F2: =IFERROR((SUMIFS(Data!$E$2:$E$2657,Data!$A$2:$A$2657,$A2,Data!$B$2:$B$2657,$B2,Data!$D$2:$D$2657,"Distribution")+SUMIFS(Data!$G$2:$G$2657,Data!$A$2:$A$2657,$A2,Data!$B$2:$B$2657,$B2,Data!$D$2:$D$2657,"Distribution"))/$D2,0) -> 0.240842 | G2: =IFERROR((SUMIFS(Data!$E$2:$E$2657,Data!$A$2:$A$2657,$A2,Data!$B$2:$B$2657,$B2,Data!$D$2:$D$2657,"RTO/market operation")+SUMIFS(Data!$G$2:$G$2657,Data!$A$2:$A$2657,$A2,Data!$B$2:$B$2657,$B2,Data!$D$2:$D$2657,"RTO/market operation"))/$D2,0) -> 0 | H2: =IFERROR((SUMIFS(Data!$E$2:$E$2657,Data!$A$2:$A$2657,$A2,Data!$B$2:$B$2657,$B2,Data!$D$2:$D$2657,"Customer accounts, service & sales")+SUMIFS(Data!$G$2:$G$2657,Data!$A$2:$A$2657,$A2,Data!$B$2:$B$2657,$B2,Data!$D$2:$D$2657,"Customer accounts, service & sales"))/$D2,0) -> 0.23002834 | I2: =IFERROR((SUMIFS(Data!$E$2:$E$2657,Data!$A$2:$A$2657,$A2,Data!$B$2:$B$2657,$B2,Data!$D$2:$D$2657,"A&G and general")+SUMIFS(Data!$G$2:$G$2657,Data!$A$2:$A$2657,$A2,Data!$B$2:$B$2657,$B2,Data!$D$2:$D$2657,"A&G and general"))/$D2,0) -> 0.4229086 | J2: =IFERROR(SUMIFS(Data!$F$2:$F$2657,Data!$A$2:$A$2657,$A2,Data!$B$2:$B$2657,$B2)/$D2,0) -> 0.002714582 | K2: =SUM(E2:I2) -> 1
A3: 1995 | B3: Ameren Illinois | C3: IL | D3: =SUMIFS(Data!$E$2:$E$2657,Data!$A$2:$A$2657,$A3,Data!$B$2:$B$2657,$B3)+SUMIFS(Data!$G$2:$G$2657,Data!$A$2:$A$2657,$A3,Data!$B$2:$B$2657,$B3) -> 466.97125 | E3: =IFERROR((SUMIFS(Data!$E$2:$E$2657,Data!$A$2:$A$2657,$A3,Data!$B$2:$B$2657,$B3,Data!$D$2:$D$2657,"Transmission")+SUMIFS(Data!$G$2:$G$2657,Data!$A$2:$A$2657,$A3,Data!$B$2:$B$2657,$B3,Data!$D$2:$D$2657,"Transmission"))/$D3,0) -> 0.07482709 | F3: =IFERROR((SUMIFS(Data!$E$2:$E$2657,Data!$A$2:$A$2657,$A3,Data!$B$2:$B$2657,$B3,Data!$D$2:$D$2657,"Distribution")+SUMIFS(Data!$G$2:$G$2657,Data!$A$2:$A$2657,$A3,Data!$B$2:$B$2657,$B3,Data!$D$2:$D$2657,"Distribution"))/$D3,0) -> 0.3033503 | G3: =IFERROR((SUMIFS(Data!$E$2:$E$2657,Data!$A$2:$A$2657,$A3,Data!$B$2:$B$2657,$B3,Data!$D$2:$D$2657,"RTO/market operation")+SUMIFS(Data!$G$2:$G$2657,Data!$A$2:$A$2657,$A3,Data!$B$2:$B$2657,$B3,Data!$D$2:$D$2657,"RTO/market operation"))/$D3,0) -> 0 | H3: =IFERROR((SUMIFS(Data!$E$2:$E$2657,Data!$A$2:$A$2657,$A3,Data!$B$2:$B$2657,$B3,Data!$D$2:$D$2657,"Customer accounts, service & sales")+SUMIFS(Data!$G$2:$G$2657,Data!$A$2:$A$2657,$A3,Data!$B$2:$B$2657,$B3,Data!$D$2:$D$2657,"Customer accounts, service & sales"))/$D3,0) -> 0.10321936 | I3: =IFERROR((SUMIFS(Data!$E$2:$E$2657,Data!$A$2:$A$2657,$A3,Data!$B$2:$B$2657,$B3,Data!$D$2:$D$2657,"A&G and general")+SUMIFS(Data!$G$2:$G$2657,Data!$A$2:$A$2657,$A3,Data!$B$2:$B$2657,$B3,Data!$D$2:$D$2657,"A&G and general"))/$D3,0) -> 0.51860324 | J3: =IFERROR(SUMIFS(Data!$F$2:$F$2657,Data!$A$2:$A$2657,$A3,Data!$B$2:$B$2657,$B3)/$D3,0) -> 1.5778273e-05 | K3: =SUM(E3:I3) -> 1
A4: 1995 | B4: Commonwealth Edison (ComEd) | C4: IL | D4: =SUMIFS(Data!$E$2:$E$2657,Data!$A$2:$A$2657,$A4,Data!$B$2:$B$2657,$B4)+SUMIFS(Data!$G$2:$G$2657,Data!$A$2:$A$2657,$A4,Data!$B$2:$B$2657,$B4) -> 1233.2446 | E4: =IFERROR((SUMIFS(Data!$E$2:$E$2657,Data!$A$2:$A$2657,$A4,Data!$B$2:$B$2657,$B4,Data!$D$2:$D$2657,"Transmission")+SUMIFS(Data!$G$2:$G$2657,Data!$A$2:$A$2657,$A4,Data!$B$2:$B$2657,$B4,Data!$D$2:$D$2657,"Transmission"))/$D4,0) -> 0.080642753 | F4: =IFERROR((SUMIFS(Data!$E$2:$E$2657,Data!$A$2:$A$2657,$A4,Data!$B$2:$B$2657,$B4,Data!$D$2:$D$2657,"Distribution")+SUMIFS(Data!$G$2:$G$2657,Data!$A$2:$A$2657,$A4,Data!$B$2:$B$2657,$B4,Data!$D$2:$D$2657,"Distribution"))/$D4,0) -> 0.30475218 | G4: =IFERROR((SUMIFS(Data!$E$2:$E$2657,Data!$A$2:$A$2657,$A4,Data!$B$2:$B$2657,$B4,Data!$D$2:$D$2657,"RTO/market operation")+SUMIFS(Data!$G$2:$G$2657,Data!$A$2:$A$2657,$A4,Data!$B$2:$B$2657,$B4,Data!$D$2:$D$2657,"RTO/market operation"))/$D4,0) -> 0 | H4: =IFERROR((SUMIFS(Data!$E$2:$E$2657,Data!$A$2:$A$2657,$A4,Data!$B$2:$B$2657,$B4,Data!$D$2:$D$2657,"Customer accounts, service & sales")+SUMIFS(Data!$G$2:$G$2657,Data!$A$2:$A$2657,$A4,Data!$B$2:$B$2657,$B4,Data!$D$2:$D$2657,"Customer accounts, service & sales"))/$D4,0) -> 0.13621169 | I4: =IFERROR((SUMIFS(Data!$E$2:$E$2657,Data!$A$2:$A$2657,$A4,Data!$B$2:$B$2657,$B4,Data!$D$2:$D$2657,"A&G and general")+SUMIFS(Data!$G$2:$G$2657,Data!$A$2:$A$2657,$A4,Data!$B$2:$B$2657,$B4,Data!$D$2:$D$2657,"A&G and general"))/$D4,0) -> 0.47839338 | J4: =IFERROR(SUMIFS(Data!$F$2:$F$2657,Data!$A$2:$A$2657,$A4,Data!$B$2:$B$2657,$B4)/$D4,0) -> 0.00018009728 | K4: =SUM(E4:I4) -> 1
A5: 1995 | B5: Consumers Energy | C5: MI | D5: =SUMIFS(Data!$E$2:$E$2657,Data!$A$2:$A$2657,$A5,Data!$B$2:$B$2657,$B5)+SUMIFS(Data!$G$2:$G$2657,Data!$A$2:$A$2657,$A5,Data!$B$2:$B$2657,$B5) -> 447.91099 | E5: =IFERROR((SUMIFS(Data!$E$2:$E$2657,Data!$A$2:$A$2657,$A5,Data!$B$2:$B$2657,$B5,Data!$D$2:$D$2657,"Transmission")+SUMIFS(Data!$G$2:$G$2657,Data!$A$2:$A$2657,$A5,Data!$B$2:$B$2657,$B5,Data!$D$2:$D$2657,"Transmission"))/$D5,0) -> 0.086435158 | F5: =IFERROR((SUMIFS(Data!$E$2:$E$2657,Data!$A$2:$A$2657,$A5,Data!$B$2:$B$2657,$B5,Data!$D$2:$D$2657,"Distribution")+SUMIFS(Data!$G$2:$G$2657,Data!$A$2:$A$2657,$A5,Data!$B$2:$B$2657,$B5,Data!$D$2:$D$2657,"Distribution"))/$D5,0) -> 0.38311152 | G5: =IFERROR((SUMIFS(Data!$E$2:$E$2657,Data!$A$2:$A$2657,$A5,Data!$B$2:$B$2657,$B5,Data!$D$2:$D$2657,"RTO/market operation")+SUMIFS(Data!$G$2:$G$2657,Data!$A$2:$A$2657,$A5,Data!$B$2:$B$2657,$B5,Data!$D$2:$D$2657,"RTO/market operation"))/$D5,0) -> 0 | H5: =IFERROR((SUMIFS(Data!$E$2:$E$2657,Data!$A$2:$A$2657,$A5,Data!$B$2:$B$2657,$B5,Data!$D$2:$D$2657,"Customer accounts, service & sales")+SUMIFS(Data!$G$2:$G$2657,Data!$A$2:$A$2657,$A5,Data!$B$2:$B$2657,$B5,Data!$D$2:$D$2657,"Customer accounts, service & sales"))/$D5,0) -> 0.17217348 | I5: =IFERROR((SUMIFS(Data!$E$2:$E$2657,Data!$A$2:$A$2657,$A5,Data!$B$2:$B$2657,$B5,Data!$D$2:$D$2657,"A&G and general")+SUMIFS(Data!$G$2:$G$2657,Data!$A$2:$A$2657,$A5,Data!$B$2:$B$2657,$B5,Data!$D$2:$D$2657,"A&G and general"))/$D5,0) -> 0.35827985 | J5: =IFERROR(SUMIFS(Data!$F$2:$F$2657,Data!$A$2:$A$2657,$A5,Data!$B$2:$B$2657,$B5)/$D5,0) -> 0 | K5: =SUM(E5:I5) -> 1
A6: 1995 | B6: DTE Electric | C6: MI | D6: =SUMIFS(Data!$E$2:$E$2657,Data!$A$2:$A$2657,$A6,Data!$B$2:$B$2657,$B6)+SUMIFS(Data!$G$2:$G$2657,Data!$A$2:$A$2657,$A6,Data!$B$2:$B$2657,$B6) -> 756.03948 | E6: =IFERROR((SUMIFS(Data!$E$2:$E$2657,Data!$A$2:$A$2657,$A6,Data!$B$2:$B$2657,$B6,Data!$D$2:$D$2657,"Transmission")+SUMIFS(Data!$G$2:$G$2657,Data!$A$2:$A$2657,$A6,Data!$B$2:$B$2657,$B6,Data!$D$2:$D$2657,"Transmission"))/$D6,0) -> 0.080249751 | F6: =IFERROR((SUMIFS(Data!$E$2:$E$2657,Data!$A$2:$A$2657,$A6,Data!$B$2:$B$2657,$B6,Data!$D$2:$D$2657,"Distribution")+SUMIFS(Data!$G$2:$G$2657,Data!$A$2:$A$2657,$A6,Data!$B$2:$B$2657,$B6,Data!$D$2:$D$2657,"Distribution"))/$D6,0) -> 0.3322246 | G6: =IFERROR((SUMIFS(Data!$E$2:$E$2657,Data!$A$2:$A$2657,$A6,Data!$B$2:$B$2657,$B6,Data!$D$2:$D$2657,"RTO/market operation")+SUMIFS(Data!$G$2:$G$2657,Data!$A$2:$A$2657,$A6,Data!$B$2:$B$2657,$B6,Data!$D$2:$D$2657,"RTO/market operation"))/$D6,0) -> 0 | H6: =IFERROR((SUMIFS(Data!$E$2:$E$2657,Data!$A$2:$A$2657,$A6,Data!$B$2:$B$2657,$B6,Data!$D$2:$D$2657,"Customer accounts, service & sales")+SUMIFS(Data!$G$2:$G$2657,Data!$A$2:$A$2657,$A6,Data!$B$2:$B$2657,$B6,Data!$D$2:$D$2657,"Customer accounts, service & sales"))/$D6,0) -> 0.11424144 | I6: =IFERROR((SUMIFS(Data!$E$2:$E$2657,Data!$A$2:$A$2657,$A6,Data!$B$2:$B$2657,$B6,Data!$D$2:$D$2657,"A&G and general")+SUMIFS(Data!$G$2:$G$2657,Data!$A$2:$A$2657,$A6,Data!$B$2:$B$2657,$B6,Data!$D$2:$D$2657,"A&G and general"))/$D6,0) -> 0.47328421 | J6: =IFERROR(SUMIFS(Data!$F$2:$F$2657,Data!$A$2:$A$2657,$A6,Data!$B$2:$B$2657,$B6)/$D6,0) -> -1.9073078e-06 | K6: =SUM(E6:I6) -> 1
A7: 1995 | B7: Duke Energy Indiana | C7: IN | D7: =SUMIFS(Data!$E$2:$E$2657,Data!$A$2:$A$2657,$A7,Data!$B$2:$B$2657,$B7)+SUMIFS(Data!$G$2:$G$2657,Data!$A$2:$A$2657,$A7,Data!$B$2:$B$2657,$B7) -> 281.87085 | E7: =IFERROR((SUMIFS(Data!$E$2:$E$2657,Data!$A$2:$A$2657,$A7,Data!$B$2:$B$2657,$B7,Data!$D$2:$D$2657,"Transmission")+SUMIFS(Data!$G$2:$G$2657,Data!$A$2:$A$2657,$A7,Data!$B$2:$B$2657,$B7,Data!$D$2:$D$2657,"Transmission"))/$D7,0) -> 0.084719204 | F7: =IFERROR((SUMIFS(Data!$E$2:$E$2657,Data!$A$2:$A$2657,$A7,Data!$B$2:$B$2657,$B7,Data!$D$2:$D$2657,"Distribution")+SUMIFS(Data!$G$2:$G$2657,Data!$A$2:$A$2657,$A7,Data!$B$2:$B$2657,$B7,Data!$D$2:$D$2657,"Distribution"))/$D7,0) -> 0.25887843 | G7: =IFERROR((SUMIFS(Data!$E$2:$E$2657,Data!$A$2:$A$2657,$A7,Data!$B$2:$B$2657,$B7,Data!$D$2:$D$2657,"RTO/market operation")+SUMIFS(Data!$G$2:$G$2657,Data!$A$2:$A$2657,$A7,Data!$B$2:$B$2657,$B7,Data!$D$2:$D$2657,"RTO/market operation"))/$D7,0) -> 0 | H7: =IFERROR((SUMIFS(Data!$E$2:$E$2657,Data!$A$2:$A$2657,$A7,Data!$B$2:$B$2657,$B7,Data!$D$2:$D$2657,"Customer accounts, service & sales")+SUMIFS(Data!$G$2:$G$2657,Data!$A$2:$A$2657,$A7,Data!$B$2:$B$2657,$B7,Data!$D$2:$D$2657,"Customer accounts, service & sales"))/$D7,0) -> 0.18168259 | I7: =IFERROR((SUMIFS(Data!$E$2:$E$2657,Data!$A$2:$A$2657,$A7,Data!$B$2:$B$2657,$B7,Data!$D$2:$D$2657,"A&G and general")+SUMIFS(Data!$G$2:$G$2657,Data!$A$2:$A$2657,$A7,Data!$B$2:$B$2657,$B7,Data!$D$2:$D$2657,"A&G and general"))/$D7,0) -> 0.47471977 | J7: =IFERROR(SUMIFS(Data!$F$2:$F$2657,Data!$A$2:$A$2657,$A7,Data!$B$2:$B$2657,$B7)/$D7,0) -> 0.0015607893 | K7: =SUM(E7:I7) -> 1
A8: 1995 | B8: Indiana Michigan Power | C8: IN/MI | D8: =SUMIFS(Data!$E$2:$E$2657,Data!$A$2:$A$2657,$A8,Data!$B$2:$B$2657,$B8)+SUMIFS(Data!$G$2:$G$2657,Data!$A$2:$A$2657,$A8,Data!$B$2:$B$2657,$B8) -> 182.46151 | E8: =IFERROR((SUMIFS(Data!$E$2:$E$2657,Data!$A$2:$A$2657,$A8,Data!$B$2:$B$2657,$B8,Data!$D$2:$D$2657,"Transmission")+SUMIFS(Data!$G$2:$G$2657,Data!$A$2:$A$2657,$A8,Data!$B$2:$B$2657,$B8,Data!$D$2:$D$2657,"Transmission"))/$D8,0) -> -0.060894519 | F8: =IFERROR((SUMIFS(Data!$E$2:$E$2657,Data!$A$2:$A$2657,$A8,Data!$B$2:$B$2657,$B8,Data!$D$2:$D$2657,"Distribution")+SUMIFS(Data!$G$2:$G$2657,Data!$A$2:$A$2657,$A8,Data!$B$2:$B$2657,$B8,Data!$D$2:$D$2657,"Distribution"))/$D8,0) -> 0.37053425 | G8: =IFERROR((SUMIFS(Data!$E$2:$E$2657,Data!$A$2:$A$2657,$A8,Data!$B$2:$B$2657,$B8,Data!$D$2:$D$2657,"RTO/market operation")+SUMIFS(Data!$G$2:$G$2657,Data!$A$2:$A$2657,$A8,Data!$B$2:$B$2657,$B8,Data!$D$2:$D$2657,"RTO/market operation"))/$D8,0) -> 0 | H8: =IFERROR((SUMIFS(Data!$E$2:$E$2657,Data!$A$2:$A$2657,$A8,Data!$B$2:$B$2657,$B8,Data!$D$2:$D$2657,"Customer accounts, service & sales")+SUMIFS(Data!$G$2:$G$2657,Data!$A$2:$A$2657,$A8,Data!$B$2:$B$2657,$B8,Data!$D$2:$D$2657,"Customer accounts, service & sales"))/$D8,0) -> 0.14620455 | I8: =IFERROR((SUMIFS(Data!$E$2:$E$2657,Data!$A$2:$A$2657,$A8,Data!$B$2:$B$2657,$B8,Data!$D$2:$D$2657,"A&G and general")+SUMIFS(Data!$G$2:$G$2657,Data!$A$2:$A$2657,$A8,Data!$B$2:$B$2657,$B8,Data!$D$2:$D$2657,"A&G and general"))/$D8,0) -> 0.54415572 | J8: =IFERROR(SUMIFS(Data!$F$2:$F$2657,Data!$A$2:$A$2657,$A8,Data!$B$2:$B$2657,$B8)/$D8,0) -> -0.25577277 | K8: =SUM(E8:I8) -> 1
A9: 1995 | B9: Indianapolis Power & Light (AES Indiana) | C9: IN | D9: =SUMIFS(Data!$E$2:$E$2657,Data!$A$2:$A$2657,$A9,Data!$B$2:$B$2657,$B9)+SUMIFS(Data!$G$2:$G$2657,Data!$A$2:$A$2657,$A9,Data!$B$2:$B$2657,$B9) -> 152.43452 | E9: =IFERROR((SUMIFS(Data!$E$2:$E$2657,Data!$A$2:$A$2657,$A9,Data!$B$2:$B$2657,$B9,Data!$D$2:$D$2657,"Transmission")+SUMIFS(Data!$G$2:$G$2657,Data!$A$2:$A$2657,$A9,Data!$B$2:$B$2657,$B9,Data!$D$2:$D$2657,"Transmission"))/$D9,0) -> 0.074071319 | F9: =IFERROR((SUMIFS(Data!$E$2:$E$2657,Data!$A$2:$A$2657,$A9,Data!$B$2:$B$2657,$B9,Data!$D$2:$D$2657,"Distribution")+SUMIFS(Data!$G$2:$G$2657,Data!$A$2:$A$2657,$A9,Data!$B$2:$B$2657,$B9,Data!$D$2:$D$2657,"Distribution"))/$D9,0) -> 0.38204587 | G9: =IFERROR((SUMIFS(Data!$E$2:$E$2657,Data!$A$2:$A$2657,$A9,Data!$B$2:$B$2657,$B9,Data!$D$2:$D$2657,"RTO/market operation")+SUMIFS(Data!$G$2:$G$2657,Data!$A$2:$A$2657,$A9,Data!$B$2:$B$2657,$B9,Data!$D$2:$D$2657,"RTO/market operation"))/$D9,0) -> 0 | H9: =IFERROR((SUMIFS(Data!$E$2:$E$2657,Data!$A$2:$A$2657,$A9,Data!$B$2:$B$2657,$B9,Data!$D$2:$D$2657,"Customer accounts, service & sales")+SUMIFS(Data!$G$2:$G$2657,Data!$A$2:$A$2657,$A9,Data!$B$2:$B$2657,$B9,Data!$D$2:$D$2657,"Customer accounts, service & sales"))/$D9,0) -> 0.11678813 | I9: =IFERROR((SUMIFS(Data!$E$2:$E$2657,Data!$A$2:$A$2657,$A9,Data!$B$2:$B$2657,$B9,Data!$D$2:$D$2657,"A&G and general")+SUMIFS(Data!$G$2:$G$2657,Data!$A$2:$A$2657,$A9,Data!$B$2:$B$2657,$B9,Data!$D$2:$D$2657,"A&G and general"))/$D9,0) -> 0.42709468 | J9: =IFERROR(SUMIFS(Data!$F$2:$F$2657,Data!$A$2:$A$2657,$A9,Data!$B$2:$B$2657,$B9)/$D9,0) -> 0 | K9: =SUM(E9:I9) -> 1
A10: 1995 | B10: Interstate Power & Light | C10: IA | D10: =SUMIFS(Data!$E$2:$E$2657,Data!$A$2:$A$2657,$A10,Data!$B$2:$B$2657,$B10)+SUMIFS(Data!$G$2:$G$2657,Data!$A$2:$A$2657,$A10,Data!$B$2:$B$2657,$B10) -> 180.85664 | E10: =IFERROR((SUMIFS(Data!$E$2:$E$2657,Data!$A$2:$A$2657,$A10,Data!$B$2:$B$2657,$B10,Data!$D$2:$D$2657,"Transmission")+SUMIFS(Data!$G$2:$G$2657,Data!$A$2:$A$2657,$A10,Data!$B$2:$B$2657,$B10,Data!$D$2:$D$2657,"Transmission"))/$D10,0) -> 0.1310422 | F10: =IFERROR((SUMIFS(Data!$E$2:$E$2657,Data!$A$2:$A$2657,$A10,Data!$B$2:$B$2657,$B10,Data!$D$2:$D$2657,"Distribution")+SUMIFS(Data!$G$2:$G$2657,Data!$A$2:$A$2657,$A10,Data!$B$2:$B$2657,$B10,Data!$D$2:$D$2657,"Distribution"))/$D10,0) -> 0.32780673 | G10: =IFERROR((SUMIFS(Data!$E$2:$E$2657,Data!$A$2:$A$2657,$A10,Data!$B$2:$B$2657,$B10,Data!$D$2:$D$2657,"RTO/market operation")+SUMIFS(Data!$G$2:$G$2657,Data!$A$2:$A$2657,$A10,Data!$B$2:$B$2657,$B10,Data!$D$2:$D$2657,"RTO/market operation"))/$D10,0) -> 0 | H10: =IFERROR((SUMIFS(Data!$E$2:$E$2657,Data!$A$2:$A$2657,$A10,Data!$B$2:$B$2657,$B10,Data!$D$2:$D$2657,"Customer accounts, service & sales")+SUMIFS(Data!$G$2:$G$2657,Data!$A$2:$A$2657,$A10,Data!$B$2:$B$2657,$B10,Data!$D$2:$D$2657,"Customer accounts, service & sales"))/$D10,0) -> 0.094287777 | I10: =IFERROR((SUMIFS(Data!$E$2:$E$2657,Data!$A$2:$A$2657,$A10,Data!$B$2:$B$2657,$B10,Data!$D$2:$D$2657,"A&G and general")+SUMIFS(Data!$G$2:$G$2657,Data!$A$2:$A$2657,$A10,Data!$B$2:$B$2657,$B10,Data!$D$2:$D$2657,"A&G and general"))/$D10,0) -> 0.4468633 | J10: =IFERROR(SUMIFS(Data!$F$2:$F$2657,Data!$A$2:$A$2657,$A10,Data!$B$2:$B$2657,$B10)/$D10,0) -> 0.0225484 | K10: =SUM(E10:I10) -> 1
A11: 1995 | B11: Madison Gas & Electric | C11: WI | D11: =SUMIFS(Data!$E$2:$E$2657,Data!$A$2:$A$2657,$A11,Data!$B$2:$B$2657,$B11)+SUMIFS(Data!$G$2:$G$2657,Data!$A$2:$A$2657,$A11,Data!$B$2:$B$2657,$B11) -> 42.807555 | E11: =IFERROR((SUMIFS(Data!$E$2:$E$2657,Data!$A$2:$A$2657,$A11,Data!$B$2:$B$2657,$B11,Data!$D$2:$D$2657,"Transmission")+SUMIFS(Data!$G$2:$G$2657,Data!$A$2:$A$2657,$A11,Data!$B$2:$B$2657,$B11,Data!$D$2:$D$2657,"Transmission"))/$D11,0) -> 0.10310792 | F11: =IFERROR((SUMIFS(Data!$E$2:$E$2657,Data!$A$2:$A$2657,$A11,Data!$B$2:$B$2657,$B11,Data!$D$2:$D$2657,"Distribution")+SUMIFS(Data!$G$2:$G$2657,Data!$A$2:$A$2657,$A11,Data!$B$2:$B$2657,$B11,Data!$D$2:$D$2657,"Distribution"))/$D11,0) -> 0.26162826 | G11: =IFERROR((SUMIFS(Data!$E$2:$E$2657,Data!$A$2:$A$2657,$A11,Data!$B$2:$B$2657,$B11,Data!$D$2:$D$2657,"RTO/market operation")+SUMIFS(Data!$G$2:$G$2657,Data!$A$2:$A$2657,$A11,Data!$B$2:$B$2657,$B11,Data!$D$2:$D$2657,"RTO/market operation"))/$D11,0) -> 0 | H11: =IFERROR((SUMIFS(Data!$E$2:$E$2657,Data!$A$2:$A$2657,$A11,Data!$B$2:$B$2657,$B11,Data!$D$2:$D$2657,"Customer accounts, service & sales")+SUMIFS(Data!$G$2:$G$2657,Data!$A$2:$A$2657,$A11,Data!$B$2:$B$2657,$B11,Data!$D$2:$D$2657,"Customer accounts, service & sales"))/$D11,0) -> 0.20657305 | I11: =IFERROR((SUMIFS(Data!$E$2:$E$2657,Data!$A$2:$A$2657,$A11,Data!$B$2:$B$2657,$B11,Data!$D$2:$D$2657,"A&G and general")+SUMIFS(Data!$G$2:$G$2657,Data!$A$2:$A$2657,$A11,Data!$B$2:$B$2657,$B11,Data!$D$2:$D$2657,"A&G and general"))/$D11,0) -> 0.42869078 | J11: =IFERROR(SUMIFS(Data!$F$2:$F$2657,Data!$A$2:$A$2657,$A11,Data!$B$2:$B$2657,$B11)/$D11,0) -> 0.0054208188 | K11: =SUM(E11:I11) -> 1
A12: 1995 | B12: MidAmerican Energy | C12: IA | D12: =SUMIFS(Data!$E$2:$E$2657,Data!$A$2:$A$2657,$A12,Data!$B$2:$B$2657,$B12)+SUMIFS(Data!$G$2:$G$2657,Data!$A$2:$A$2657,$A12,Data!$B$2:$B$2657,$B12) -> 261.5407 | E12: =IFERROR((SUMIFS(Data!$E$2:$E$2657,Data!$A$2:$A$2657,$A12,Data!$B$2:$B$2657,$B12,Data!$D$2:$D$2657,"Transmission")+SUMIFS(Data!$G$2:$G$2657,Data!$A$2:$A$2657,$A12,Data!$B$2:$B$2657,$B12,Data!$D$2:$D$2657,"Transmission"))/$D12,0) -> 0.084450248 | F12: =IFERROR((SUMIFS(Data!$E$2:$E$2657,Data!$A$2:$A$2657,$A12,Data!$B$2:$B$2657,$B12,Data!$D$2:$D$2657,"Distribution")+SUMIFS(Data!$G$2:$G$2657,Data!$A$2:$A$2657,$A12,Data!$B$2:$B$2657,$B12,Data!$D$2:$D$2657,"Distribution"))/$D12,0) -> 0.30172791 | G12: =IFERROR((SUMIFS(Data!$E$2:$E$2657,Data!$A$2:$A$2657,$A12,Data!$B$2:$B$2657,$B12,Data!$D$2:$D$2657,"RTO/market operation")+SUMIFS(Data!$G$2:$G$2657,Data!$A$2:$A$2657,$A12,Data!$B$2:$B$2657,$B12,Data!$D$2:$D$2657,"RTO/market operation"))/$D12,0) -> 0 | H12: =IFERROR((SUMIFS(Data!$E$2:$E$2657,Data!$A$2:$A$2657,$A12,Data!$B$2:$B$2657,$B12,Data!$D$2:$D$2657,"Customer accounts, service & sales")+SUMIFS(Data!$G$2:$G$2657,Data!$A$2:$A$2657,$A12,Data!$B$2:$B$2657,$B12,Data!$D$2:$D$2657,"Customer accounts, service & sales"))/$D12,0) -> 0.12861103 | I12: =IFERROR((SUMIFS(Data!$E$2:$E$2657,Data!$A$2:$A$2657,$A12,Data!$B$2:$B$2657,$B12,Data!$D$2:$D$2657,"A&G and general")+SUMIFS(Data!$G$2:$G$2657,Data!$A$2:$A$2657,$A12,Data!$B$2:$B$2657,$B12,Data!$D$2:$D$2657,"A&G and general"))/$D12,0) -> 0.48521082 | J12: =IFERROR(SUMIFS(Data!$F$2:$F$2657,Data!$A$2:$A$2657,$A12,Data!$B$2:$B$2657,$B12)/$D12,0) -> 0.0018981061 | K12: =SUM(E12:I12) -> 1
A13: 1995 | B13: NIPSCO | C13: IN | D13: =SUMIFS(Data!$E$2:$E$2657,Data!$A$2:$A$2657,$A13,Data!$B$2:$B$2657,$B13)+SUMIFS(Data!$G$2:$G$2657,Data!$A$2:$A$2657,$A13,Data!$B$2:$B$2657,$B13) -> 197.6338 | E13: =IFERROR((SUMIFS(Data!$E$2:$E$2657,Data!$A$2:$A$2657,$A13,Data!$B$2:$B$2657,$B13,Data!$D$2:$D$2657,"Transmission")+SUMIFS(Data!$G$2:$G$2657,Data!$A$2:$A$2657,$A13,Data!$B$2:$B$2657,$B13,Data!$D$2:$D$2657,"Transmission"))/$D13,0) -> 0.13937136 | F13: =IFERROR((SUMIFS(Data!$E$2:$E$2657,Data!$A$2:$A$2657,$A13,Data!$B$2:$B$2657,$B13,Data!$D$2:$D$2657,"Distribution")+SUMIFS(Data!$G$2:$G$2657,Data!$A$2:$A$2657,$A13,Data!$B$2:$B$2657,$B13,Data!$D$2:$D$2657,"Distribution"))/$D13,0) -> 0.27589843 | G13: =IFERROR((SUMIFS(Data!$E$2:$E$2657,Data!$A$2:$A$2657,$A13,Data!$B$2:$B$2657,$B13,Data!$D$2:$D$2657,"RTO/market operation")+SUMIFS(Data!$G$2:$G$2657,Data!$A$2:$A$2657,$A13,Data!$B$2:$B$2657,$B13,Data!$D$2:$D$2657,"RTO/market operation"))/$D13,0) -> 0 | H13: =IFERROR((SUMIFS(Data!$E$2:$E$2657,Data!$A$2:$A$2657,$A13,Data!$B$2:$B$2657,$B13,Data!$D$2:$D$2657,"Customer accounts, service & sales")+SUMIFS(Data!$G$2:$G$2657,Data!$A$2:$A$2657,$A13,Data!$B$2:$B$2657,$B13,Data!$D$2:$D$2657,"Customer accounts, service & sales"))/$D13,0) -> 0.12247373 | I13: =IFERROR((SUMIFS(Data!$E$2:$E$2657,Data!$A$2:$A$2657,$A13,Data!$B$2:$B$2657,$B13,Data!$D$2:$D$2657,"A&G and general")+SUMIFS(Data!$G$2:$G$2657,Data!$A$2:$A$2657,$A13,Data!$B$2:$B$2657,$B13,Data!$D$2:$D$2657,"A&G and general"))/$D13,0) -> 0.46225648 | J13: =IFERROR(SUMIFS(Data!$F$2:$F$2657,Data!$A$2:$A$2657,$A13,Data!$B$2:$B$2657,$B13)/$D13,0) -> 0.0010356225 | K13: =SUM(E13:I13) -> 1
... A584: 2025 | B584: Wisconsin Public Service | C584: WI | D584: =SUMIFS(Data!$E$2:$E$2657,Data!$A$2:$A$2657,$A584,Data!$B$2:$B$2657,$B584)+SUMIFS(Data!$G$2:$G$2657,Data!$A$2:$A$2657,$A584,Data!$B$2:$B$2657,$B584) -> 413.25671 | E584: =IFERROR((SUMIFS(Data!$E$2:$E$2657,Data!$A$2:$A$2657,$A584,Data!$B$2:$B$2657,$B584,Data!$D$2:$D$2657,"Transmission")+SUMIFS(Data!$G$2:$G$2657,Data!$A$2:$A$2657,$A584,Data!$B$2:$B$2657,$B584,Data!$D$2:$D$2657,"Transmission"))/$D584,0) -> 0.43897974 | F584: =IFERROR((SUMIFS(Data!$E$2:$E$2657,Data!$A$2:$A$2657,$A584,Data!$B$2:$B$2657,$B584,Data!$D$2:$D$2657,"Distribution")+SUMIFS(Data!$G$2:$G$2657,Data!$A$2:$A$2657,$A584,Data!$B$2:$B$2657,$B584,Data!$D$2:$D$2657,"Distribution"))/$D584,0) -> 0.27154684 | G584: =IFERROR((SUMIFS(Data!$E$2:$E$2657,Data!$A$2:$A$2657,$A584,Data!$B$2:$B$2657,$B584,Data!$D$2:$D$2657,"RTO/market operation")+SUMIFS(Data!$G$2:$G$2657,Data!$A$2:$A$2657,$A584,Data!$B$2:$B$2657,$B584,Data!$D$2:$D$2657,"RTO/market operation"))/$D584,0) -> 0.0048134487 | H584: =IFERROR((SUMIFS(Data!$E$2:$E$2657,Data!$A$2:$A$2657,$A584,Data!$B$2:$B$2657,$B584,Data!$D$2:$D$2657,"Customer accounts, service & sales")+SUMIFS(Data!$G$2:$G$2657,Data!$A$2:$A$2657,$A584,Data!$B$2:$B$2657,$B584,Data!$D$2:$D$2657,"Customer accounts, service & sales"))/$D584,0) -> 0.10143361 | I584: =IFERROR((SUMIFS(Data!$E$2:$E$2657,Data!$A$2:$A$2657,$A584,Data!$B$2:$B$2657,$B584,Data!$D$2:$D$2657,"A&G and general")+SUMIFS(Data!$G$2:$G$2657,Data!$A$2:$A$2657,$A584,Data!$B$2:$B$2657,$B584,Data!$D$2:$D$2657,"A&G and general"))/$D584,0) -> 0.18322637 | J584: =IFERROR(SUMIFS(Data!$F$2:$F$2657,Data!$A$2:$A$2657,$A584,Data!$B$2:$B$2657,$B584)/$D584,0) -> 0.42294433 | K584: =SUM(E584:I584) -> 1

Sheet Reconciliation
A1: Reconciliation of line items to reported totals, by utility and year
A2: Tolerance (share of reported total): | D2: 0.005
A3: Line-item O&M: sum of the O&M line items used in this workbook (credit accounts 504, 522, 922, 929 as negative). Reported O&M: PUDL row operations_and_maintenance_expenses_electric. Depreciation function rows: p. 336 depreciation_amortization_total for each plant function, after removing duplicate rows (column H). Reported depreciation: the p. 336 total-function row.
A5: Year | B5: Utility | C5: Line-item O&M ($mm) | D5: Reported total electric O&M ($mm) | E5: O&M difference ($mm) | F5: O&M difference (%) | G5: Depreciation function rows ($mm) | H5: Duplicate row removed ($mm) | I5: Reported total depreciation ($mm) | J5: Depreciation difference ($mm) | K5: Depreciation difference (%) | L5: Status | M5: Helper: absolute O&M difference, included rows ($mm)
A6: 1995 | B6: ALLETE (Minnesota Power) | C6: 284.24026 | D6: 284.24026 | E6: =IF(D6="","",C6-D6) -> 0 | F6: =IF(OR(D6="",D6=0),"",E6/D6) -> 0 | G6: 36.61544 | H6: 0 | I6: 36.61544 | J6: =IF(I6="","",G6-I6) -> 0 | K6: =IF(OR(I6="",I6=0),"",J6/I6) -> 0 | L6: =IF(OR(D6="",I6=""),"No reported total for O&M or depreciation",IF(AND(ABS(F6)<=$D$2,ABS(K6)<=$D$2),"Reconciles within tolerance","Outside tolerance")) -> Reconciles within tolerance | M6: =IF(OR(E6="",LEFT(L6,8)="Excluded"),"",ABS(E6)) -> 0
A7: 1996 | B7: ALLETE (Minnesota Power) | C7: 307.19231 | D7: 307.19231 | E7: =IF(D7="","",C7-D7) -> 0 | F7: =IF(OR(D7="",D7=0),"",E7/D7) -> 0 | G7: 37.954656 | H7: 0 | I7: 37.954656 | J7: =IF(I7="","",G7-I7) -> 0 | K7: =IF(OR(I7="",I7=0),"",J7/I7) -> 0 | L7: =IF(OR(D7="",I7=""),"No reported total for O&M or depreciation",IF(AND(ABS(F7)<=$D$2,ABS(K7)<=$D$2),"Reconciles within tolerance","Outside tolerance")) -> Reconciles within tolerance | M7: =IF(OR(E7="",LEFT(L7,8)="Excluded"),"",ABS(E7)) -> 0
A8: 1997 | B8: ALLETE (Minnesota Power) | C8: 312.01781 | D8: 312.01781 | E8: =IF(D8="","",C8-D8) -> 0 | F8: =IF(OR(D8="",D8=0),"",E8/D8) -> 0 | G8: 39.398779 | H8: 0 | I8: 39.398779 | J8: =IF(I8="","",G8-I8) -> 0 | K8: =IF(OR(I8="",I8=0),"",J8/I8) -> 0 | L8: =IF(OR(D8="",I8=""),"No reported total for O&M or depreciation",IF(AND(ABS(F8)<=$D$2,ABS(K8)<=$D$2),"Reconciles within tolerance","Outside tolerance")) -> Reconciles within tolerance | M8: =IF(OR(E8="",LEFT(L8,8)="Excluded"),"",ABS(E8)) -> 0
A9: 1998 | B9: ALLETE (Minnesota Power) | C9: 323.89261 | D9: 323.89261 | E9: =IF(D9="","",C9-D9) -> 0 | F9: =IF(OR(D9="",D9=0),"",E9/D9) -> 0 | G9: 40.52345 | H9: 0 | I9: 40.52345 | J9: =IF(I9="","",G9-I9) -> 0 | K9: =IF(OR(I9="",I9=0),"",J9/I9) -> 0 | L9: =IF(OR(D9="",I9=""),"No reported total for O&M or depreciation",IF(AND(ABS(F9)<=$D$2,ABS(K9)<=$D$2),"Reconciles within tolerance","Outside tolerance")) -> Reconciles within tolerance | M9: =IF(OR(E9="",LEFT(L9,8)="Excluded"),"",ABS(E9)) -> 0
A10: 1999 | B10: ALLETE (Minnesota Power) | C10: 325.58368 | D10: 325.58368 | E10: =IF(D10="","",C10-D10) -> 0 | F10: =IF(OR(D10="",D10=0),"",E10/D10) -> 0 | G10: 39.13347 | H10: 0 | I10: 39.13347 | J10: =IF(I10="","",G10-I10) -> 0 | K10: =IF(OR(I10="",I10=0),"",J10/I10) -> 0 | L10: =IF(OR(D10="",I10=""),"No reported total for O&M or depreciation",IF(AND(ABS(F10)<=$D$2,ABS(K10)<=$D$2),"Reconciles within tolerance","Outside tolerance")) -> Reconciles within tolerance | M10: =IF(OR(E10="",LEFT(L10,8)="Excluded"),"",ABS(E10)) -> 0
A11: 2000 | B11: ALLETE (Minnesota Power) | C11: 346.31205 | D11: 346.31205 | E11: =IF(D11="","",C11-D11) -> 0 | F11: =IF(OR(D11="",D11=0),"",E11/D11) -> 0 | G11: 40.137973 | H11: 0 | I11: 40.137973 | J11: =IF(I11="","",G11-I11) -> 0 | K11: =IF(OR(I11="",I11=0),"",J11/I11) -> 0 | L11: =IF(OR(D11="",I11=""),"No reported total for O&M or depreciation",IF(AND(ABS(F11)<=$D$2,ABS(K11)<=$D$2),"Reconciles within tolerance","Outside tolerance")) -> Reconciles within tolerance | M11: =IF(OR(E11="",LEFT(L11,8)="Excluded"),"",ABS(E11)) -> 0
A12: 2001 | B12: ALLETE (Minnesota Power) | C12: 354.84481 | D12: 354.84481 | E12: =IF(D12="","",C12-D12) -> 0 | F12: =IF(OR(D12="",D12=0),"",E12/D12) -> 0 | G12: 38.350605 | H12: 0 | I12: 38.350605 | J12: =IF(I12="","",G12-I12) -> 0 | K12: =IF(OR(I12="",I12=0),"",J12/I12) -> 0 | L12: =IF(OR(D12="",I12=""),"No reported total for O&M or depreciation",IF(AND(ABS(F12)<=$D$2,ABS(K12)<=$D$2),"Reconciles within tolerance","Outside tolerance")) -> Reconciles within tolerance | M12: =IF(OR(E12="",LEFT(L12,8)="Excluded"),"",ABS(E12)) -> 0
A13: 2002 | B13: ALLETE (Minnesota Power) | C13: 321.44805 | D13: 321.44805 | E13: =IF(D13="","",C13-D13) -> 0 | F13: =IF(OR(D13="",D13=0),"",E13/D13) -> 0 | G13: 38.216688 | H13: 0 | I13: 38.216688 | J13: =IF(I13="","",G13-I13) -> 0 | K13: =IF(OR(I13="",I13=0),"",J13/I13) -> 0 | L13: =IF(OR(D13="",I13=""),"No reported total for O&M or depreciation",IF(AND(ABS(F13)<=$D$2,ABS(K13)<=$D$2),"Reconciles within tolerance","Outside tolerance")) -> Reconciles within tolerance | M13: =IF(OR(E13="",LEFT(L13,8)="Excluded"),"",ABS(E13)) -> 0
A14: 2003 | B14: ALLETE (Minnesota Power) | C14: 342.57603 | D14: 342.57603 | E14: =IF(D14="","",C14-D14) -> 0 | F14: =IF(OR(D14="",D14=0),"",E14/D14) -> 0 | G14: 38.797093 | H14: 0 | I14: 38.797093 | J14: =IF(I14="","",G14-I14) -> 0 | K14: =IF(OR(I14="",I14=0),"",J14/I14) -> 0 | L14: =IF(OR(D14="",I14=""),"No reported total for O&M or depreciation",IF(AND(ABS(F14)<=$D$2,ABS(K14)<=$D$2),"Reconciles within tolerance","Outside tolerance")) -> Reconciles within tolerance | M14: =IF(OR(E14="",LEFT(L14,8)="Excluded"),"",ABS(E14)) -> 0
A15: 2004 | B15: ALLETE (Minnesota Power) | C15: 385.74835 | D15: 385.74835 | E15: =IF(D15="","",C15-D15) -> 0 | F15: =IF(OR(D15="",D15=0),"",E15/D15) -> 0 | G15: 37.036726 | H15: 0 | I15: 37.036726 | J15: =IF(I15="","",G15-I15) -> 0 | K15: =IF(OR(I15="",I15=0),"",J15/I15) -> 0 | L15: =IF(OR(D15="",I15=""),"No reported total for O&M or depreciation",IF(AND(ABS(F15)<=$D$2,ABS(K15)<=$D$2),"Reconciles within tolerance","Outside tolerance")) -> Reconciles within tolerance | M15: =IF(OR(E15="",LEFT(L15,8)="Excluded"),"",ABS(E15)) -> 0
A16: 2005 | B16: ALLETE (Minnesota Power) | C16: 396.2457 | D16: 396.2457 | E16: =IF(D16="","",C16-D16) -> 0 | F16: =IF(OR(D16="",D16=0),"",E16/D16) -> 0 | G16: 36.82965 | H16: 0 | I16: 36.82965 | J16: =IF(I16="","",G16-I16) -> 0 | K16: =IF(OR(I16="",I16=0),"",J16/I16) -> 0 | L16: =IF(OR(D16="",I16=""),"No reported total for O&M or depreciation",IF(AND(ABS(F16)<=$D$2,ABS(K16)<=$D$2),"Reconciles within tolerance","Outside tolerance")) -> Reconciles within tolerance | M16: =IF(OR(E16="",LEFT(L16,8)="Excluded"),"",ABS(E16)) -> 0
A17: 2006 | B17: ALLETE (Minnesota Power) | C17: 453.86135 | D17: 453.86135 | E17: =IF(D17="","",C17-D17) -> 0 | F17: =IF(OR(D17="",D17=0),"",E17/D17) -> 0 | G17: 41.452873 | H17: 0 | I17: 41.452873 | J17: =IF(I17="","",G17-I17) -> 0 | K17: =IF(OR(I17="",I17=0),"",J17/I17) -> 0 | L17: =IF(OR(D17="",I17=""),"No reported total for O&M or depreciation",IF(AND(ABS(F17)<=$D$2,ABS(K17)<=$D$2),"Reconciles within tolerance","Outside tolerance")) -> Reconciles within tolerance | M17: =IF(OR(E17="",LEFT(L17,8)="Excluded"),"",ABS(E17)) -> 0
... A47: 2005 | B47: Ameren Illinois | C47: 1706.4663 | D47: 1706.4663 | E47: =IF(D47="","",C47-D47) -> 0 | F47: =IF(OR(D47="",D47=0),"",E47/D47) -> 0 | G47: 134.60709 | H47: 0 | I47: 134.60709 | J47: =IF(I47="","",G47-I47) -> 0 | K47: =IF(OR(I47="",I47=0),"",J47/I47) -> 0 | L47: =IF(OR(D47="",I47=""),"No reported total for O&M or depreciation",IF(AND(ABS(F47)<=$D$2,ABS(K47)<=$D$2),"Reconciles within tolerance","Outside tolerance")) -> Reconciles within tolerance | M47: =IF(OR(E47="",LEFT(L47,8)="Excluded"),"",ABS(E47)) -> 0
A48: 2006 | B48: Ameren Illinois | C48: 2141.9692 | D48: 1787.4833 | E48: =IF(D48="","",C48-D48) -> 354.48588 | F48: =IF(OR(D48="",D48=0),"",E48/D48) -> 0.19831564 | G48: 140.29823 | H48: 0 | I48: 140.29823 | J48: =IF(I48="","",G48-I48) -> 0 | K48: =IF(OR(I48="",I48=0),"",J48/I48) -> 0 | L48: Excluded from analysis (Notes, data treatment 4) | M48: =IF(OR(E48="",LEFT(L48,8)="Excluded"),"",ABS(E48))
A49: 2007 | B49: Ameren Illinois | C49: 1891.2094 | D49: 1891.2094 | E49: =IF(D49="","",C49-D49) -> 0 | F49: =IF(OR(D49="",D49=0),"",E49/D49) -> 0 | G49: 144.72827 | H49: 0 | I49: 144.72827 | J49: =IF(I49="","",G49-I49) -> 0 | K49: =IF(OR(I49="",I49=0),"",J49/I49) -> 0 | L49: =IF(OR(D49="",I49=""),"No reported total for O&M or depreciation",IF(AND(ABS(F49)<=$D$2,ABS(K49)<=$D$2),"Reconciles within tolerance","Outside tolerance")) -> Reconciles within tolerance | M49: =IF(OR(E49="",LEFT(L49,8)="Excluded"),"",ABS(E49)) -> 0
A50: 2008 | B50: Ameren Illinois | C50: 1848.7509 | D50: 1848.7509 | E50: =IF(D50="","",C50-D50) -> 0 | F50: =IF(OR(D50="",D50=0),"",E50/D50) -> 0 | G50: 151.80568 | H50: 0 | I50: 151.80568 | J50: =IF(I50="","",G50-I50) -> 0 | K50: =IF(OR(I50="",I50=0),"",J50/I50) -> 0 | L50: =IF(OR(D50="",I50=""),"No reported total for O&M or depreciation",IF(AND(ABS(F50)<=$D$2,ABS(K50)<=$D$2),"Reconciles within tolerance","Outside tolerance")) -> Reconciles within tolerance | M50: =IF(OR(E50="",LEFT(L50,8)="Excluded"),"",ABS(E50)) -> 0
A51: 2009 | B51: Ameren Illinois | C51: 1539.0796 | D51: 1539.0796 | E51: =IF(D51="","",C51-D51) -> 0 | F51: =IF(OR(D51="",D51=0),"",E51/D51) -> 0 | G51: 168.58011 | H51: 0 | I51: 168.58011 | J51: =IF(I51="","",G51-I51) -> 0 | K51: =IF(OR(I51="",I51=0),"",J51/I51) -> 0 | L51: =IF(OR(D51="",I51=""),"No reported total for O&M or depreciation",IF(AND(ABS(F51)<=$D$2,ABS(K51)<=$D$2),"Reconciles within tolerance","Outside tolerance")) -> Reconciles within tolerance | M51: =IF(OR(E51="",LEFT(L51,8)="Excluded"),"",ABS(E51)) -> 0
A52: 2010 | B52: Ameren Illinois | C52: 1377.5525 | D52: 1377.5525 | E52: =IF(D52="","",C52-D52) -> 0 | F52: =IF(OR(D52="",D52=0),"",E52/D52) -> 0 | G52: 171.78685 | H52: 0 | I52: 171.78685 | J52: =IF(I52="","",G52-I52) -> 0 | K52: =IF(OR(I52="",I52=0),"",J52/I52) -> 0 | L52: =IF(OR(D52="",I52=""),"No reported total for O&M or depreciation",IF(AND(ABS(F52)<=$D$2,ABS(K52)<=$D$2),"Reconciles within tolerance","Outside tolerance")) -> Reconciles within tolerance | M52: =IF(OR(E52="",LEFT(L52,8)="Excluded"),"",ABS(E52)) -> 0
A53: 2011 | B53: Ameren Illinois | C53: 1306.5952 | D53: 1306.5952 | E53: =IF(D53="","",C53-D53) -> 0 | F53: =IF(OR(D53="",D53=0),"",E53/D53) -> 0 | G53: 176.06646 | H53: 0 | I53: 176.06646 | J53: =IF(I53="","",G53-I53) -> 0 | K53: =IF(OR(I53="",I53=0),"",J53/I53) -> 0 | L53: =IF(OR(D53="",I53=""),"No reported total for O&M or depreciation",IF(AND(ABS(F53)<=$D$2,ABS(K53)<=$D$2),"Reconciles within tolerance","Outside tolerance")) -> Reconciles within tolerance | M53: =IF(OR(E53="",LEFT(L53,8)="Excluded"),"",ABS(E53)) -> 0
A54: 2012 | B54: Ameren Illinois | C54: 1176.8776 | D54: 1176.8776 | E54: =IF(D54="","",C54-D54) -> 0 | F54: =IF(OR(D54="",D54=0),"",E54/D54) -> 0 | G54: 182.70093 | H54: 0 | I54: 182.70093 | J54: =IF(I54="","",G54-I54) -> 0 | K54: =IF(OR(I54="",I54=0),"",J54/I54) -> 0 | L54: =IF(OR(D54="",I54=""),"No reported total for O&M or depreciation",IF(AND(ABS(F54)<=$D$2,ABS(K54)<=$D$2),"Reconciles within tolerance","Outside tolerance")) -> Reconciles within tolerance | M54: =IF(OR(E54="",LEFT(L54,8)="Excluded"),"",ABS(E54)) -> 0
A55: 2013 | B55: Ameren Illinois | C55: 899.77123 | D55: 899.77123 | E55: =IF(D55="","",C55-D55) -> 0 | F55: =IF(OR(D55="",D55=0),"",E55/D55) -> 0 | G55: 205.70518 | H55: 0 | I55: 205.70518 | J55: =IF(I55="","",G55-I55) -> 0 | K55: =IF(OR(I55="",I55=0),"",J55/I55) -> 0 | L55: =IF(OR(D55="",I55=""),"No reported total for O&M or depreciation",IF(AND(ABS(F55)<=$D$2,ABS(K55)<=$D$2),"Reconciles within tolerance","Outside tolerance")) -> Reconciles within tolerance | M55: =IF(OR(E55="",LEFT(L55,8)="Excluded"),"",ABS(E55)) -> 0
A56: 2014 | B56: Ameren Illinois | C56: 927.35921 | D56: 927.35921 | E56: =IF(D56="","",C56-D56) -> 0 | F56: =IF(OR(D56="",D56=0),"",E56/D56) -> 0 | G56: 222.44603 | H56: 0 | I56: 222.44603 | J56: =IF(I56="","",G56-I56) -> 0 | K56: =IF(OR(I56="",I56=0),"",J56/I56) -> 0 | L56: =IF(OR(D56="",I56=""),"No reported total for O&M or depreciation",IF(AND(ABS(F56)<=$D$2,ABS(K56)<=$D$2),"Reconciles within tolerance","Outside tolerance")) -> Reconciles within tolerance | M56: =IF(OR(E56="",LEFT(L56,8)="Excluded"),"",ABS(E56)) -> 0
A57: 2015 | B57: Ameren Illinois | C57: 1006.9449 | D57: 1006.9449 | E57: =IF(D57="","",C57-D57) -> 0 | F57: =IF(OR(D57="",D57=0),"",E57/D57) -> 0 | G57: 242.26477 | H57: 0 | I57: 242.26477 | J57: =IF(I57="","",G57-I57) -> 0 | K57: =IF(OR(I57="",I57=0),"",J57/I57) -> 0 | L57: =IF(OR(D57="",I57=""),"No reported total for O&M or depreciation",IF(AND(ABS(F57)<=$D$2,ABS(K57)<=$D$2),"Reconciles within tolerance","Outside tolerance")) -> Reconciles within tolerance | M57: =IF(OR(E57="",LEFT(L57,8)="Excluded"),"",ABS(E57)) -> 0
A58: 2016 | B58: Ameren Illinois | C58: 992.65207 | D58: 992.65207 | E58: =IF(D58="","",C58-D58) -> 0 | F58: =IF(OR(D58="",D58=0),"",E58/D58) -> 0 | G58: 264.86377 | H58: 0 | I58: 264.86377 | J58: =IF(I58="","",G58-I58) -> 0 | K58: =IF(OR(I58="",I58=0),"",J58/I58) -> 0 | L58: =IF(OR(D58="",I58=""),"No reported total for O&M or depreciation",IF(AND(ABS(F58)<=$D$2,ABS(K58)<=$D$2),"Reconciles within tolerance","Outside tolerance")) -> Reconciles within tolerance | M58: =IF(OR(E58="",LEFT(L58,8)="Excluded"),"",ABS(E58)) -> 0
A59: 2017 | B59: Ameren Illinois | C59: 955.44566 | D59: 955.44566 | E59: =IF(D59="","",C59-D59) -> 0 | F59: =IF(OR(D59="",D59=0),"",E59/D59) -> 0 | G59: 282.70688 | H59: 0 | I59: 282.70688 | J59: =IF(I59="","",G59-I59) -> 0 | K59: =IF(OR(I59="",I59=0),"",J59/I59) -> 0 | L59: =IF(OR(D59="",I59=""),"No reported total for O&M or depreciation",IF(AND(ABS(F59)<=$D$2,ABS(K59)<=$D$2),"Reconciles within tolerance","Outside tolerance")) -> Reconciles within tolerance | M59: =IF(OR(E59="",LEFT(L59,8)="Excluded"),"",ABS(E59)) -> 0
A60: 2018 | B60: Ameren Illinois | C60: 936.35114 | D60: 936.35114 | E60: =IF(D60="","",C60-D60) -> 0 | F60: =IF(OR(D60="",D60=0),"",E60/D60) -> 0 | G60: 309.3227 | H60: 0 | I60: 309.3227 | J60: =IF(I60="","",G60-I60) -> 0 | K60: =IF(OR(I60="",I60=0),"",J60/I60) -> 0 | L60: =IF(OR(D60="",I60=""),"No reported total for O&M or depreciation",IF(AND(ABS(F60)<=$D$2,ABS(K60)<=$D$2),"Reconciles within tolerance","Outside tolerance")) -> Reconciles within tolerance | M60: =IF(OR(E60="",LEFT(L60,8)="Excluded"),"",ABS(E60)) -> 0
... A136: 2005 | B136: DTE Electric | C136: 2857.6516 | D136: 2857.6516 | E136: =IF(D136="","",C136-D136) -> 0 | F136: =IF(OR(D136="",D136=0),"",E136/D136) -> 0 | G136: 432.89329 | H136: 0 | I136: 432.89329 | J136: =IF(I136="","",G136-I136) -> 0 | K136: =IF(OR(I136="",I136=0),"",J136/I136) -> 0 | L136: =IF(OR(D136="",I136=""),"No reported total for O&M or depreciation",IF(AND(ABS(F136)<=$D$2,ABS(K136)<=$D$2),"Reconciles within tolerance","Outside tolerance")) -> Reconciles within tolerance | M136: =IF(OR(E136="",LEFT(L136,8)="Excluded"),"",ABS(E136)) -> 0
A137: 2006 | B137: DTE Electric | C137: 2850.9912 | D137: 2850.9912 | E137: =IF(D137="","",C137-D137) -> 0 | F137: =IF(OR(D137="",D137=0),"",E137/D137) -> 0 | G137: 866.52423 | H137: 0 | J137: =IF(I137="","",G137-I137) | K137: =IF(OR(I137="",I137=0),"",J137/I137) | L137: =IF(OR(D137="",I137=""),"No reported total for O&M or depreciation",IF(AND(ABS(F137)<=$D$2,ABS(K137)<=$D$2),"Reconciles within tolerance","Outside tolerance")) -> No reported total for O&M or depreciation | M137: =IF(OR(E137="",LEFT(L137,8)="Excluded"),"",ABS(E137)) -> 0
