Workbook

Sheet Read Me
A1: Twin Cities home energy model: results
A3: Purpose | B3: Annual and monthly electricity and natural gas cost for a typical Twin Cities metro single-family home under four heating setups, with and without a heat pump water heater, on Xcel Energy and CenterPoint Energy residential rates.
A4: Usage source | B4: NREL End-Use Load Profiles for the U.S. Building Stock, ResStock 2025 Release 1, actual meteorological year 2018 (Open Energy Data Initiative). Scope: 2,443 simulated single-family detached homes with gas furnaces in Anoka, Carver, Dakota, Hennepin, Ramsey, Scott and Washington counties. Gas totals are as NREL published them; the metro mean (1,503 therms/yr) is above commonly cited CenterPoint residential averages, a comparison not checked against a published source.
A5: Profiles | B5: Average = mean of 200 homes sampled in proportion to ResStock weights (seed 2018); smooths hourly peaks. Median home = ResStock building 164367 (2,179 sq ft), closest to median floor area, electricity and gas use.
A6: Setups | B6: Gas furnace (baseline); cold-climate heat pump with electric resistance backup (ResStock upgrade 4); dual-fuel heat pump with 95% AFUE gas backup, 35F switchover (upgrade 5); electric baseboard (baseline heat delivered at 100% efficiency); each also with a heat pump water heater (upgrade 9). Gas cooking, drying and other gas uses remain in every setup.
A7: Rates: status | B7: Every price on the Rates sheet is unverified. The build environment could not reach xcelenergy.com, centerpointenergy.com, mn.gov or eDockets; values come from web search summaries of the sources named in each row, with effective dates not confirmed. Xcel Resource Adjustment riders and CenterPoint per-therm riders are set to zero. The Xcel fuel cost charge (January 2026) and CenterPoint cost of gas (April 2026) are applied to all months. Taxes and franchise fees are excluded. Dual-fuel control events are not modeled.
A8: Rates: to update | B8: Replace the yellow cells on the Rates sheet with values from the Xcel Energy Minnesota Electric Rate Book (MPUC No. 2, Section 5) and the CenterPoint Energy Minnesota Gas Rate Book (Residential Sales Service). All bills recalculate.
A9: Legend | B9: Blue text = hardcoded input or model output. Yellow fill = rate input to replace with the tariff value. Black text = formula.
A10: Sheets | B10: Summary: annual cost by setup and plan, lowest-cost plan, electric/gas split, chart. Rates: price inputs. Plan Eligibility: which plans apply to which setups. Monthly Bills: monthly kWh, time-of-use period kWh, therms and bill formulas. Annual Usage: end-use totals, highest hourly use, sample check.
A11: Hourly data | B11: The 8,760-hour profiles are in outputs/profiles/ as CSV files (one per profile and setup).

Sheet Summary
A1: Annual energy cost by home setup and rate plan
A2: Twin Cities metro single-family home, NREL ResStock 2025.1 with 2018 weather. Costs use unverified rates on the Rates sheet; n/a = plan not modeled for that setup (Plan Eligibility sheet).
A4: Average of 200 sampled homes
A5: Setup | B5: Electricity (kWh/yr) | C5: Gas (therms/yr) | D5: Standard ($/yr) | E5: Time-of-use ($/yr) | F5: Space heating ($/yr) | G5: Dual fuel ($/yr) | H5: Lowest cost ($/yr) | I5: Lowest-cost plan
A6: Gas furnace | B6: =SUMIFS('Monthly Bills'!$E$5:$E$196,'Monthly Bills'!$A$5:$A$196,"average",'Monthly Bills'!$B$5:$B$196,"gas_furnace") -> 10283.78 | C6: =SUMIFS('Monthly Bills'!$L$5:$L$196,'Monthly Bills'!$A$5:$A$196,"average",'Monthly Bills'!$B$5:$B$196,"gas_furnace") -> 1458.593 | D6: =IF('Plan Eligibility'!$B$5="Yes",SUMIFS('Monthly Bills'!$M$5:$M$196,'Monthly Bills'!$A$5:$A$196,"average",'Monthly Bills'!$B$5:$B$196,"gas_furnace")+SUMIFS('Monthly Bills'!$Q$5:$Q$196,'Monthly Bills'!$A$5:$A$196,"average",'Monthly Bills'!$B$5:$B$196,"gas_furnace"),"n/a") -> 3040.6662 | E6: =IF('Plan Eligibility'!$C$5="Yes",SUMIFS('Monthly Bills'!$N$5:$N$196,'Monthly Bills'!$A$5:$A$196,"average",'Monthly Bills'!$B$5:$B$196,"gas_furnace")+SUMIFS('Monthly Bills'!$Q$5:$Q$196,'Monthly Bills'!$A$5:$A$196,"average",'Monthly Bills'!$B$5:$B$196,"gas_furnace"),"n/a") -> 2959.134 | F6: =IF('Plan Eligibility'!$D$5="Yes",SUMIFS('Monthly Bills'!$O$5:$O$196,'Monthly Bills'!$A$5:$A$196,"average",'Monthly Bills'!$B$5:$B$196,"gas_furnace")+SUMIFS('Monthly Bills'!$Q$5:$Q$196,'Monthly Bills'!$A$5:$A$196,"average",'Monthly Bills'!$B$5:$B$196,"gas_furnace"),"n/a") -> n/a | G6: =IF('Plan Eligibility'!$E$5="Yes",SUMIFS('Monthly Bills'!$P$5:$P$196,'Monthly Bills'!$A$5:$A$196,"average",'Monthly Bills'!$B$5:$B$196,"gas_furnace")+SUMIFS('Monthly Bills'!$Q$5:$Q$196,'Monthly Bills'!$A$5:$A$196,"average",'Monthly Bills'!$B$5:$B$196,"gas_furnace"),"n/a") -> n/a | H6: =MIN(D6:G6) -> 2959.134 | I6: =SUBSTITUTE(INDEX($D$5:$G$5,MATCH(H6,D6:G6,0))," ($/yr)","") -> Time-of-use
A7: Heat pump + electric backup | B7: =SUMIFS('Monthly Bills'!$E$5:$E$196,'Monthly Bills'!$A$5:$A$196,"average",'Monthly Bills'!$B$5:$B$196,"ashp_resistance_backup") -> 23438.721 | C7: =SUMIFS('Monthly Bills'!$L$5:$L$196,'Monthly Bills'!$A$5:$A$196,"average",'Monthly Bills'!$B$5:$B$196,"ashp_resistance_backup") -> 177.99 | D7: =IF('Plan Eligibility'!$B$6="Yes",SUMIFS('Monthly Bills'!$M$5:$M$196,'Monthly Bills'!$A$5:$A$196,"average",'Monthly Bills'!$B$5:$B$196,"ashp_resistance_backup")+SUMIFS('Monthly Bills'!$Q$5:$Q$196,'Monthly Bills'!$A$5:$A$196,"average",'Monthly Bills'!$B$5:$B$196,"ashp_resistance_backup"),"n/a") -> 3609.551 | E7: =IF('Plan Eligibility'!$C$6="Yes",SUMIFS('Monthly Bills'!$N$5:$N$196,'Monthly Bills'!$A$5:$A$196,"average",'Monthly Bills'!$B$5:$B$196,"ashp_resistance_backup")+SUMIFS('Monthly Bills'!$Q$5:$Q$196,'Monthly Bills'!$A$5:$A$196,"average",'Monthly Bills'!$B$5:$B$196,"ashp_resistance_backup"),"n/a") -> 3342.0838 | F7: =IF('Plan Eligibility'!$D$6="Yes",SUMIFS('Monthly Bills'!$O$5:$O$196,'Monthly Bills'!$A$5:$A$196,"average",'Monthly Bills'!$B$5:$B$196,"ashp_resistance_backup")+SUMIFS('Monthly Bills'!$Q$5:$Q$196,'Monthly Bills'!$A$5:$A$196,"average",'Monthly Bills'!$B$5:$B$196,"ashp_resistance_backup"),"n/a") -> 2447.6294 | G7: =IF('Plan Eligibility'!$E$6="Yes",SUMIFS('Monthly Bills'!$P$5:$P$196,'Monthly Bills'!$A$5:$A$196,"average",'Monthly Bills'!$B$5:$B$196,"ashp_resistance_backup")+SUMIFS('Monthly Bills'!$Q$5:$Q$196,'Monthly Bills'!$A$5:$A$196,"average",'Monthly Bills'!$B$5:$B$196,"ashp_resistance_backup"),"n/a") -> n/a | H7: =MIN(D7:G7) -> 2447.6294 | I7: =SUBSTITUTE(INDEX($D$5:$G$5,MATCH(H7,D7:G7,0))," ($/yr)","") -> Space heating
A8: Heat pump + gas backup (dual fuel) | B8: =SUMIFS('Monthly Bills'!$E$5:$E$196,'Monthly Bills'!$A$5:$A$196,"average",'Monthly Bills'!$B$5:$B$196,"ashp_gas_backup") -> 12037.909 | C8: =SUMIFS('Monthly Bills'!$L$5:$L$196,'Monthly Bills'!$A$5:$A$196,"average",'Monthly Bills'!$B$5:$B$196,"ashp_gas_backup") -> 1245.813 | D8: =IF('Plan Eligibility'!$B$7="Yes",SUMIFS('Monthly Bills'!$M$5:$M$196,'Monthly Bills'!$A$5:$A$196,"average",'Monthly Bills'!$B$5:$B$196,"ashp_gas_backup")+SUMIFS('Monthly Bills'!$Q$5:$Q$196,'Monthly Bills'!$A$5:$A$196,"average",'Monthly Bills'!$B$5:$B$196,"ashp_gas_backup"),"n/a") -> 3085.8661 | E8: =IF('Plan Eligibility'!$C$7="Yes",SUMIFS('Monthly Bills'!$N$5:$N$196,'Monthly Bills'!$A$5:$A$196,"average",'Monthly Bills'!$B$5:$B$196,"ashp_gas_backup")+SUMIFS('Monthly Bills'!$Q$5:$Q$196,'Monthly Bills'!$A$5:$A$196,"average",'Monthly Bills'!$B$5:$B$196,"ashp_gas_backup"),"n/a") -> 2986.5701 | F8: =IF('Plan Eligibility'!$D$7="Yes",SUMIFS('Monthly Bills'!$O$5:$O$196,'Monthly Bills'!$A$5:$A$196,"average",'Monthly Bills'!$B$5:$B$196,"ashp_gas_backup")+SUMIFS('Monthly Bills'!$Q$5:$Q$196,'Monthly Bills'!$A$5:$A$196,"average",'Monthly Bills'!$B$5:$B$196,"ashp_gas_backup"),"n/a") -> n/a | G8: =IF('Plan Eligibility'!$E$7="Yes",SUMIFS('Monthly Bills'!$P$5:$P$196,'Monthly Bills'!$A$5:$A$196,"average",'Monthly Bills'!$B$5:$B$196,"ashp_gas_backup")+SUMIFS('Monthly Bills'!$Q$5:$Q$196,'Monthly Bills'!$A$5:$A$196,"average",'Monthly Bills'!$B$5:$B$196,"ashp_gas_backup"),"n/a") -> 2950.0586 | H8: =MIN(D8:G8) -> 2950.0586 | I8: =SUBSTITUTE(INDEX($D$5:$G$5,MATCH(H8,D8:G8,0))," ($/yr)","") -> Dual fuel
A9: Electric baseboard | B9: =SUMIFS('Monthly Bills'!$E$5:$E$196,'Monthly Bills'!$A$5:$A$196,"average",'Monthly Bills'!$B$5:$B$196,"baseboard") -> 41838.246 | C9: =SUMIFS('Monthly Bills'!$L$5:$L$196,'Monthly Bills'!$A$5:$A$196,"average",'Monthly Bills'!$B$5:$B$196,"baseboard") -> 177.971 | D9: =IF('Plan Eligibility'!$B$8="Yes",SUMIFS('Monthly Bills'!$M$5:$M$196,'Monthly Bills'!$A$5:$A$196,"average",'Monthly Bills'!$B$5:$B$196,"baseboard")+SUMIFS('Monthly Bills'!$Q$5:$Q$196,'Monthly Bills'!$A$5:$A$196,"average",'Monthly Bills'!$B$5:$B$196,"baseboard"),"n/a") -> 6080.6338 | E9: =IF('Plan Eligibility'!$C$8="Yes",SUMIFS('Monthly Bills'!$N$5:$N$196,'Monthly Bills'!$A$5:$A$196,"average",'Monthly Bills'!$B$5:$B$196,"baseboard")+SUMIFS('Monthly Bills'!$Q$5:$Q$196,'Monthly Bills'!$A$5:$A$196,"average",'Monthly Bills'!$B$5:$B$196,"baseboard"),"n/a") -> 5576.4691 | F9: =IF('Plan Eligibility'!$D$8="Yes",SUMIFS('Monthly Bills'!$O$5:$O$196,'Monthly Bills'!$A$5:$A$196,"average",'Monthly Bills'!$B$5:$B$196,"baseboard")+SUMIFS('Monthly Bills'!$Q$5:$Q$196,'Monthly Bills'!$A$5:$A$196,"average",'Monthly Bills'!$B$5:$B$196,"baseboard"),"n/a") -> 3858.0589 | G9: =IF('Plan Eligibility'!$E$8="Yes",SUMIFS('Monthly Bills'!$P$5:$P$196,'Monthly Bills'!$A$5:$A$196,"average",'Monthly Bills'!$B$5:$B$196,"baseboard")+SUMIFS('Monthly Bills'!$Q$5:$Q$196,'Monthly Bills'!$A$5:$A$196,"average",'Monthly Bills'!$B$5:$B$196,"baseboard"),"n/a") -> n/a | H9: =MIN(D9:G9) -> 3858.0589 | I9: =SUBSTITUTE(INDEX($D$5:$G$5,MATCH(H9,D9:G9,0))," ($/yr)","") -> Space heating
A10: Gas furnace + heat pump water heater | B10: =SUMIFS('Monthly Bills'!$E$5:$E$196,'Monthly Bills'!$A$5:$A$196,"average",'Monthly Bills'!$B$5:$B$196,"gas_furnace_hpwh") -> 10591.412 | C10: =SUMIFS('Monthly Bills'!$L$5:$L$196,'Monthly Bills'!$A$5:$A$196,"average",'Monthly Bills'!$B$5:$B$196,"gas_furnace_hpwh") -> 1309.012 | D10: =IF('Plan Eligibility'!$B$9="Yes",SUMIFS('Monthly Bills'!$M$5:$M$196,'Monthly Bills'!$A$5:$A$196,"average",'Monthly Bills'!$B$5:$B$196,"gas_furnace_hpwh")+SUMIFS('Monthly Bills'!$Q$5:$Q$196,'Monthly Bills'!$A$5:$A$196,"average",'Monthly Bills'!$B$5:$B$196,"gas_furnace_hpwh"),"n/a") -> 2943.4905 | E10: =IF('Plan Eligibility'!$C$9="Yes",SUMIFS('Monthly Bills'!$N$5:$N$196,'Monthly Bills'!$A$5:$A$196,"average",'Monthly Bills'!$B$5:$B$196,"gas_furnace_hpwh")+SUMIFS('Monthly Bills'!$Q$5:$Q$196,'Monthly Bills'!$A$5:$A$196,"average",'Monthly Bills'!$B$5:$B$196,"gas_furnace_hpwh"),"n/a") -> 2858.9377 | F10: =IF('Plan Eligibility'!$D$9="Yes",SUMIFS('Monthly Bills'!$O$5:$O$196,'Monthly Bills'!$A$5:$A$196,"average",'Monthly Bills'!$B$5:$B$196,"gas_furnace_hpwh")+SUMIFS('Monthly Bills'!$Q$5:$Q$196,'Monthly Bills'!$A$5:$A$196,"average",'Monthly Bills'!$B$5:$B$196,"gas_furnace_hpwh"),"n/a") -> n/a | G10: =IF('Plan Eligibility'!$E$9="Yes",SUMIFS('Monthly Bills'!$P$5:$P$196,'Monthly Bills'!$A$5:$A$196,"average",'Monthly Bills'!$B$5:$B$196,"gas_furnace_hpwh")+SUMIFS('Monthly Bills'!$Q$5:$Q$196,'Monthly Bills'!$A$5:$A$196,"average",'Monthly Bills'!$B$5:$B$196,"gas_furnace_hpwh"),"n/a") -> n/a | H10: =MIN(D10:G10) -> 2858.9377 | I10: =SUBSTITUTE(INDEX($D$5:$G$5,MATCH(H10,D10:G10,0))," ($/yr)","") -> Time-of-use
A11: Heat pump + electric backup + heat pump water heater | B11: =SUMIFS('Monthly Bills'!$E$5:$E$196,'Monthly Bills'!$A$5:$A$196,"average",'Monthly Bills'!$B$5:$B$196,"ashp_resistance_backup_hpwh") -> 23746.749 | C11: =SUMIFS('Monthly Bills'!$L$5:$L$196,'Monthly Bills'!$A$5:$A$196,"average",'Monthly Bills'!$B$5:$B$196,"ashp_resistance_backup_hpwh") -> 28.386 | D11: =IF('Plan Eligibility'!$B$10="Yes",SUMIFS('Monthly Bills'!$M$5:$M$196,'Monthly Bills'!$A$5:$A$196,"average",'Monthly Bills'!$B$5:$B$196,"ashp_resistance_backup_hpwh")+SUMIFS('Monthly Bills'!$Q$5:$Q$196,'Monthly Bills'!$A$5:$A$196,"average",'Monthly Bills'!$B$5:$B$196,"ashp_resistance_backup_hpwh"),"n/a") -> 3511.7664 | E11: =IF('Plan Eligibility'!$C$10="Yes",SUMIFS('Monthly Bills'!$N$5:$N$196,'Monthly Bills'!$A$5:$A$196,"average",'Monthly Bills'!$B$5:$B$196,"ashp_resistance_backup_hpwh")+SUMIFS('Monthly Bills'!$Q$5:$Q$196,'Monthly Bills'!$A$5:$A$196,"average",'Monthly Bills'!$B$5:$B$196,"ashp_resistance_backup_hpwh"),"n/a") -> 3241.9145 | F11: =IF('Plan Eligibility'!$D$10="Yes",SUMIFS('Monthly Bills'!$O$5:$O$196,'Monthly Bills'!$A$5:$A$196,"average",'Monthly Bills'!$B$5:$B$196,"ashp_resistance_backup_hpwh")+SUMIFS('Monthly Bills'!$Q$5:$Q$196,'Monthly Bills'!$A$5:$A$196,"average",'Monthly Bills'!$B$5:$B$196,"ashp_resistance_backup_hpwh"),"n/a") -> 2334.4247 | G11: =IF('Plan Eligibility'!$E$10="Yes",SUMIFS('Monthly Bills'!$P$5:$P$196,'Monthly Bills'!$A$5:$A$196,"average",'Monthly Bills'!$B$5:$B$196,"ashp_resistance_backup_hpwh")+SUMIFS('Monthly Bills'!$Q$5:$Q$196,'Monthly Bills'!$A$5:$A$196,"average",'Monthly Bills'!$B$5:$B$196,"ashp_resistance_backup_hpwh"),"n/a") -> n/a | H11: =MIN(D11:G11) -> 2334.4247 | I11: =SUBSTITUTE(INDEX($D$5:$G$5,MATCH(H11,D11:G11,0))," ($/yr)","") -> Space heating
A12: Heat pump + gas backup (dual fuel) + heat pump water heater | B12: =SUMIFS('Monthly Bills'!$E$5:$E$196,'Monthly Bills'!$A$5:$A$196,"average",'Monthly Bills'!$B$5:$B$196,"ashp_gas_backup_hpwh") -> 12346.251 | C12: =SUMIFS('Monthly Bills'!$L$5:$L$196,'Monthly Bills'!$A$5:$A$196,"average",'Monthly Bills'!$B$5:$B$196,"ashp_gas_backup_hpwh") -> 1096.359 | D12: =IF('Plan Eligibility'!$B$11="Yes",SUMIFS('Monthly Bills'!$M$5:$M$196,'Monthly Bills'!$A$5:$A$196,"average",'Monthly Bills'!$B$5:$B$196,"ashp_gas_backup_hpwh")+SUMIFS('Monthly Bills'!$Q$5:$Q$196,'Monthly Bills'!$A$5:$A$196,"average",'Monthly Bills'!$B$5:$B$196,"ashp_gas_backup_hpwh"),"n/a") -> 2988.6008 | E12: =IF('Plan Eligibility'!$C$11="Yes",SUMIFS('Monthly Bills'!$N$5:$N$196,'Monthly Bills'!$A$5:$A$196,"average",'Monthly Bills'!$B$5:$B$196,"ashp_gas_backup_hpwh")+SUMIFS('Monthly Bills'!$Q$5:$Q$196,'Monthly Bills'!$A$5:$A$196,"average",'Monthly Bills'!$B$5:$B$196,"ashp_gas_backup_hpwh"),"n/a") -> 2886.5787 | F12: =IF('Plan Eligibility'!$D$11="Yes",SUMIFS('Monthly Bills'!$O$5:$O$196,'Monthly Bills'!$A$5:$A$196,"average",'Monthly Bills'!$B$5:$B$196,"ashp_gas_backup_hpwh")+SUMIFS('Monthly Bills'!$Q$5:$Q$196,'Monthly Bills'!$A$5:$A$196,"average",'Monthly Bills'!$B$5:$B$196,"ashp_gas_backup_hpwh"),"n/a") -> n/a | G12: =IF('Plan Eligibility'!$E$11="Yes",SUMIFS('Monthly Bills'!$P$5:$P$196,'Monthly Bills'!$A$5:$A$196,"average",'Monthly Bills'!$B$5:$B$196,"ashp_gas_backup_hpwh")+SUMIFS('Monthly Bills'!$Q$5:$Q$196,'Monthly Bills'!$A$5:$A$196,"average",'Monthly Bills'!$B$5:$B$196,"ashp_gas_backup_hpwh"),"n/a") -> 2853.0976 | H12: =MIN(D12:G12) -> 2853.0976 | I12: =SUBSTITUTE(INDEX($D$5:$G$5,MATCH(H12,D12:G12,0))," ($/yr)","") -> Dual fuel
A13: Electric baseboard + heat pump water heater | B13: =SUMIFS('Monthly Bills'!$E$5:$E$196,'Monthly Bills'!$A$5:$A$196,"average",'Monthly Bills'!$B$5:$B$196,"baseboard_hpwh") -> 42145.878 | C13: =SUMIFS('Monthly Bills'!$L$5:$L$196,'Monthly Bills'!$A$5:$A$196,"average",'Monthly Bills'!$B$5:$B$196,"baseboard_hpwh") -> 28.386 | D13: =IF('Plan Eligibility'!$B$12="Yes",SUMIFS('Monthly Bills'!$M$5:$M$196,'Monthly Bills'!$A$5:$A$196,"average",'Monthly Bills'!$B$5:$B$196,"baseboard_hpwh")+SUMIFS('Monthly Bills'!$Q$5:$Q$196,'Monthly Bills'!$A$5:$A$196,"average",'Monthly Bills'!$B$5:$B$196,"baseboard_hpwh"),"n/a") -> 5982.8135 | E13: =IF('Plan Eligibility'!$C$12="Yes",SUMIFS('Monthly Bills'!$N$5:$N$196,'Monthly Bills'!$A$5:$A$196,"average",'Monthly Bills'!$B$5:$B$196,"baseboard_hpwh")+SUMIFS('Monthly Bills'!$Q$5:$Q$196,'Monthly Bills'!$A$5:$A$196,"average",'Monthly Bills'!$B$5:$B$196,"baseboard_hpwh"),"n/a") -> 5476.2694 | F13: =IF('Plan Eligibility'!$D$12="Yes",SUMIFS('Monthly Bills'!$O$5:$O$196,'Monthly Bills'!$A$5:$A$196,"average",'Monthly Bills'!$B$5:$B$196,"baseboard_hpwh")+SUMIFS('Monthly Bills'!$Q$5:$Q$196,'Monthly Bills'!$A$5:$A$196,"average",'Monthly Bills'!$B$5:$B$196,"baseboard_hpwh"),"n/a") -> 3744.8403 | G13: =IF('Plan Eligibility'!$E$12="Yes",SUMIFS('Monthly Bills'!$P$5:$P$196,'Monthly Bills'!$A$5:$A$196,"average",'Monthly Bills'!$B$5:$B$196,"baseboard_hpwh")+SUMIFS('Monthly Bills'!$Q$5:$Q$196,'Monthly Bills'!$A$5:$A$196,"average",'Monthly Bills'!$B$5:$B$196,"baseboard_hpwh"),"n/a") -> n/a | H13: =MIN(D13:G13) -> 3744.8403 | I13: =SUBSTITUTE(INDEX($D$5:$G$5,MATCH(H13,D13:G13,0))," ($/yr)","") -> Space heating
A16: Median home (ResStock building 164367)
A17: Setup | B17: Electricity (kWh/yr) | C17: Gas (therms/yr) | D17: Standard ($/yr) | E17: Time-of-use ($/yr) | F17: Space heating ($/yr) | G17: Dual fuel ($/yr) | H17: Lowest cost ($/yr) | I17: Lowest-cost plan
A18: Gas furnace | B18: =SUMIFS('Monthly Bills'!$E$5:$E$196,'Monthly Bills'!$A$5:$A$196,"median_home",'Monthly Bills'!$B$5:$B$196,"gas_furnace") -> 9683.202 | C18: =SUMIFS('Monthly Bills'!$L$5:$L$196,'Monthly Bills'!$A$5:$A$196,"median_home",'Monthly Bills'!$B$5:$B$196,"gas_furnace") -> 1391.311 | D18: =IF('Plan Eligibility'!$B$5="Yes",SUMIFS('Monthly Bills'!$M$5:$M$196,'Monthly Bills'!$A$5:$A$196,"median_home",'Monthly Bills'!$B$5:$B$196,"gas_furnace")+SUMIFS('Monthly Bills'!$Q$5:$Q$196,'Monthly Bills'!$A$5:$A$196,"median_home",'Monthly Bills'!$B$5:$B$196,"gas_furnace"),"n/a") -> 2898.6689 | E18: =IF('Plan Eligibility'!$C$5="Yes",SUMIFS('Monthly Bills'!$N$5:$N$196,'Monthly Bills'!$A$5:$A$196,"median_home",'Monthly Bills'!$B$5:$B$196,"gas_furnace")+SUMIFS('Monthly Bills'!$Q$5:$Q$196,'Monthly Bills'!$A$5:$A$196,"median_home",'Monthly Bills'!$B$5:$B$196,"gas_furnace"),"n/a") -> 2807.1906 | F18: =IF('Plan Eligibility'!$D$5="Yes",SUMIFS('Monthly Bills'!$O$5:$O$196,'Monthly Bills'!$A$5:$A$196,"median_home",'Monthly Bills'!$B$5:$B$196,"gas_furnace")+SUMIFS('Monthly Bills'!$Q$5:$Q$196,'Monthly Bills'!$A$5:$A$196,"median_home",'Monthly Bills'!$B$5:$B$196,"gas_furnace"),"n/a") -> n/a | G18: =IF('Plan Eligibility'!$E$5="Yes",SUMIFS('Monthly Bills'!$P$5:$P$196,'Monthly Bills'!$A$5:$A$196,"median_home",'Monthly Bills'!$B$5:$B$196,"gas_furnace")+SUMIFS('Monthly Bills'!$Q$5:$Q$196,'Monthly Bills'!$A$5:$A$196,"median_home",'Monthly Bills'!$B$5:$B$196,"gas_furnace"),"n/a") -> n/a | H18: =MIN(D18:G18) -> 2807.1906 | I18: =SUBSTITUTE(INDEX($D$17:$G$17,MATCH(H18,D18:G18,0))," ($/yr)","") -> Time-of-use
A19: Heat pump + electric backup | B19: =SUMIFS('Monthly Bills'!$E$5:$E$196,'Monthly Bills'!$A$5:$A$196,"median_home",'Monthly Bills'!$B$5:$B$196,"ashp_resistance_backup") -> 19347.406 | C19: =SUMIFS('Monthly Bills'!$L$5:$L$196,'Monthly Bills'!$A$5:$A$196,"median_home",'Monthly Bills'!$B$5:$B$196,"ashp_resistance_backup") -> 279.725 | D19: =IF('Plan Eligibility'!$B$6="Yes",SUMIFS('Monthly Bills'!$M$5:$M$196,'Monthly Bills'!$A$5:$A$196,"median_home",'Monthly Bills'!$B$5:$B$196,"ashp_resistance_backup")+SUMIFS('Monthly Bills'!$Q$5:$Q$196,'Monthly Bills'!$A$5:$A$196,"median_home",'Monthly Bills'!$B$5:$B$196,"ashp_resistance_backup"),"n/a") -> 3157.3895 | E19: =IF('Plan Eligibility'!$C$6="Yes",SUMIFS('Monthly Bills'!$N$5:$N$196,'Monthly Bills'!$A$5:$A$196,"median_home",'Monthly Bills'!$B$5:$B$196,"ashp_resistance_backup")+SUMIFS('Monthly Bills'!$Q$5:$Q$196,'Monthly Bills'!$A$5:$A$196,"median_home",'Monthly Bills'!$B$5:$B$196,"ashp_resistance_backup"),"n/a") -> 2928.1312 | F19: =IF('Plan Eligibility'!$D$6="Yes",SUMIFS('Monthly Bills'!$O$5:$O$196,'Monthly Bills'!$A$5:$A$196,"median_home",'Monthly Bills'!$B$5:$B$196,"ashp_resistance_backup")+SUMIFS('Monthly Bills'!$Q$5:$Q$196,'Monthly Bills'!$A$5:$A$196,"median_home",'Monthly Bills'!$B$5:$B$196,"ashp_resistance_backup"),"n/a") -> 2240.2793 | G19: =IF('Plan Eligibility'!$E$6="Yes",SUMIFS('Monthly Bills'!$P$5:$P$196,'Monthly Bills'!$A$5:$A$196,"median_home",'Monthly Bills'!$B$5:$B$196,"ashp_resistance_backup")+SUMIFS('Monthly Bills'!$Q$5:$Q$196,'Monthly Bills'!$A$5:$A$196,"median_home",'Monthly Bills'!$B$5:$B$196,"ashp_resistance_backup"),"n/a") -> n/a | H19: =MIN(D19:G19) -> 2240.2793 | I19: =SUBSTITUTE(INDEX($D$17:$G$17,MATCH(H19,D19:G19,0))," ($/yr)","") -> Space heating
A20: Heat pump + gas backup (dual fuel) | B20: =SUMIFS('Monthly Bills'!$E$5:$E$196,'Monthly Bills'!$A$5:$A$196,"median_home",'Monthly Bills'!$B$5:$B$196,"ashp_gas_backup") -> 10857.627 | C20: =SUMIFS('Monthly Bills'!$L$5:$L$196,'Monthly Bills'!$A$5:$A$196,"median_home",'Monthly Bills'!$B$5:$B$196,"ashp_gas_backup") -> 1095.78 | D20: =IF('Plan Eligibility'!$B$7="Yes",SUMIFS('Monthly Bills'!$M$5:$M$196,'Monthly Bills'!$A$5:$A$196,"median_home",'Monthly Bills'!$B$5:$B$196,"ashp_gas_backup")+SUMIFS('Monthly Bills'!$Q$5:$Q$196,'Monthly Bills'!$A$5:$A$196,"median_home",'Monthly Bills'!$B$5:$B$196,"ashp_gas_backup"),"n/a") -> 2787.5673 | E20: =IF('Plan Eligibility'!$C$7="Yes",SUMIFS('Monthly Bills'!$N$5:$N$196,'Monthly Bills'!$A$5:$A$196,"median_home",'Monthly Bills'!$B$5:$B$196,"ashp_gas_backup")+SUMIFS('Monthly Bills'!$Q$5:$Q$196,'Monthly Bills'!$A$5:$A$196,"median_home",'Monthly Bills'!$B$5:$B$196,"ashp_gas_backup"),"n/a") -> 2686.3158 | F20: =IF('Plan Eligibility'!$D$7="Yes",SUMIFS('Monthly Bills'!$O$5:$O$196,'Monthly Bills'!$A$5:$A$196,"median_home",'Monthly Bills'!$B$5:$B$196,"ashp_gas_backup")+SUMIFS('Monthly Bills'!$Q$5:$Q$196,'Monthly Bills'!$A$5:$A$196,"median_home",'Monthly Bills'!$B$5:$B$196,"ashp_gas_backup"),"n/a") -> n/a | G20: =IF('Plan Eligibility'!$E$7="Yes",SUMIFS('Monthly Bills'!$P$5:$P$196,'Monthly Bills'!$A$5:$A$196,"median_home",'Monthly Bills'!$B$5:$B$196,"ashp_gas_backup")+SUMIFS('Monthly Bills'!$Q$5:$Q$196,'Monthly Bills'!$A$5:$A$196,"median_home",'Monthly Bills'!$B$5:$B$196,"ashp_gas_backup"),"n/a") -> 2687.6067 | H20: =MIN(D20:G20) -> 2686.3158 | I20: =SUBSTITUTE(INDEX($D$17:$G$17,MATCH(H20,D20:G20,0))," ($/yr)","") -> Time-of-use
A21: Electric baseboard | B21: =SUMIFS('Monthly Bills'!$E$5:$E$196,'Monthly Bills'!$A$5:$A$196,"median_home",'Monthly Bills'!$B$5:$B$196,"baseboard") -> 35744.788 | C21: =SUMIFS('Monthly Bills'!$L$5:$L$196,'Monthly Bills'!$A$5:$A$196,"median_home",'Monthly Bills'!$B$5:$B$196,"baseboard") -> 279.631 | D21: =IF('Plan Eligibility'!$B$8="Yes",SUMIFS('Monthly Bills'!$M$5:$M$196,'Monthly Bills'!$A$5:$A$196,"median_home",'Monthly Bills'!$B$5:$B$196,"baseboard")+SUMIFS('Monthly Bills'!$Q$5:$Q$196,'Monthly Bills'!$A$5:$A$196,"median_home",'Monthly Bills'!$B$5:$B$196,"baseboard"),"n/a") -> 5358.8817 | E21: =IF('Plan Eligibility'!$C$8="Yes",SUMIFS('Monthly Bills'!$N$5:$N$196,'Monthly Bills'!$A$5:$A$196,"median_home",'Monthly Bills'!$B$5:$B$196,"baseboard")+SUMIFS('Monthly Bills'!$Q$5:$Q$196,'Monthly Bills'!$A$5:$A$196,"median_home",'Monthly Bills'!$B$5:$B$196,"baseboard"),"n/a") -> 4908.1875 | F21: =IF('Plan Eligibility'!$D$8="Yes",SUMIFS('Monthly Bills'!$O$5:$O$196,'Monthly Bills'!$A$5:$A$196,"median_home",'Monthly Bills'!$B$5:$B$196,"baseboard")+SUMIFS('Monthly Bills'!$Q$5:$Q$196,'Monthly Bills'!$A$5:$A$196,"median_home",'Monthly Bills'!$B$5:$B$196,"baseboard"),"n/a") -> 3493.5246 | G21: =IF('Plan Eligibility'!$E$8="Yes",SUMIFS('Monthly Bills'!$P$5:$P$196,'Monthly Bills'!$A$5:$A$196,"median_home",'Monthly Bills'!$B$5:$B$196,"baseboard")+SUMIFS('Monthly Bills'!$Q$5:$Q$196,'Monthly Bills'!$A$5:$A$196,"median_home",'Monthly Bills'!$B$5:$B$196,"baseboard"),"n/a") -> n/a | H21: =MIN(D21:G21) -> 3493.5246 | I21: =SUBSTITUTE(INDEX($D$17:$G$17,MATCH(H21,D21:G21,0))," ($/yr)","") -> Space heating
A22: Gas furnace + heat pump water heater | B22: =SUMIFS('Monthly Bills'!$E$5:$E$196,'Monthly Bills'!$A$5:$A$196,"median_home",'Monthly Bills'!$B$5:$B$196,"gas_furnace_hpwh") -> 10762.928 | C22: =SUMIFS('Monthly Bills'!$L$5:$L$196,'Monthly Bills'!$A$5:$A$196,"median_home",'Monthly Bills'!$B$5:$B$196,"gas_furnace_hpwh") -> 1150.834 | D22: =IF('Plan Eligibility'!$B$9="Yes",SUMIFS('Monthly Bills'!$M$5:$M$196,'Monthly Bills'!$A$5:$A$196,"median_home",'Monthly Bills'!$B$5:$B$196,"gas_furnace_hpwh")+SUMIFS('Monthly Bills'!$Q$5:$Q$196,'Monthly Bills'!$A$5:$A$196,"median_home",'Monthly Bills'!$B$5:$B$196,"gas_furnace_hpwh"),"n/a") -> 2825.6643 | E22: =IF('Plan Eligibility'!$C$9="Yes",SUMIFS('Monthly Bills'!$N$5:$N$196,'Monthly Bills'!$A$5:$A$196,"median_home",'Monthly Bills'!$B$5:$B$196,"gas_furnace_hpwh")+SUMIFS('Monthly Bills'!$Q$5:$Q$196,'Monthly Bills'!$A$5:$A$196,"median_home",'Monthly Bills'!$B$5:$B$196,"gas_furnace_hpwh"),"n/a") -> 2727.5592 | F22: =IF('Plan Eligibility'!$D$9="Yes",SUMIFS('Monthly Bills'!$O$5:$O$196,'Monthly Bills'!$A$5:$A$196,"median_home",'Monthly Bills'!$B$5:$B$196,"gas_furnace_hpwh")+SUMIFS('Monthly Bills'!$Q$5:$Q$196,'Monthly Bills'!$A$5:$A$196,"median_home",'Monthly Bills'!$B$5:$B$196,"gas_furnace_hpwh"),"n/a") -> n/a | G22: =IF('Plan Eligibility'!$E$9="Yes",SUMIFS('Monthly Bills'!$P$5:$P$196,'Monthly Bills'!$A$5:$A$196,"median_home",'Monthly Bills'!$B$5:$B$196,"gas_furnace_hpwh")+SUMIFS('Monthly Bills'!$Q$5:$Q$196,'Monthly Bills'!$A$5:$A$196,"median_home",'Monthly Bills'!$B$5:$B$196,"gas_furnace_hpwh"),"n/a") -> n/a | H22: =MIN(D22:G22) -> 2727.5592 | I22: =SUBSTITUTE(INDEX($D$17:$G$17,MATCH(H22,D22:G22,0))," ($/yr)","") -> Time-of-use
A23: Heat pump + electric backup + heat pump water heater | B23: =SUMIFS('Monthly Bills'!$E$5:$E$196,'Monthly Bills'!$A$5:$A$196,"median_home",'Monthly Bills'!$B$5:$B$196,"ashp_resistance_backup_hpwh") -> 20427.133 | C23: =SUMIFS('Monthly Bills'!$L$5:$L$196,'Monthly Bills'!$A$5:$A$196,"median_home",'Monthly Bills'!$B$5:$B$196,"ashp_resistance_backup_hpwh") -> 39.151 | D23: =IF('Plan Eligibility'!$B$10="Yes",SUMIFS('Monthly Bills'!$M$5:$M$196,'Monthly Bills'!$A$5:$A$196,"median_home",'Monthly Bills'!$B$5:$B$196,"ashp_resistance_backup_hpwh")+SUMIFS('Monthly Bills'!$Q$5:$Q$196,'Monthly Bills'!$A$5:$A$196,"median_home",'Monthly Bills'!$B$5:$B$196,"ashp_resistance_backup_hpwh"),"n/a") -> 3082.6653 | E23: =IF('Plan Eligibility'!$C$10="Yes",SUMIFS('Monthly Bills'!$N$5:$N$196,'Monthly Bills'!$A$5:$A$196,"median_home",'Monthly Bills'!$B$5:$B$196,"ashp_resistance_backup_hpwh")+SUMIFS('Monthly Bills'!$Q$5:$Q$196,'Monthly Bills'!$A$5:$A$196,"median_home",'Monthly Bills'!$B$5:$B$196,"ashp_resistance_backup_hpwh"),"n/a") -> 2848.409 | F23: =IF('Plan Eligibility'!$D$10="Yes",SUMIFS('Monthly Bills'!$O$5:$O$196,'Monthly Bills'!$A$5:$A$196,"median_home",'Monthly Bills'!$B$5:$B$196,"ashp_resistance_backup_hpwh")+SUMIFS('Monthly Bills'!$Q$5:$Q$196,'Monthly Bills'!$A$5:$A$196,"median_home",'Monthly Bills'!$B$5:$B$196,"ashp_resistance_backup_hpwh"),"n/a") -> 2118.4995 | G23: =IF('Plan Eligibility'!$E$10="Yes",SUMIFS('Monthly Bills'!$P$5:$P$196,'Monthly Bills'!$A$5:$A$196,"median_home",'Monthly Bills'!$B$5:$B$196,"ashp_resistance_backup_hpwh")+SUMIFS('Monthly Bills'!$Q$5:$Q$196,'Monthly Bills'!$A$5:$A$196,"median_home",'Monthly Bills'!$B$5:$B$196,"ashp_resistance_backup_hpwh"),"n/a") -> n/a | H23: =MIN(D23:G23) -> 2118.4995 | I23: =SUBSTITUTE(INDEX($D$17:$G$17,MATCH(H23,D23:G23,0))," ($/yr)","") -> Space heating
A24: Heat pump + gas backup (dual fuel) + heat pump water heater | B24: =SUMIFS('Monthly Bills'!$E$5:$E$196,'Monthly Bills'!$A$5:$A$196,"median_home",'Monthly Bills'!$B$5:$B$196,"ashp_gas_backup_hpwh") -> 11937.351 | C24: =SUMIFS('Monthly Bills'!$L$5:$L$196,'Monthly Bills'!$A$5:$A$196,"median_home",'Monthly Bills'!$B$5:$B$196,"ashp_gas_backup_hpwh") -> 855.242 | D24: =IF('Plan Eligibility'!$B$11="Yes",SUMIFS('Monthly Bills'!$M$5:$M$196,'Monthly Bills'!$A$5:$A$196,"median_home",'Monthly Bills'!$B$5:$B$196,"ashp_gas_backup_hpwh")+SUMIFS('Monthly Bills'!$Q$5:$Q$196,'Monthly Bills'!$A$5:$A$196,"median_home",'Monthly Bills'!$B$5:$B$196,"ashp_gas_backup_hpwh"),"n/a") -> 2714.37 | E24: =IF('Plan Eligibility'!$C$11="Yes",SUMIFS('Monthly Bills'!$N$5:$N$196,'Monthly Bills'!$A$5:$A$196,"median_home",'Monthly Bills'!$B$5:$B$196,"ashp_gas_backup_hpwh")+SUMIFS('Monthly Bills'!$Q$5:$Q$196,'Monthly Bills'!$A$5:$A$196,"median_home",'Monthly Bills'!$B$5:$B$196,"ashp_gas_backup_hpwh"),"n/a") -> 2606.628 | F24: =IF('Plan Eligibility'!$D$11="Yes",SUMIFS('Monthly Bills'!$O$5:$O$196,'Monthly Bills'!$A$5:$A$196,"median_home",'Monthly Bills'!$B$5:$B$196,"ashp_gas_backup_hpwh")+SUMIFS('Monthly Bills'!$Q$5:$Q$196,'Monthly Bills'!$A$5:$A$196,"median_home",'Monthly Bills'!$B$5:$B$196,"ashp_gas_backup_hpwh"),"n/a") -> n/a | G24: =IF('Plan Eligibility'!$E$11="Yes",SUMIFS('Monthly Bills'!$P$5:$P$196,'Monthly Bills'!$A$5:$A$196,"median_home",'Monthly Bills'!$B$5:$B$196,"ashp_gas_backup_hpwh")+SUMIFS('Monthly Bills'!$Q$5:$Q$196,'Monthly Bills'!$A$5:$A$196,"median_home",'Monthly Bills'!$B$5:$B$196,"ashp_gas_backup_hpwh"),"n/a") -> 2614.5448 | H24: =MIN(D24:G24) -> 2606.628 | I24: =SUBSTITUTE(INDEX($D$17:$G$17,MATCH(H24,D24:G24,0))," ($/yr)","") -> Time-of-use
A25: Electric baseboard + heat pump water heater | B25: =SUMIFS('Monthly Bills'!$E$5:$E$196,'Monthly Bills'!$A$5:$A$196,"median_home",'Monthly Bills'!$B$5:$B$196,"baseboard_hpwh") -> 36824.513 | C25: =SUMIFS('Monthly Bills'!$L$5:$L$196,'Monthly Bills'!$A$5:$A$196,"median_home",'Monthly Bills'!$B$5:$B$196,"baseboard_hpwh") -> 39.151 | D25: =IF('Plan Eligibility'!$B$12="Yes",SUMIFS('Monthly Bills'!$M$5:$M$196,'Monthly Bills'!$A$5:$A$196,"median_home",'Monthly Bills'!$B$5:$B$196,"baseboard_hpwh")+SUMIFS('Monthly Bills'!$Q$5:$Q$196,'Monthly Bills'!$A$5:$A$196,"median_home",'Monthly Bills'!$B$5:$B$196,"baseboard_hpwh"),"n/a") -> 5284.0309 | E25: =IF('Plan Eligibility'!$C$12="Yes",SUMIFS('Monthly Bills'!$N$5:$N$196,'Monthly Bills'!$A$5:$A$196,"median_home",'Monthly Bills'!$B$5:$B$196,"baseboard_hpwh")+SUMIFS('Monthly Bills'!$Q$5:$Q$196,'Monthly Bills'!$A$5:$A$196,"median_home",'Monthly Bills'!$B$5:$B$196,"baseboard_hpwh"),"n/a") -> 4828.5538 | F25: =IF('Plan Eligibility'!$D$12="Yes",SUMIFS('Monthly Bills'!$O$5:$O$196,'Monthly Bills'!$A$5:$A$196,"median_home",'Monthly Bills'!$B$5:$B$196,"baseboard_hpwh")+SUMIFS('Monthly Bills'!$Q$5:$Q$196,'Monthly Bills'!$A$5:$A$196,"median_home",'Monthly Bills'!$B$5:$B$196,"baseboard_hpwh"),"n/a") -> 3371.8325 | G25: =IF('Plan Eligibility'!$E$12="Yes",SUMIFS('Monthly Bills'!$P$5:$P$196,'Monthly Bills'!$A$5:$A$196,"median_home",'Monthly Bills'!$B$5:$B$196,"baseboard_hpwh")+SUMIFS('Monthly Bills'!$Q$5:$Q$196,'Monthly Bills'!$A$5:$A$196,"median_home",'Monthly Bills'!$B$5:$B$196,"baseboard_hpwh"),"n/a") -> n/a | H25: =MIN(D25:G25) -> 3371.8325 | I25: =SUBSTITUTE(INDEX($D$17:$G$17,MATCH(H25,D25:G25,0))," ($/yr)","") -> Space heating
A28: Electric and gas split, average profile
A29: Setup | B29: Standard electric ($/yr) | C29: Time-of-use electric ($/yr) | D29: Space heating electric ($/yr) | E29: Dual fuel electric ($/yr) | F29: Gas ($/yr)
A30: Gas furnace | B30: =IF('Plan Eligibility'!$B$5="Yes",SUMIFS('Monthly Bills'!$M$5:$M$196,'Monthly Bills'!$A$5:$A$196,"average",'Monthly Bills'!$B$5:$B$196,"gas_furnace"),"n/a") -> 1562.4296 | C30: =IF('Plan Eligibility'!$C$5="Yes",SUMIFS('Monthly Bills'!$N$5:$N$196,'Monthly Bills'!$A$5:$A$196,"average",'Monthly Bills'!$B$5:$B$196,"gas_furnace"),"n/a") -> 1480.8973 | D30: =IF('Plan Eligibility'!$D$5="Yes",SUMIFS('Monthly Bills'!$O$5:$O$196,'Monthly Bills'!$A$5:$A$196,"average",'Monthly Bills'!$B$5:$B$196,"gas_furnace"),"n/a") -> n/a | E30: =IF('Plan Eligibility'!$E$5="Yes",SUMIFS('Monthly Bills'!$P$5:$P$196,'Monthly Bills'!$A$5:$A$196,"average",'Monthly Bills'!$B$5:$B$196,"gas_furnace"),"n/a") -> n/a | F30: =SUMIFS('Monthly Bills'!$Q$5:$Q$196,'Monthly Bills'!$A$5:$A$196,"average",'Monthly Bills'!$B$5:$B$196,"gas_furnace") -> 1478.2366
A31: Heat pump + electric backup | B31: =IF('Plan Eligibility'!$B$6="Yes",SUMIFS('Monthly Bills'!$M$5:$M$196,'Monthly Bills'!$A$5:$A$196,"average",'Monthly Bills'!$B$5:$B$196,"ashp_resistance_backup"),"n/a") -> 3329.0752 | C31: =IF('Plan Eligibility'!$C$6="Yes",SUMIFS('Monthly Bills'!$N$5:$N$196,'Monthly Bills'!$A$5:$A$196,"average",'Monthly Bills'!$B$5:$B$196,"ashp_resistance_backup"),"n/a") -> 3061.608 | D31: =IF('Plan Eligibility'!$D$6="Yes",SUMIFS('Monthly Bills'!$O$5:$O$196,'Monthly Bills'!$A$5:$A$196,"average",'Monthly Bills'!$B$5:$B$196,"ashp_resistance_backup"),"n/a") -> 2167.1536 | E31: =IF('Plan Eligibility'!$E$6="Yes",SUMIFS('Monthly Bills'!$P$5:$P$196,'Monthly Bills'!$A$5:$A$196,"average",'Monthly Bills'!$B$5:$B$196,"ashp_resistance_backup"),"n/a") -> n/a | F31: =SUMIFS('Monthly Bills'!$Q$5:$Q$196,'Monthly Bills'!$A$5:$A$196,"average",'Monthly Bills'!$B$5:$B$196,"ashp_resistance_backup") -> 280.47583
A32: Heat pump + gas backup (dual fuel) | B32: =IF('Plan Eligibility'!$B$7="Yes",SUMIFS('Monthly Bills'!$M$5:$M$196,'Monthly Bills'!$A$5:$A$196,"average",'Monthly Bills'!$B$5:$B$196,"ashp_gas_backup"),"n/a") -> 1806.6448 | C32: =IF('Plan Eligibility'!$C$7="Yes",SUMIFS('Monthly Bills'!$N$5:$N$196,'Monthly Bills'!$A$5:$A$196,"average",'Monthly Bills'!$B$5:$B$196,"ashp_gas_backup"),"n/a") -> 1707.3487 | D32: =IF('Plan Eligibility'!$D$7="Yes",SUMIFS('Monthly Bills'!$O$5:$O$196,'Monthly Bills'!$A$5:$A$196,"average",'Monthly Bills'!$B$5:$B$196,"ashp_gas_backup"),"n/a") -> n/a | E32: =IF('Plan Eligibility'!$E$7="Yes",SUMIFS('Monthly Bills'!$P$5:$P$196,'Monthly Bills'!$A$5:$A$196,"average",'Monthly Bills'!$B$5:$B$196,"ashp_gas_backup"),"n/a") -> 1670.8372 | F32: =SUMIFS('Monthly Bills'!$Q$5:$Q$196,'Monthly Bills'!$A$5:$A$196,"average",'Monthly Bills'!$B$5:$B$196,"ashp_gas_backup") -> 1279.2214
A33: Electric baseboard | B33: =IF('Plan Eligibility'!$B$8="Yes",SUMIFS('Monthly Bills'!$M$5:$M$196,'Monthly Bills'!$A$5:$A$196,"average",'Monthly Bills'!$B$5:$B$196,"baseboard"),"n/a") -> 5800.1758 | C33: =IF('Plan Eligibility'!$C$8="Yes",SUMIFS('Monthly Bills'!$N$5:$N$196,'Monthly Bills'!$A$5:$A$196,"average",'Monthly Bills'!$B$5:$B$196,"baseboard"),"n/a") -> 5296.011 | D33: =IF('Plan Eligibility'!$D$8="Yes",SUMIFS('Monthly Bills'!$O$5:$O$196,'Monthly Bills'!$A$5:$A$196,"average",'Monthly Bills'!$B$5:$B$196,"baseboard"),"n/a") -> 3577.6008 | E33: =IF('Plan Eligibility'!$E$8="Yes",SUMIFS('Monthly Bills'!$P$5:$P$196,'Monthly Bills'!$A$5:$A$196,"average",'Monthly Bills'!$B$5:$B$196,"baseboard"),"n/a") -> n/a | F33: =SUMIFS('Monthly Bills'!$Q$5:$Q$196,'Monthly Bills'!$A$5:$A$196,"average",'Monthly Bills'!$B$5:$B$196,"baseboard") -> 280.45806
A34: Gas furnace + heat pump water heater | B34: =IF('Plan Eligibility'!$B$9="Yes",SUMIFS('Monthly Bills'!$M$5:$M$196,'Monthly Bills'!$A$5:$A$196,"average",'Monthly Bills'!$B$5:$B$196,"gas_furnace_hpwh"),"n/a") -> 1605.1585 | C34: =IF('Plan Eligibility'!$C$9="Yes",SUMIFS('Monthly Bills'!$N$5:$N$196,'Monthly Bills'!$A$5:$A$196,"average",'Monthly Bills'!$B$5:$B$196,"gas_furnace_hpwh"),"n/a") -> 1520.6057 | D34: =IF('Plan Eligibility'!$D$9="Yes",SUMIFS('Monthly Bills'!$O$5:$O$196,'Monthly Bills'!$A$5:$A$196,"average",'Monthly Bills'!$B$5:$B$196,"gas_furnace_hpwh"),"n/a") -> n/a | E34: =IF('Plan Eligibility'!$E$9="Yes",SUMIFS('Monthly Bills'!$P$5:$P$196,'Monthly Bills'!$A$5:$A$196,"average",'Monthly Bills'!$B$5:$B$196,"gas_furnace_hpwh"),"n/a") -> n/a | F34: =SUMIFS('Monthly Bills'!$Q$5:$Q$196,'Monthly Bills'!$A$5:$A$196,"average",'Monthly Bills'!$B$5:$B$196,"gas_furnace_hpwh") -> 1338.332
A35: Heat pump + electric backup + heat pump water heater | B35: =IF('Plan Eligibility'!$B$10="Yes",SUMIFS('Monthly Bills'!$M$5:$M$196,'Monthly Bills'!$A$5:$A$196,"average",'Monthly Bills'!$B$5:$B$196,"ashp_resistance_backup_hpwh"),"n/a") -> 3371.2167 | C35: =IF('Plan Eligibility'!$C$10="Yes",SUMIFS('Monthly Bills'!$N$5:$N$196,'Monthly Bills'!$A$5:$A$196,"average",'Monthly Bills'!$B$5:$B$196,"ashp_resistance_backup_hpwh"),"n/a") -> 3101.3647 | D35: =IF('Plan Eligibility'!$D$10="Yes",SUMIFS('Monthly Bills'!$O$5:$O$196,'Monthly Bills'!$A$5:$A$196,"average",'Monthly Bills'!$B$5:$B$196,"ashp_resistance_backup_hpwh"),"n/a") -> 2193.875 | E35: =IF('Plan Eligibility'!$E$10="Yes",SUMIFS('Monthly Bills'!$P$5:$P$196,'Monthly Bills'!$A$5:$A$196,"average",'Monthly Bills'!$B$5:$B$196,"ashp_resistance_backup_hpwh"),"n/a") -> n/a | F35: =SUMIFS('Monthly Bills'!$Q$5:$Q$196,'Monthly Bills'!$A$5:$A$196,"average",'Monthly Bills'!$B$5:$B$196,"ashp_resistance_backup_hpwh") -> 140.54971
A36: Heat pump + gas backup (dual fuel) + heat pump water heater | B36: =IF('Plan Eligibility'!$B$11="Yes",SUMIFS('Monthly Bills'!$M$5:$M$196,'Monthly Bills'!$A$5:$A$196,"average",'Monthly Bills'!$B$5:$B$196,"ashp_gas_backup_hpwh"),"n/a") -> 1849.1653 | C36: =IF('Plan Eligibility'!$C$11="Yes",SUMIFS('Monthly Bills'!$N$5:$N$196,'Monthly Bills'!$A$5:$A$196,"average",'Monthly Bills'!$B$5:$B$196,"ashp_gas_backup_hpwh"),"n/a") -> 1747.1432 | D36: =IF('Plan Eligibility'!$D$11="Yes",SUMIFS('Monthly Bills'!$O$5:$O$196,'Monthly Bills'!$A$5:$A$196,"average",'Monthly Bills'!$B$5:$B$196,"ashp_gas_backup_hpwh"),"n/a") -> n/a | E36: =IF('Plan Eligibility'!$E$11="Yes",SUMIFS('Monthly Bills'!$P$5:$P$196,'Monthly Bills'!$A$5:$A$196,"average",'Monthly Bills'!$B$5:$B$196,"ashp_gas_backup_hpwh"),"n/a") -> 1713.6621 | F36: =SUMIFS('Monthly Bills'!$Q$5:$Q$196,'Monthly Bills'!$A$5:$A$196,"average",'Monthly Bills'!$B$5:$B$196,"ashp_gas_backup_hpwh") -> 1139.4355
A37: Electric baseboard + heat pump water heater | B37: =IF('Plan Eligibility'!$B$12="Yes",SUMIFS('Monthly Bills'!$M$5:$M$196,'Monthly Bills'!$A$5:$A$196,"average",'Monthly Bills'!$B$5:$B$196,"baseboard_hpwh"),"n/a") -> 5842.2638 | C37: =IF('Plan Eligibility'!$C$12="Yes",SUMIFS('Monthly Bills'!$N$5:$N$196,'Monthly Bills'!$A$5:$A$196,"average",'Monthly Bills'!$B$5:$B$196,"baseboard_hpwh"),"n/a") -> 5335.7197 | D37: =IF('Plan Eligibility'!$D$12="Yes",SUMIFS('Monthly Bills'!$O$5:$O$196,'Monthly Bills'!$A$5:$A$196,"average",'Monthly Bills'!$B$5:$B$196,"baseboard_hpwh"),"n/a") -> 3604.2906 | E37: =IF('Plan Eligibility'!$E$12="Yes",SUMIFS('Monthly Bills'!$P$5:$P$196,'Monthly Bills'!$A$5:$A$196,"average",'Monthly Bills'!$B$5:$B$196,"baseboard_hpwh"),"n/a") -> n/a | F37: =SUMIFS('Monthly Bills'!$Q$5:$Q$196,'Monthly Bills'!$A$5:$A$196,"average",'Monthly Bills'!$B$5:$B$196,"baseboard_hpwh") -> 140.54971

Sheet Rates
A1: Rate inputs
A2: Blue text on yellow = input to replace with the current tariff sheet value. Every price is unverified (see Read Me). Bills on the other sheets recalculate from these cells.
A4: Rate | B4: Component | C4: Applies to | D4: Months | E4: Hours / days | F4: Price | G4: Unit | H4: Source | I4: Notes
A5: xcel_standard | B5: customer_charge | C5: total | D5: 1-12 | E5: all hours | F5: 8 | G5: USD/month | H5: Web search summary citing Xcel MN residential rate card (MNResRateCard.pdf); effective date not confirmed | I5: Overhead service; underground service is $10.00
A6: xcel_standard | B6: energy_summer | C6: total | D6: 6-9 | E6: all hours | F6: 0.13655 | G6: USD/kWh | H6: Web search summary citing Xcel MN residential rate card (MNResRateCard.pdf); effective date not confirmed
A7: xcel_standard | B7: energy_winter_block1 | C7: total | D7: 10-12;1-5 | E7: all hours; monthly block from 0 kWh to 1000 kWh | F7: 0.12096 | G7: USD/kWh | H7: Web search summary citing Xcel MN residential rate card (MNResRateCard.pdf); effective date not confirmed | I7: First 1000 kWh per month
A8: xcel_standard | B8: energy_winter_block2 | C8: total | D8: 10-12;1-5 | E8: all hours; monthly block from 1000 kWh | F8: 0.11838 | G8: USD/kWh | H8: Web search summary citing Xcel MN residential rate card (MNResRateCard.pdf); effective date not confirmed | I8: kWh above 1000 per month
A9: xcel_standard | B9: fuel_cost_charge | C9: total | D9: 1-12 | E9: all hours | F9: 0.01568 | G9: USD/kWh | H9: Web search summary: Xcel MN Fuel Cost Charge for residential January 2026 | I9: Set monthly; January 2026 value applied to all months
A10: xcel_standard | B10: resource_adjustment | C10: total | D10: 1-12 | E10: all hours | F10: 0 | G10: USD/kWh | H10: Not found; Xcel Resource Adjustment riders (CIP; SEP; RDF; TCR; RES) apply per kWh but values were not retrieved | I10: Enter current rider total
A11: xcel_standard | B11: winter_block_size | D11: 10-12;1-5 | F11: 1000 | G11: kWh/month | H11: Block limit in config/rates/xcel_standard.csv | I11: Size of the first winter energy block
A12: xcel_tou | B12: customer_charge | C12: total | D12: 1-12 | E12: all hours | F12: 8 | G12: USD/month | H12: Not found; assumed equal to standard residential customer charge
A13: xcel_tou | B13: on_peak_summer | C13: total | D13: 6-9 | E13: 18-21 local, weekday nonholiday | F13: 0.21 | G13: USD/kWh | H13: Web search summaries of Hoodline (July 2026) and CUB Minnesota reports on the approved Xcel MN residential time-of-use rate; prices reported as approximate | I13: 6-9 p.m. non-holiday weekdays
A14: xcel_tou | B14: on_peak_winter | C14: total | D14: 10-12;1-5 | E14: 18-21 local, weekday nonholiday | F14: 0.17 | G14: USD/kWh | H14: Web search summaries of Hoodline (July 2026) and CUB Minnesota reports on the approved Xcel MN residential time-of-use rate; prices reported as approximate
A15: xcel_tou | B15: super_off_peak | C15: total | D15: 1-12 | E15: 0-6 local | F15: 0.075 | G15: USD/kWh | H15: Web search summaries of Hoodline (July 2026) and CUB Minnesota reports on the approved Xcel MN residential time-of-use rate; prices reported as approximate | I15: Midnight-6 a.m. every day
A16: xcel_tou | B16: base_summer_weekday | C16: total | D16: 6-9 | E16: 6-18;21-24 local, weekday nonholiday | F16: 0.13 | G16: USD/kWh | H16: Web search summaries of Hoodline (July 2026) and CUB Minnesota reports on the approved Xcel MN residential time-of-use rate; prices reported as approximate | I16: All other hours billed near the standard flat price
A17: xcel_tou | B17: base_summer_weekend | C17: total | D17: 6-9 | E17: 6-24 local, weekend holiday | F17: 0.13 | G17: USD/kWh | H17: Web search summaries of Hoodline (July 2026) and CUB Minnesota reports on the approved Xcel MN residential time-of-use rate; prices reported as approximate
A18: xcel_tou | B18: base_winter_weekday | C18: total | D18: 10-12;1-5 | E18: 6-18;21-24 local, weekday nonholiday | F18: 0.11 | G18: USD/kWh | H18: Web search summaries of Hoodline (July 2026) and CUB Minnesota reports on the approved Xcel MN residential time-of-use rate; prices reported as approximate
A19: xcel_tou | B19: base_winter_weekend | C19: total | D19: 10-12;1-5 | E19: 6-24 local, weekend holiday | F19: 0.11 | G19: USD/kWh | H19: Web search summaries of Hoodline (July 2026) and CUB Minnesota reports on the approved Xcel MN residential time-of-use rate; prices reported as approximate
A20: xcel_tou | B20: fuel_cost_charge | C20: total | D20: 1-12 | E20: all hours | F20: 0.01568 | G20: USD/kWh | H20: Web search summary: Xcel MN Fuel Cost Charge for residential January 2026 | I20: Not confirmed whether TOU prices include fuel cost
A21: xcel_tou | B21: resource_adjustment | C21: total | D21: 1-12 | E21: all hours | F21: 0 | G21: USD/kWh | H21: Not found; Xcel Resource Adjustment riders (CIP; SEP; RDF; TCR; RES) apply per kWh but values were not retrieved | I21: Enter current rider total
A22: xcel_space_heating | B22: customer_charge | C22: total | D22: 1-12 | E22: all hours | F22: 8 | G22: USD/month | H22: Web search summary citing Xcel MN residential rate card (MNResRateCard.pdf); effective date not confirmed | I22: Overhead service
A23: xcel_space_heating | B23: energy_summer | C23: total | D23: 6-9 | E23: all hours | F23: 0.13655 | G23: USD/kWh | H23: Web search summary citing Xcel MN residential rate card (MNResRateCard.pdf); effective date not confirmed | I23: Same as standard residential
A24: xcel_space_heating | B24: energy_winter_space_heat | C24: total | D24: 10-12;1-5 | E24: all hours | F24: 0.06 | G24: USD/kWh | H24: Web search summary (electricchoice.com page citing Xcel MN rates); tariff structure not confirmed | I24: Tariff may apply the lower price only above a monthly block or only to space heating kWh
A25: xcel_space_heating | B25: fuel_cost_charge | C25: total | D25: 1-12 | E25: all hours | F25: 0.01568 | G25: USD/kWh | H25: Web search summary: Xcel MN Fuel Cost Charge for residential January 2026 | I25: January 2026 value applied to all months
A26: xcel_space_heating | B26: resource_adjustment | C26: total | D26: 1-12 | E26: all hours | F26: 0 | G26: USD/kWh | H26: Not found; Xcel Resource Adjustment riders (CIP; SEP; RDF; TCR; RES) apply per kWh but values were not retrieved | I26: Enter current rider total
A27: xcel_dual_fuel | B27: customer_charge | C27: non_heating | D27: 1-12 | E27: all hours | F27: 8 | G27: USD/month | H27: Web search summary citing Xcel MN residential rate card (MNResRateCard.pdf); effective date not confirmed | I27: Main meter: standard residential
A28: xcel_dual_fuel | B28: energy_summer | C28: non_heating | D28: 6-9 | E28: all hours | F28: 0.13655 | G28: USD/kWh | H28: Web search summary citing Xcel MN residential rate card (MNResRateCard.pdf); effective date not confirmed
A29: xcel_dual_fuel | B29: energy_winter_block1 | C29: non_heating | D29: 10-12;1-5 | E29: all hours; monthly block from 0 kWh to 1000 kWh | F29: 0.12096 | G29: USD/kWh | H29: Web search summary citing Xcel MN residential rate card (MNResRateCard.pdf); effective date not confirmed
A30: xcel_dual_fuel | B30: energy_winter_block2 | C30: non_heating | D30: 10-12;1-5 | E30: all hours; monthly block from 1000 kWh | F30: 0.11838 | G30: USD/kWh | H30: Web search summary citing Xcel MN residential rate card (MNResRateCard.pdf); effective date not confirmed
A31: xcel_dual_fuel | B31: ecs_customer_charge | C31: heating | D31: 1-12 | E31: all hours | F31: 4.95 | G31: USD/month | H31: Web search summary citing Xcel MN residential rate card: Energy-Controlled Service (non-demand); effective date not confirmed | I31: Second meter on the interruptible heating load
A32: xcel_dual_fuel | B32: ecs_energy | C32: heating | D32: 1-12 | E32: all hours | F32: 0.04506 | G32: USD/kWh | H32: Web search summary citing Xcel MN residential rate card: Energy-Controlled Service (non-demand); effective date not confirmed | I32: Utility control events not modeled
A33: xcel_dual_fuel | B33: fuel_cost_charge | C33: total | D33: 1-12 | E33: all hours | F33: 0.01568 | G33: USD/kWh | H33: Web search summary: Xcel MN Fuel Cost Charge for residential January 2026 | I33: January 2026 value applied to all months
A34: xcel_dual_fuel | B34: resource_adjustment | C34: total | D34: 1-12 | E34: all hours | F34: 0 | G34: USD/kWh | H34: Not found; Xcel Resource Adjustment riders (CIP; SEP; RDF; TCR; RES) apply per kWh but values were not retrieved | I34: Enter current rider total
A35: xcel_dual_fuel | B35: winter_block_size | D35: 10-12;1-5 | F35: 1000 | G35: kWh/month | H35: Block limit in config/rates/xcel_dual_fuel.csv | I35: Size of the first winter energy block
A36: centerpoint_residential | B36: basic_charge | C36: total | D36: 1-12 | E36: all hours | F36: 9.5 | G36: USD/month | H36: Web search summary citing CenterPoint Energy MN final rates bill insert (250620-07_MN_FinalRates_BI_Sept_Web.pdf); effective September 2025
A37: centerpoint_residential | B37: delivery_charge | C37: total | D37: 1-12 | E37: all hours | F37: 0.3347 | G37: USD/therm | H37: Web search summary citing CenterPoint Energy MN final rates bill insert (250620-07_MN_FinalRates_BI_Sept_Web.pdf); effective September 2025
A38: centerpoint_residential | B38: cost_of_gas | C38: total | D38: 1-12 | E38: all hours | F38: 0.60061 | G38: USD/therm | H38: Web search summary: CenterPoint MN residential cost of gas as of April 2026; the tariff resets this monthly | I38: Replace with monthly values (one row per month) for seasonal gas prices
A39: centerpoint_residential | B39: gas_riders | C39: total | D39: 1-12 | E39: all hours | F39: 0 | G39: USD/therm | H39: Not found; CenterPoint MN per-therm riders (CIP adjustment and others) were not retrieved | I39: Enter current rider total

Sheet Plan Eligibility
A1: Which setups each rate plan is modeled for
A2: Yes/No inputs from config/rate_plans.csv. A setup marked No shows n/a on the Summary sheet.
A4: Setup | B4: Standard | C4: Time-of-use | D4: Space heating | E4: Dual fuel
A5: gas_furnace | B5: Yes | C5: Yes | D5: No | E5: No
A6: ashp_resistance_backup | B6: Yes | C6: Yes | D6: Yes | E6: No
A7: ashp_gas_backup | B7: Yes | C7: Yes | D7: No | E7: Yes
A8: baseboard | B8: Yes | C8: Yes | D8: Yes | E8: No
A9: gas_furnace_hpwh | B9: Yes | C9: Yes | D9: No | E9: No
A10: ashp_resistance_backup_hpwh | B10: Yes | C10: Yes | D10: Yes | E10: No
A11: ashp_gas_backup_hpwh | B11: Yes | C11: Yes | D11: No | E11: Yes
A12: baseboard_hpwh | B12: Yes | C12: Yes | D12: Yes | E12: No
A14: Plan descriptions: standard = Xcel standard residential + CenterPoint residential; time_of_use = Xcel residential time-of-use + CenterPoint residential; space_heating = Xcel residential with electric space heating + CenterPoint residential; dual_fuel = Xcel standard (house) + Energy-Controlled Service (heating) + CenterPoint residential

Sheet Annual Usage
A1: Annual use by end use and highest hourly use
A2: Model outputs from outputs/annual_usage.csv. Highest hourly kWh equals average kW over that hour; the average profile smooths peaks across 200 homes.
A4: Profile | B4: Setup | C4: Electricity (kWh) | D4: Heating (kWh) | E4: Cooling (kWh) | F4: Hot water (kWh) | G4: Other (kWh) | H4: Highest hour (kWh) | I4: Highest hour (standard time) | J4: Gas (therms) | K4: Gas heating (therms) | L4: Gas hot water (therms) | M4: Gas other (therms)
A5: average | B5: gas_furnace | C5: 10283.8 | D5: 903.8 | E5: 1983.6 | F5: 582.2 | G5: 6814.2 | H5: 3.1 | I5: 2018-06-29 20:00:00 | J5: 1458.6 | K5: 1280.6 | L5: 149.6 | M5: 28.4
A6: median_home | B6: gas_furnace | C6: 9683.2 | D6: 832.5 | E6: 2627.7 | F6: 0 | G6: 6223 | H6: 4.4 | I6: 2018-08-06 20:00:00 | J6: 1391.3 | K6: 1111.7 | L6: 240.5 | M6: 39.2
A7: average | B7: ashp_resistance_backup | C7: 23438.7 | D7: 14383.9 | E7: 1660.6 | F7: 581.8 | G7: 6812.4 | H7: 15.9 | I7: 2018-01-01 09:00:00 | J7: 178 | K7: 0 | L7: 149.6 | M7: 28.4
A8: median_home | B8: ashp_resistance_backup | C8: 19347.4 | D8: 10910.3 | E8: 2214.8 | F8: 0 | G8: 6222.3 | H8: 11 | I8: 2018-01-01 19:00:00 | J8: 279.7 | K8: 0 | L8: 240.6 | M8: 39.2
A9: average | B9: ashp_gas_backup | C9: 12037.9 | D9: 2564.9 | E9: 2078.5 | F9: 581.5 | G9: 6813.1 | H9: 3.4 | I9: 2018-06-29 19:00:00 | J9: 1245.8 | K9: 1068 | L9: 149.5 | M9: 28.4
A10: median_home | B10: ashp_gas_backup | C10: 10857.6 | D10: 1902 | E10: 2733 | F10: 0 | G10: 6222.6 | H10: 4.7 | I10: 2018-08-06 20:00:00 | J10: 1095.8 | K10: 816.1 | L10: 240.5 | M10: 39.2
A11: average | B11: baseboard | C11: 41838.2 | D11: 32458.2 | E11: 1983.6 | F11: 582.2 | G11: 6814.2 | H11: 20.3 | I11: 2018-01-01 08:00:00 | J11: 178 | K11: 0 | L11: 149.6 | M11: 28.4
A12: median_home | B12: baseboard | C12: 35744.8 | D12: 26894.1 | E12: 2627.7 | F12: 0 | G12: 6223 | H12: 17.5 | I12: 2018-01-01 19:00:00 | J12: 279.6 | K12: 0 | L12: 240.5 | M12: 39.2
A13: average | B13: gas_furnace_hpwh | C13: 10591.4 | D13: 903.8 | E13: 1983.6 | F13: 889.8 | G13: 6814.2 | H13: 3.1 | I13: 2018-06-29 20:00:00 | J13: 1309 | K13: 1280.6 | L13: 0 | M13: 28.4
A14: median_home | B14: gas_furnace_hpwh | C14: 10762.9 | D14: 832.5 | E14: 2627.7 | F14: 1079.7 | G14: 6223 | H14: 4.6 | I14: 2018-07-10 19:00:00 | J14: 1150.8 | K14: 1111.7 | L14: 0 | M14: 39.2
A15: average | B15: ashp_resistance_backup_hpwh | C15: 23746.7 | D15: 14383.9 | E15: 1660.6 | F15: 889.8 | G15: 6812.4 | H15: 16 | I15: 2018-01-01 09:00:00 | J15: 28.4 | K15: 0 | L15: 0 | M15: 28.4
A16: median_home | B16: ashp_resistance_backup_hpwh | C16: 20427.1 | D16: 10910.3 | E16: 2214.8 | F16: 1079.7 | G16: 6222.3 | H16: 11.4 | I16: 2018-01-01 19:00:00 | J16: 39.2 | K16: 0 | L16: 0 | M16: 39.2
... A20: median_home | B20: baseboard_hpwh | C20: 36824.5 | D20: 26894.1 | E20: 2627.7 | F20: 1079.7 | G20: 6223 | H20: 17.9 | I20: 2018-01-01 19:00:00 | J20: 39.2 | K20: 0 | L20: 0 | M20: 39.2
A23: Sample check: annual values from ResStock metadata
A24: Metric | B24: All 2,443 metro homes: mean | C24: All metro homes: median | D24: 200-home sample: mean | E24: Median home
A25: elec_kwh | B25: 10134.9 | C25: 9606.3 | D25: 10283.8 | E25: 9683.1
A26: sqft | B26: 2293.4 | C26: 2179 | D26: 2357 | E26: 2179
A27: gas_therms | B27: 1503.4 | C27: 1392.3 | D27: 1458.6 | E27: 1391.3

Sheet Monthly Bills
A1: Monthly billing quantities and bills
A2: Columns E-L are model outputs from the hourly profiles (blue). Columns M-Q are formulas using the Rates sheet. Time-of-use periods use local clock time: on-peak 6-9 p.m. non-holiday weekdays, super off-peak midnight-6 a.m.
A4: Profile | B4: Setup | C4: Month | D4: Summer (Jun-Sep) | E4: Electricity (kWh) | F4: Heating electricity (kWh) | G4: Non-heating electricity (kWh) | H4: On-peak kWh | I4: Super off-peak kWh | J4: Base kWh, weekdays | K4: Base kWh, weekends/holidays | L4: Gas (therms) | M4: Standard electric ($) | N4: Time-of-use electric ($) | O4: Space heating electric ($) | P4: Dual fuel electric ($) | Q4: Gas ($)
A5: average | B5: gas_furnace | C5: 1 | D5: =IF(AND(C5>=6,C5<=9),1,0) -> 0 | E5: 903.405 | F5: 209.848 | G5: =E5-F5 -> 693.557 | H5: 111.648 | I5: 157.031 | J5: 408.443 | K5: 226.283 | L5: 314.659 | M5: =Rates!$F$5+IF(D5=1,E5*Rates!$F$6,MIN(E5,Rates!$F$11)*Rates!$F$7+MAX(E5-Rates!$F$11,0)*Rates!$F$8)+E5*(Rates!$F$9+Rates!$F$10) -> 131.44126 | N5: =Rates!$F$12+H5*IF(D5=1,Rates!$F$13,Rates!$F$14)+I5*Rates!$F$15+J5*IF(D5=1,Rates!$F$16,Rates!$F$18)+K5*IF(D5=1,Rates!$F$17,Rates!$F$19)+E5*(Rates!$F$20+Rates!$F$21) -> 122.74274 | O5: =Rates!$F$22+IF(D5=1,E5*Rates!$F$23,E5*Rates!$F$24)+E5*(Rates!$F$25+Rates!$F$26) -> 76.36969 | P5: =Rates!$F$27+IF(D5=1,G5*Rates!$F$28,MIN(G5,Rates!$F$35)*Rates!$F$29+MAX(G5-Rates!$F$35,0)*Rates!$F$30)+IF(F5>0,Rates!$F$31,0)+F5*Rates!$F$32+E5*(Rates!$F$33+Rates!$F$34) -> 120.4638 | Q5: =IF(L5>0,Rates!$F$36,0)+L5*(Rates!$F$37+Rates!$F$38+Rates!$F$39) -> 303.80371
A6: average | B6: gas_furnace | C6: 2 | D6: =IF(AND(C6>=6,C6<=9),1,0) -> 0 | E6: 808.162 | F6: 179.652 | G6: =E6-F6 -> 628.51 | H6: 99.836 | I6: 140.711 | J6: 367.465 | K6: 200.15 | L6: 270.387 | M6: =Rates!$F$5+IF(D6=1,E6*Rates!$F$6,MIN(E6,Rates!$F$11)*Rates!$F$7+MAX(E6-Rates!$F$11,0)*Rates!$F$8)+E6*(Rates!$F$9+Rates!$F$10) -> 118.42726 | N6: =Rates!$F$12+H6*IF(D6=1,Rates!$F$13,Rates!$F$14)+I6*Rates!$F$15+J6*IF(D6=1,Rates!$F$16,Rates!$F$18)+K6*IF(D6=1,Rates!$F$17,Rates!$F$19)+E6*(Rates!$F$20+Rates!$F$21) -> 110.63508 | O6: =Rates!$F$22+IF(D6=1,E6*Rates!$F$23,E6*Rates!$F$24)+E6*(Rates!$F$25+Rates!$F$26) -> 69.1617 | P6: =Rates!$F$27+IF(D6=1,G6*Rates!$F$28,MIN(G6,Rates!$F$35)*Rates!$F$29+MAX(G6-Rates!$F$35,0)*Rates!$F$30)+IF(F6>0,Rates!$F$31,0)+F6*Rates!$F$32+E6*(Rates!$F$33+Rates!$F$34) -> 109.74167 | Q6: =IF(L6>0,Rates!$F$36,0)+L6*(Rates!$F$37+Rates!$F$38+Rates!$F$39) -> 262.39566
A7: average | B7: gas_furnace | C7: 3 | D7: =IF(AND(C7>=6,C7<=9),1,0) -> 0 | E7: 779.344 | F7: 104.702 | G7: =E7-F7 -> 674.642 | H7: 92.949 | I7: 133.863 | J7: 359.217 | K7: 193.315 | L7: 165.623 | M7: =Rates!$F$5+IF(D7=1,E7*Rates!$F$6,MIN(E7,Rates!$F$11)*Rates!$F$7+MAX(E7-Rates!$F$11,0)*Rates!$F$8)+E7*(Rates!$F$9+Rates!$F$10) -> 114.48956 | N7: =Rates!$F$12+H7*IF(D7=1,Rates!$F$13,Rates!$F$14)+I7*Rates!$F$15+J7*IF(D7=1,Rates!$F$16,Rates!$F$18)+K7*IF(D7=1,Rates!$F$17,Rates!$F$19)+E7*(Rates!$F$20+Rates!$F$21) -> 106.83969 | O7: =Rates!$F$22+IF(D7=1,E7*Rates!$F$23,E7*Rates!$F$24)+E7*(Rates!$F$25+Rates!$F$26) -> 66.980754 | P7: =Rates!$F$27+IF(D7=1,G7*Rates!$F$28,MIN(G7,Rates!$F$35)*Rates!$F$29+MAX(G7-Rates!$F$35,0)*Rates!$F$30)+IF(F7>0,Rates!$F$31,0)+F7*Rates!$F$32+E7*(Rates!$F$33+Rates!$F$34) -> 111.49268 | Q7: =IF(L7>0,Rates!$F$36,0)+L7*(Rates!$F$37+Rates!$F$38+Rates!$F$39) -> 164.40885
A8: average | B8: gas_furnace | C8: 4 | D8: =IF(AND(C8>=6,C8<=9),1,0) -> 0 | E8: 720.501 | F8: 79.51 | G8: =E8-F8 -> 640.991 | H8: 82.054 | I8: 125.285 | J8: 324.531 | K8: 188.631 | L8: 128.484 | M8: =Rates!$F$5+IF(D8=1,E8*Rates!$F$6,MIN(E8,Rates!$F$11)*Rates!$F$7+MAX(E8-Rates!$F$11,0)*Rates!$F$8)+E8*(Rates!$F$9+Rates!$F$10) -> 106.44926 | N8: =Rates!$F$12+H8*IF(D8=1,Rates!$F$13,Rates!$F$14)+I8*Rates!$F$15+J8*IF(D8=1,Rates!$F$16,Rates!$F$18)+K8*IF(D8=1,Rates!$F$17,Rates!$F$19)+E8*(Rates!$F$20+Rates!$F$21) -> 99.090831 | O8: =Rates!$F$22+IF(D8=1,E8*Rates!$F$23,E8*Rates!$F$24)+E8*(Rates!$F$25+Rates!$F$26) -> 62.527516 | P8: =Rates!$F$27+IF(D8=1,G8*Rates!$F$28,MIN(G8,Rates!$F$35)*Rates!$F$29+MAX(G8-Rates!$F$35,0)*Rates!$F$30)+IF(F8>0,Rates!$F$31,0)+F8*Rates!$F$32+E8*(Rates!$F$33+Rates!$F$34) -> 105.36445 | Q8: =IF(L8>0,Rates!$F$36,0)+L8*(Rates!$F$37+Rates!$F$38+Rates!$F$39) -> 129.67237
A9: average | B9: gas_furnace | C9: 5 | D9: =IF(AND(C9>=6,C9<=9),1,0) -> 0 | E9: 856.293 | F9: 2.636 | G9: =E9-F9 -> 853.657 | H9: 115.741 | I9: 131.628 | J9: 380.419 | K9: 228.505 | L9: 18.698 | M9: =Rates!$F$5+IF(D9=1,E9*Rates!$F$6,MIN(E9,Rates!$F$11)*Rates!$F$7+MAX(E9-Rates!$F$11,0)*Rates!$F$8)+E9*(Rates!$F$9+Rates!$F$10) -> 125.00388 | N9: =Rates!$F$12+H9*IF(D9=1,Rates!$F$13,Rates!$F$14)+I9*Rates!$F$15+J9*IF(D9=1,Rates!$F$16,Rates!$F$18)+K9*IF(D9=1,Rates!$F$17,Rates!$F$19)+E9*(Rates!$F$20+Rates!$F$21) -> 117.95638 | O9: =Rates!$F$22+IF(D9=1,E9*Rates!$F$23,E9*Rates!$F$24)+E9*(Rates!$F$25+Rates!$F$26) -> 72.804254 | P9: =Rates!$F$27+IF(D9=1,G9*Rates!$F$28,MIN(G9,Rates!$F$35)*Rates!$F$29+MAX(G9-Rates!$F$35,0)*Rates!$F$30)+IF(F9>0,Rates!$F$31,0)+F9*Rates!$F$32+E9*(Rates!$F$33+Rates!$F$34) -> 129.7538 | Q9: =IF(L9>0,Rates!$F$36,0)+L9*(Rates!$F$37+Rates!$F$38+Rates!$F$39) -> 26.988426
A10: average | B10: gas_furnace | C10: 6 | D10: =IF(AND(C10>=6,C10<=9),1,0) -> 1 | E10: 951.494 | F10: 0.286 | G10: =E10-F10 -> 951.208 | H10: 129.032 | I10: 157.934 | J10: 417.297 | K10: 247.231 | L10: 13.759 | M10: =Rates!$F$5+IF(D10=1,E10*Rates!$F$6,MIN(E10,Rates!$F$11)*Rates!$F$7+MAX(E10-Rates!$F$11,0)*Rates!$F$8)+E10*(Rates!$F$9+Rates!$F$10) -> 152.84593 | N10: =Rates!$F$12+H10*IF(D10=1,Rates!$F$13,Rates!$F$14)+I10*Rates!$F$15+J10*IF(D10=1,Rates!$F$16,Rates!$F$18)+K10*IF(D10=1,Rates!$F$17,Rates!$F$19)+E10*(Rates!$F$20+Rates!$F$21) -> 148.24984 | O10: =Rates!$F$22+IF(D10=1,E10*Rates!$F$23,E10*Rates!$F$24)+E10*(Rates!$F$25+Rates!$F$26) -> 152.84593 | P10: =Rates!$F$27+IF(D10=1,G10*Rates!$F$28,MIN(G10,Rates!$F$35)*Rates!$F$29+MAX(G10-Rates!$F$35,0)*Rates!$F$30)+IF(F10>0,Rates!$F$31,0)+F10*Rates!$F$32+E10*(Rates!$F$33+Rates!$F$34) -> 157.76977 | Q10: =IF(L10>0,Rates!$F$36,0)+L10*(Rates!$F$37+Rates!$F$38+Rates!$F$39) -> 22.36893
A11: average | B11: gas_furnace | C11: 7 | D11: =IF(AND(C11>=6,C11<=9),1,0) -> 1 | E11: 1102.828 | F11: 0.199 | G11: =E11-F11 -> 1102.629 | H11: 141.507 | I11: 183.106 | J11: 468.864 | K11: 309.352 | L11: 13.094 | M11: =Rates!$F$5+IF(D11=1,E11*Rates!$F$6,MIN(E11,Rates!$F$11)*Rates!$F$7+MAX(E11-Rates!$F$11,0)*Rates!$F$8)+E11*(Rates!$F$9+Rates!$F$10) -> 175.88351 | N11: =Rates!$F$12+H11*IF(D11=1,Rates!$F$13,Rates!$F$14)+I11*Rates!$F$15+J11*IF(D11=1,Rates!$F$16,Rates!$F$18)+K11*IF(D11=1,Rates!$F$17,Rates!$F$19)+E11*(Rates!$F$20+Rates!$F$21) -> 169.90984 | O11: =Rates!$F$22+IF(D11=1,E11*Rates!$F$23,E11*Rates!$F$24)+E11*(Rates!$F$25+Rates!$F$26) -> 175.88351 | P11: =Rates!$F$27+IF(D11=1,G11*Rates!$F$28,MIN(G11,Rates!$F$35)*Rates!$F$29+MAX(G11-Rates!$F$35,0)*Rates!$F$30)+IF(F11>0,Rates!$F$31,0)+F11*Rates!$F$32+E11*(Rates!$F$33+Rates!$F$34) -> 180.8153 | Q11: =IF(L11>0,Rates!$F$36,0)+L11*(Rates!$F$37+Rates!$F$38+Rates!$F$39) -> 21.746949
